Workbook

Sheet Сводка
A1: Еженедельный съём соцсетей
A2: Текущая неделя — лист: | B2: 28.09-04.10
A3: Прошлая неделя — лист: | B3: 21-27.09
A4: снято 05.10.2026 · ВК 27/27 (Барков), ТГ 22/22 (Барков), МАКС 21/21 (MaxStat), ОК 20/20 (админские выгрузки)
A6: Площадка | B6: Публикаций | C6: Просмотры | D6: Просмотры пред. неделя (сопост. периметр) | E6: Δ % | F6: Лайки | G6: Лайки пред. неделя (сопост. периметр) | H6: Δ % | I6: Лайков на 1000 просмотров | J6: Подписчики | K6: Прирост подписчиков | L6: Δ % просмотров пред. неделя | M6: Ускорение просмотров, п.п. | N6: Δ % лайков пред. неделя | O6: Ускорение лайков, п.п. | P6: Прирост подписч. пред. неделя | Q6: Ускорение подписчиков, чел.
A7: ВКонтакте | B7: {=INDIRECT("'"&$B$2&"'!C30")} | C7: {=IF($B7=0,"",INDIRECT("'"&$B$2&"'!D30"))} | D7: {=IF($B7=0,"",INDIRECT("'"&$B$2&"'!E30"))} | E7: =IF(B7=0,"",IFERROR(C7/D7-1,"")) | F7: {=IF($B7=0,"",INDIRECT("'"&$B$2&"'!H30"))} | G7: {=IF($B7=0,"",INDIRECT("'"&$B$2&"'!I30"))} | H7: =IF(B7=0,"",IFERROR(F7/G7-1,"")) | I7: =IFERROR(F7/C7*1000,"") | J7: {=IF($B7=0,"",INDIRECT("'"&$B$2&"'!N30"))} | K7: {=IF($B7=0,"",INDIRECT("'"&$B$2&"'!O30"))} | L7: {=IFERROR(IF(INDIRECT("'"&$B$3&"'!G30")="","",INDIRECT("'"&$B$3&"'!G30")),"")} | M7: =IF(OR($E7="",$L7=""),"",$E7-$L7) | N7: {=IFERROR(IF(INDIRECT("'"&$B$3&"'!K30")="","",INDIRECT("'"&$B$3&"'!K30")),"")} | O7: =IF(OR($H7="",$N7=""),"",$H7-$N7) | P7: {=IFERROR(IF(INDIRECT("'"&$B$3&"'!O30")="","",INDIRECT("'"&$B$3&"'!O30")),"")} | Q7: =IF(OR($B7=0,$K7="",$P7=""),"",$K7-$P7)
A8: Одноклассники | B8: {=INDIRECT("'"&$B$2&"'!C51")} | C8: {=IF($B8=0,"",INDIRECT("'"&$B$2&"'!D51"))} | D8: {=IF($B8=0,"",INDIRECT("'"&$B$2&"'!E51"))} | E8: =IF(B8=0,"",IFERROR(C8/D8-1,"")) | F8: {=IF($B8=0,"",INDIRECT("'"&$B$2&"'!H51"))} | G8: {=IF($B8=0,"",INDIRECT("'"&$B$2&"'!I51"))} | H8: =IF(B8=0,"",IFERROR(F8/G8-1,"")) | I8: =IFERROR(F8/C8*1000,"") | J8: {=IF($B8=0,"",INDIRECT("'"&$B$2&"'!N51"))} | K8: {=IF($B8=0,"",INDIRECT("'"&$B$2&"'!O51"))} | L8: {=IFERROR(IF(INDIRECT("'"&$B$3&"'!G51")="","",INDIRECT("'"&$B$3&"'!G51")),"")} | M8: =IF(OR($E8="",$L8=""),"",$E8-$L8) | N8: {=IFERROR(IF(INDIRECT("'"&$B$3&"'!K51")="","",INDIRECT("'"&$B$3&"'!K51")),"")} | O8: =IF(OR($H8="",$N8=""),"",$H8-$N8) | P8: {=IFERROR(IF(INDIRECT("'"&$B$3&"'!O51")="","",INDIRECT("'"&$B$3&"'!O51")),"")} | Q8: =IF(OR($B8=0,$K8="",$P8=""),"",$K8-$P8)
A9: Telegram | B9: {=INDIRECT("'"&$B$2&"'!C74")} | C9: {=IF($B9=0,"",INDIRECT("'"&$B$2&"'!D74"))} | D9: {=IF($B9=0,"",INDIRECT("'"&$B$2&"'!E74"))} | E9: =IF(B9=0,"",IFERROR(C9/D9-1,"")) | F9: {=IF($B9=0,"",INDIRECT("'"&$B$2&"'!H74"))} | G9: {=IF($B9=0,"",INDIRECT("'"&$B$2&"'!I74"))} | H9: =IF(B9=0,"",IFERROR(F9/G9-1,"")) | I9: =IFERROR(F9/C9*1000,"") | J9: {=IF($B9=0,"",INDIRECT("'"&$B$2&"'!N74"))} | K9: {=IF($B9=0,"",INDIRECT("'"&$B$2&"'!O74"))} | L9: {=IFERROR(IF(INDIRECT("'"&$B$3&"'!G74")="","",INDIRECT("'"&$B$3&"'!G74")),"")} | M9: =IF(OR($E9="",$L9=""),"",$E9-$L9) | N9: {=IFERROR(IF(INDIRECT("'"&$B$3&"'!K74")="","",INDIRECT("'"&$B$3&"'!K74")),"")} | O9: =IF(OR($H9="",$N9=""),"",$H9-$N9) | P9: {=IFERROR(IF(INDIRECT("'"&$B$3&"'!O74")="","",INDIRECT("'"&$B$3&"'!O74")),"")} | Q9: =IF(OR($B9=0,$K9="",$P9=""),"",$K9-$P9)
A10: МАКС | B10: {=INDIRECT("'"&$B$2&"'!C96")} | C10: {=IF($B10=0,"",INDIRECT("'"&$B$2&"'!D96"))} | D10: {=IF($B10=0,"",INDIRECT("'"&$B$2&"'!E96"))} | E10: =IF(B10=0,"",IFERROR(C10/D10-1,"")) | F10: {=IF($B10=0,"",INDIRECT("'"&$B$2&"'!H96"))} | G10: {=IF($B10=0,"",INDIRECT("'"&$B$2&"'!I96"))} | H10: =IF(B10=0,"",IFERROR(F10/G10-1,"")) | I10: =IFERROR(F10/C10*1000,"") | J10: {=IF($B10=0,"",INDIRECT("'"&$B$2&"'!N96"))} | K10: {=IF($B10=0,"",INDIRECT("'"&$B$2&"'!O96"))} | L10: {=IFERROR(IF(INDIRECT("'"&$B$3&"'!G96")="","",INDIRECT("'"&$B$3&"'!G96")),"")} | M10: =IF(OR($E10="",$L10=""),"",$E10-$L10) | N10: {=IFERROR(IF(INDIRECT("'"&$B$3&"'!K96")="","",INDIRECT("'"&$B$3&"'!K96")),"")} | O10: =IF(OR($H10="",$N10=""),"",$H10-$N10) | P10: {=IFERROR(IF(INDIRECT("'"&$B$3&"'!O96")="","",INDIRECT("'"&$B$3&"'!O96")),"")} | Q10: =IF(OR($B10=0,$K10="",$P10=""),"",$K10-$P10)
A11: ИТОГО | B11: =SUM(B7:B10) | C11: =SUM(C7:C10) | D11: =SUM(D7:D10) | E11: =IF(OR(B7=0,B8=0,B9=0,B10=0),"",IFERROR(C11/D11-1,"")) | F11: =SUM(F7:F10) | G11: =SUM(G7:G10) | H11: =IF(OR(B7=0,B8=0,B9=0,B10=0),"",IFERROR(F11/G11-1,"")) | I11: =IFERROR(F11/C11*1000,"") | J11: =SUM(J7:J10) | K11: =SUM(K7:K10) | L11: {=IFERROR(IF(INDIRECT("'"&$B$3&"'!G97")="","",INDIRECT("'"&$B$3&"'!G97")),"")} | M11: =IF(OR($E11="",$L11=""),"",$E11-$L11) | N11: {=IFERROR(IF(INDIRECT("'"&$B$3&"'!K97")="","",INDIRECT("'"&$B$3&"'!K97")),"")} | O11: =IF(OR($H11="",$N11=""),"",$H11-$N11) | P11: {=IFERROR(IF(INDIRECT("'"&$B$3&"'!O97")="","",INDIRECT("'"&$B$3&"'!O97")),"")} | Q11: =IF(OR(B7=0,B8=0,B9=0,B10=0),"",$K11-$P11)
A13: ускорение = насколько прирост этой недели отличается от прироста прошлой, в процентных пунктах.
A14: Плюс — рост ускорился, минус — рост замедлился (или падение усилилось). Считается от Δ % листа прошлой недели.

Sheet 28.09-04.10
A1: Недельный съём · 28.09–04.10.2026 | Q1: Лист прошлой недели (питает колонки E, I, O):
A2: Площадка | B2: Ресурс | C2: Публикаций | D2: Просмотры | E2: Просмотры пред. неделя | F2: Δ просмотров | G2: Δ % | H2: Лайки | I2: Лайки пред. неделя | J2: Δ лайков | K2: Δ % | L2: Ср. просмотров на пост | M2: Лайков на 1000 просмотров | N2: Подписчики | O2: Прирост подписчиков | Q2: 21-27.09 | S2: Δ % просмотров пред. неделя | T2: Ускорение просмотров, п.п. | U2: Δ % лайков пред. неделя | V2: Ускорение лайков, п.п. | W2: Прирост подписч. пред. неделя | X2: Ускорение подписчиков, чел.
A3: ВКонтакте | B3: Ямал-Медиа | C3: 110 | D3: 2647589 | E3: =IF($D3="","",IFERROR(IF(ISBLANK(INDIRECT("'"&$Q$2&"'!D"&ROW())),"",INDIRECT("'"&$Q$2&"'!D"&ROW())),"")) | F3: =IF(OR(D3="",E3=""),"",D3-E3) | G3: =IFERROR(F3/E3,"") | H3: 5901 | I3: =IF($H3="","",IFERROR(IF(ISBLANK(INDIRECT("'"&$Q$2&"'!H"&ROW())),"",INDIRECT("'"&$Q$2&"'!H"&ROW())),"")) | J3: =IF(OR(H3="",I3=""),"",H3-I3) | K3: =IFERROR(J3/I3,"") | L3: =IFERROR(D3/C3,"") | M3: =IFERROR(H3/D3*1000,"") | N3: 89650 | O3: =IFERROR(IF(OR(N3="",ISBLANK(INDIRECT("'"&$Q$2&"'!N"&ROW()))),"",N3-INDIRECT("'"&$Q$2&"'!N"&ROW())),"") | Q3: Колонки E и I берут прошлую неделю только по строкам, снятым в текущей — сравнение идёт по сопоставимому периметру. | S3: =IFERROR(IF(ISBLANK(INDIRECT("'"&$Q$2&"'!G"&ROW())),"",INDIRECT("'"&$Q$2&"'!G"&ROW())),"") | T3: =IF(OR($G3="",$S3=""),"",$G3-$S3) | U3: =IFERROR(IF(ISBLANK(INDIRECT("'"&$Q$2&"'!K"&ROW())),"",INDIRECT("'"&$Q$2&"'!K"&ROW())),"") | V3: =IF(OR($K3="",$U3=""),"",$K3-$U3) | W3: =IFERROR(IF(ISBLANK(INDIRECT("'"&$Q$2&"'!O"&ROW())),"",INDIRECT("'"&$Q$2&"'!O"&ROW())),"") | X3: =IF(OR($O3="",$W3=""),"",$O3-$W3)
A4: ВКонтакте | B4: Север-Пресс | C4: 120 | D4: 218156 | E4: =IF($D4="","",IFERROR(IF(ISBLANK(INDIRECT("'"&$Q$2&"'!D"&ROW())),"",INDIRECT("'"&$Q$2&"'!D"&ROW())),"")) | F4: =IF(OR(D4="",E4=""),"",D4-E4) | G4: =IFERROR(F4/E4,"") | H4: 672 | I4: =IF($H4="","",IFERROR(IF(ISBLANK(INDIRECT("'"&$Q$2&"'!H"&ROW())),"",INDIRECT("'"&$Q$2&"'!H"&ROW())),"")) | J4: =IF(OR(H4="",I4=""),"",H4-I4) | K4: =IFERROR(J4/I4,"") | L4: =IFERROR(D4/C4,"") | M4: =IFERROR(H4/D4*1000,"") | N4: 26291 | O4: =IFERROR(IF(OR(N4="",ISBLANK(INDIRECT("'"&$Q$2&"'!N"&ROW()))),"",N4-INDIRECT("'"&$Q$2&"'!N"&ROW())),"") | Q4: ОК: «просмотры» = VIEWS листа Topics, лайки = сумма LIKES листа Actions (по группе, как в прошлых съёмах). | S4: =IFERROR(IF(ISBLANK(INDIRECT("'"&$Q$2&"'!G"&ROW())),"",INDIRECT("'"&$Q$2&"'!G"&ROW())),"") | T4: =IF(OR($G4="",$S4=""),"",$G4-$S4) | U4: =IFERROR(IF(ISBLANK(INDIRECT("'"&$Q$2&"'!K"&ROW())),"",INDIRECT("'"&$Q$2&"'!K"&ROW())),"") | V4: =IF(OR($K4="",$U4=""),"",$K4-$U4) | W4: =IFERROR(IF(ISBLANK(INDIRECT("'"&$Q$2&"'!O"&ROW())),"",INDIRECT("'"&$Q$2&"'!O"&ROW())),"") | X4: =IF(OR($O4="",$W4=""),"",$O4-$W4)
A5: ВКонтакте | B5: Лента СП | C5: 171 | D5: 2991 | E5: =IF($D5="","",IFERROR(IF(ISBLANK(INDIRECT("'"&$Q$2&"'!D"&ROW())),"",INDIRECT("'"&$Q$2&"'!D"&ROW())),"")) | F5: =IF(OR(D5="",E5=""),"",D5-E5) | G5: =IFERROR(F5/E5,"") | H5: 12 | I5: =IF($H5="","",IFERROR(IF(ISBLANK(INDIRECT("'"&$Q$2&"'!H"&ROW())),"",INDIRECT("'"&$Q$2&"'!H"&ROW())),"")) | J5: =IF(OR(H5="",I5=""),"",H5-I5) | K5: =IFERROR(J5/I5,"") | L5: =IFERROR(D5/C5,"") | M5: =IFERROR(H5/D5*1000,"") | N5: 3503 | O5: =IFERROR(IF(OR(N5="",ISBLANK(INDIRECT("'"&$Q$2&"'!N"&ROW()))),"",N5-INDIRECT("'"&$Q$2&"'!N"&ROW())),"") | S5: =IFERROR(IF(ISBLANK(INDIRECT("'"&$Q$2&"'!G"&ROW())),"",INDIRECT("'"&$Q$2&"'!G"&ROW())),"") | T5: =IF(OR($G5="",$S5=""),"",$G5-$S5) | U5: =IFERROR(IF(ISBLANK(INDIRECT("'"&$Q$2&"'!K"&ROW())),"",INDIRECT("'"&$Q$2&"'!K"&ROW())),"") | V5: =IF(OR($K5="",$U5=""),"",$K5-$U5) | W5: =IFERROR(IF(ISBLANK(INDIRECT("'"&$Q$2&"'!O"&ROW())),"",INDIRECT("'"&$Q$2&"'!O"&ROW())),"") | X5: =IF(OR($O5="",$W5=""),"",$O5-$W5)
A6: ВКонтакте | B6: Красный Север | C6: 83 | D6: 79350 | E6: =IF($D6="","",IFERROR(IF(ISBLANK(INDIRECT("'"&$Q$2&"'!D"&ROW())),"",INDIRECT("'"&$Q$2&"'!D"&ROW())),"")) | F6: =IF(OR(D6="",E6=""),"",D6-E6) | G6: =IFERROR(F6/E6,"") | H6: 466 | I6: =IF($H6="","",IFERROR(IF(ISBLANK(INDIRECT("'"&$Q$2&"'!H"&ROW())),"",INDIRECT("'"&$Q$2&"'!H"&ROW())),"")) | J6: =IF(OR(H6="",I6=""),"",H6-I6) | K6: =IFERROR(J6/I6,"") | L6: =IFERROR(D6/C6,"") | M6: =IFERROR(H6/D6*1000,"") | N6: 22949 | O6: =IFERROR(IF(OR(N6="",ISBLANK(INDIRECT("'"&$Q$2&"'!N"&ROW()))),"",N6-INDIRECT("'"&$Q$2&"'!N"&ROW())),"") | S6: =IFERROR(IF(ISBLANK(INDIRECT("'"&$Q$2&"'!G"&ROW())),"",INDIRECT("'"&$Q$2&"'!G"&ROW())),"") | T6: =IF(OR($G6="",$S6=""),"",$G6-$S6) | U6: =IFERROR(IF(ISBLANK(INDIRECT("'"&$Q$2&"'!K"&ROW())),"",INDIRECT("'"&$Q$2&"'!K"&ROW())),"") | V6: =IF(OR($K6="",$U6=""),"",$K6-$U6) | W6: =IFERROR(IF(ISBLANK(INDIRECT("'"&$Q$2&"'!O"&ROW())),"",INDIRECT("'"&$Q$2&"'!O"&ROW())),"") | X6: =IF(OR($O6="",$W6=""),"",$O6-$W6)
A7: ВКонтакте | B7: Новый Уренгой | C7: 95 | D7: 84352 | E7: =IF($D7="","",IFERROR(IF(ISBLANK(INDIRECT("'"&$Q$2&"'!D"&ROW())),"",INDIRECT("'"&$Q$2&"'!D"&ROW())),"")) | F7: =IF(OR(D7="",E7=""),"",D7-E7) | G7: =IFERROR(F7/E7,"") | H7: 1068 | I7: =IF($H7="","",IFERROR(IF(ISBLANK(INDIRECT("'"&$Q$2&"'!H"&ROW())),"",INDIRECT("'"&$Q$2&"'!H"&ROW())),"")) | J7: =IF(OR(H7="",I7=""),"",H7-I7) | K7: =IFERROR(J7/I7,"") | L7: =IFERROR(D7/C7,"") | M7: =IFERROR(H7/D7*1000,"") | N7: 24901 | O7: =IFERROR(IF(OR(N7="",ISBLANK(INDIRECT("'"&$Q$2&"'!N"&ROW()))),"",N7-INDIRECT("'"&$Q$2&"'!N"&ROW())),"") | S7: =IFERROR(IF(ISBLANK(INDIRECT("'"&$Q$2&"'!G"&ROW())),"",INDIRECT("'"&$Q$2&"'!G"&ROW())),"") | T7: =IF(OR($G7="",$S7=""),"",$G7-$S7) | U7: =IFERROR(IF(ISBLANK(INDIRECT("'"&$Q$2&"'!K"&ROW())),"",INDIRECT("'"&$Q$2&"'!K"&ROW())),"") | V7: =IF(OR($K7="",$U7=""),"",$K7-$U7) | W7: =IFERROR(IF(ISBLANK(INDIRECT("'"&$Q$2&"'!O"&ROW())),"",INDIRECT("'"&$Q$2&"'!O"&ROW())),"") | X7: =IF(OR($O7="",$W7=""),"",$O7-$W7)
A8: ВКонтакте | B8: Надым | C8: 76 | D8: 196212 | E8: =IF($D8="","",IFERROR(IF(ISBLANK(INDIRECT("'"&$Q$2&"'!D"&ROW())),"",INDIRECT("'"&$Q$2&"'!D"&ROW())),"")) | F8: =IF(OR(D8="",E8=""),"",D8-E8) | G8: =IFERROR(F8/E8,"") | H8: 2605 | I8: =IF($H8="","",IFERROR(IF(ISBLANK(INDIRECT("'"&$Q$2&"'!H"&ROW())),"",INDIRECT("'"&$Q$2&"'!H"&ROW())),"")) | J8: =IF(OR(H8="",I8=""),"",H8-I8) | K8: =IFERROR(J8/I8,"") | L8: =IFERROR(D8/C8,"") | M8: =IFERROR(H8/D8*1000,"") | N8: 21769 | O8: =IFERROR(IF(OR(N8="",ISBLANK(INDIRECT("'"&$Q$2&"'!N"&ROW()))),"",N8-INDIRECT("'"&$Q$2&"'!N"&ROW())),"") | S8: =IFERROR(IF(ISBLANK(INDIRECT("'"&$Q$2&"'!G"&ROW())),"",INDIRECT("'"&$Q$2&"'!G"&ROW())),"") | T8: =IF(OR($G8="",$S8=""),"",$G8-$S8) | U8: =IFERROR(IF(ISBLANK(INDIRECT("'"&$Q$2&"'!K"&ROW())),"",INDIRECT("'"&$Q$2&"'!K"&ROW())),"") | V8: =IF(OR($K8="",$U8=""),"",$K8-$U8) | W8: =IFERROR(IF(ISBLANK(INDIRECT("'"&$Q$2&"'!O"&ROW())),"",INDIRECT("'"&$Q$2&"'!O"&ROW())),"") | X8: =IF(OR($O8="",$W8=""),"",$O8-$W8)
A9: ВКонтакте | B9: Ноябрьск | C9: 91 | D9: 320603 | E9: =IF($D9="","",IFERROR(IF(ISBLANK(INDIRECT("'"&$Q$2&"'!D"&ROW())),"",INDIRECT("'"&$Q$2&"'!D"&ROW())),"")) | F9: =IF(OR(D9="",E9=""),"",D9-E9) | G9: =IFERROR(F9/E9,"") | H9: 4182 | I9: =IF($H9="","",IFERROR(IF(ISBLANK(INDIRECT("'"&$Q$2&"'!H"&ROW())),"",INDIRECT("'"&$Q$2&"'!H"&ROW())),"")) | J9: =IF(OR(H9="",I9=""),"",H9-I9) | K9: =IFERROR(J9/I9,"") | L9: =IFERROR(D9/C9,"") | M9: =IFERROR(H9/D9*1000,"") | N9: 31346 | O9: =IFERROR(IF(OR(N9="",ISBLANK(INDIRECT("'"&$Q$2&"'!N"&ROW()))),"",N9-INDIRECT("'"&$Q$2&"'!N"&ROW())),"") | S9: =IFERROR(IF(ISBLANK(INDIRECT("'"&$Q$2&"'!G"&ROW())),"",INDIRECT("'"&$Q$2&"'!G"&ROW())),"") | T9: =IF(OR($G9="",$S9=""),"",$G9-$S9) | U9: =IFERROR(IF(ISBLANK(INDIRECT("'"&$Q$2&"'!K"&ROW())),"",INDIRECT("'"&$Q$2&"'!K"&ROW())),"") | V9: =IF(OR($K9="",$U9=""),"",$K9-$U9) | W9: =IFERROR(IF(ISBLANK(INDIRECT("'"&$Q$2&"'!O"&ROW())),"",INDIRECT("'"&$Q$2&"'!O"&ROW())),"") | X9: =IF(OR($O9="",$W9=""),"",$O9-$W9)
A10: ВКонтакте | B10: Салехард | C10: 145 | D10: 197099 | E10: =IF($D10="","",IFERROR(IF(ISBLANK(INDIRECT("'"&$Q$2&"'!D"&ROW())),"",INDIRECT("'"&$Q$2&"'!D"&ROW())),"")) | F10: =IF(OR(D10="",E10=""),"",D10-E10) | G10: =IFERROR(F10/E10,"") | H10: 2190 | I10: =IF($H10="","",IFERROR(IF(ISBLANK(INDIRECT("'"&$Q$2&"'!H"&ROW())),"",INDIRECT("'"&$Q$2&"'!H"&ROW())),"")) | J10: =IF(OR(H10="",I10=""),"",H10-I10) | K10: =IFERROR(J10/I10,"") | L10: =IFERROR(D10/C10,"") | M10: =IFERROR(H10/D10*1000,"") | N10: 21613 | O10: =IFERROR(IF(OR(N10="",ISBLANK(INDIRECT("'"&$Q$2&"'!N"&ROW()))),"",N10-INDIRECT("'"&$Q$2&"'!N"&ROW())),"") | S10: =IFERROR(IF(ISBLANK(INDIRECT("'"&$Q$2&"'!G"&ROW())),"",INDIRECT("'"&$Q$2&"'!G"&ROW())),"") | T10: =IF(OR($G10="",$S10=""),"",$G10-$S10) | U10: =IFERROR(IF(ISBLANK(INDIRECT("'"&$Q$2&"'!K"&ROW())),"",INDIRECT("'"&$Q$2&"'!K"&ROW())),"") | V10: =IF(OR($K10="",$U10=""),"",$K10-$U10) | W10: =IFERROR(IF(ISBLANK(INDIRECT("'"&$Q$2&"'!O"&ROW())),"",INDIRECT("'"&$Q$2&"'!O"&ROW())),"") | X10: =IF(OR($O10="",$W10=""),"",$O10-$W10)
A11: ВКонтакте | B11: Приуралье | C11: 104 | D11: 366428 | E11: =IF($D11="","",IFERROR(IF(ISBLANK(INDIRECT("'"&$Q$2&"'!D"&ROW())),"",INDIRECT("'"&$Q$2&"'!D"&ROW())),"")) | F11: =IF(OR(D11="",E11=""),"",D11-E11) | G11: =IFERROR(F11/E11,"") | H11: 2775 | I11: =IF($H11="","",IFERROR(IF(ISBLANK(INDIRECT("'"&$Q$2&"'!H"&ROW())),"",INDIRECT("'"&$Q$2&"'!H"&ROW())),"")) | J11: =IF(OR(H11="",I11=""),"",H11-I11) | K11: =IFERROR(J11/I11,"") | L11: =IFERROR(D11/C11,"") | M11: =IFERROR(H11/D11*1000,"") | N11: 20815 | O11: =IFERROR(IF(OR(N11="",ISBLANK(INDIRECT("'"&$Q$2&"'!N"&ROW()))),"",N11-INDIRECT("'"&$Q$2&"'!N"&ROW())),"") | S11: =IFERROR(IF(ISBLANK(INDIRECT("'"&$Q$2&"'!G"&ROW())),"",INDIRECT("'"&$Q$2&"'!G"&ROW())),"") | T11: =IF(OR($G11="",$S11=""),"",$G11-$S11) | U11: =IFERROR(IF(ISBLANK(INDIRECT("'"&$Q$2&"'!K"&ROW())),"",INDIRECT("'"&$Q$2&"'!K"&ROW())),"") | V11: =IF(OR($K11="",$U11=""),"",$K11-$U11) | W11: =IFERROR(IF(ISBLANK(INDIRECT("'"&$Q$2&"'!O"&ROW())),"",INDIRECT("'"&$Q$2&"'!O"&ROW())),"") | X11: =IF(OR($O11="",$W11=""),"",$O11-$W11)
A12: ВКонтакте | B12: Лабытнанги | C12: 65 | D12: 119193 | E12: =IF($D12="","",IFERROR(IF(ISBLANK(INDIRECT("'"&$Q$2&"'!D"&ROW())),"",INDIRECT("'"&$Q$2&"'!D"&ROW())),"")) | F12: =IF(OR(D12="",E12=""),"",D12-E12) | G12: =IFERROR(F12/E12,"") | H12: 1839 | I12: =IF($H12="","",IFERROR(IF(ISBLANK(INDIRECT("'"&$Q$2&"'!H"&ROW())),"",INDIRECT("'"&$Q$2&"'!H"&ROW())),"")) | J12: =IF(OR(H12="",I12=""),"",H12-I12) | K12: =IFERROR(J12/I12,"") | L12: =IFERROR(D12/C12,"") | M12: =IFERROR(H12/D12*1000,"") | N12: 15558 | O12: =IFERROR(IF(OR(N12="",ISBLANK(INDIRECT("'"&$Q$2&"'!N"&ROW()))),"",N12-INDIRECT("'"&$Q$2&"'!N"&ROW())),"") | S12: =IFERROR(IF(ISBLANK(INDIRECT("'"&$Q$2&"'!G"&ROW())),"",INDIRECT("'"&$Q$2&"'!G"&ROW())),"") | T12: =IF(OR($G12="",$S12=""),"",$G12-$S12) | U12: =IFERROR(IF(ISBLANK(INDIRECT("'"&$Q$2&"'!K"&ROW())),"",INDIRECT("'"&$Q$2&"'!K"&ROW())),"") | V12: =IF(OR($K12="",$U12=""),"",$K12-$U12) | W12: =IFERROR(IF(ISBLANK(INDIRECT("'"&$Q$2&"'!O"&ROW())),"",INDIRECT("'"&$Q$2&"'!O"&ROW())),"") | X12: =IF(OR($O12="",$W12=""),"",$O12-$W12)
A13: ВКонтакте | B13: Пуровский | C13: 47 | D13: 19819 | E13: =IF($D13="","",IFERROR(IF(ISBLANK(INDIRECT("'"&$Q$2&"'!D"&ROW())),"",INDIRECT("'"&$Q$2&"'!D"&ROW())),"")) | F13: =IF(OR(D13="",E13=""),"",D13-E13) | G13: =IFERROR(F13/E13,"") | H13: 287 | I13: =IF($H13="","",IFERROR(IF(ISBLANK(INDIRECT("'"&$Q$2&"'!H"&ROW())),"",INDIRECT("'"&$Q$2&"'!H"&ROW())),"")) | J13: =IF(OR(H13="",I13=""),"",H13-I13) | K13: =IFERROR(J13/I13,"") | L13: =IFERROR(D13/C13,"") | M13: =IFERROR(H13/D13*1000,"") | N13: 16429 | O13: =IFERROR(IF(OR(N13="",ISBLANK(INDIRECT("'"&$Q$2&"'!N"&ROW()))),"",N13-INDIRECT("'"&$Q$2&"'!N"&ROW())),"") | S13: =IFERROR(IF(ISBLANK(INDIRECT("'"&$Q$2&"'!G"&ROW())),"",INDIRECT("'"&$Q$2&"'!G"&ROW())),"") | T13: =IF(OR($G13="",$S13=""),"",$G13-$S13) | U13: =IFERROR(IF(ISBLANK(INDIRECT("'"&$Q$2&"'!K"&ROW())),"",INDIRECT("'"&$Q$2&"'!K"&ROW())),"") | V13: =IF(OR($K13="",$U13=""),"",$K13-$U13) | W13: =IFERROR(IF(ISBLANK(INDIRECT("'"&$Q$2&"'!O"&ROW())),"",INDIRECT("'"&$Q$2&"'!O"&ROW())),"") | X13: =IF(OR($O13="",$W13=""),"",$O13-$W13)
A14: ВКонтакте | B14: Тазовский | C14: 65 | D14: 58490 | E14: =IF($D14="","",IFERROR(IF(ISBLANK(INDIRECT("'"&$Q$2&"'!D"&ROW())),"",INDIRECT("'"&$Q$2&"'!D"&ROW())),"")) | F14: =IF(OR(D14="",E14=""),"",D14-E14) | G14: =IFERROR(F14/E14,"") | H14: 798 | I14: =IF($H14="","",IFERROR(IF(ISBLANK(INDIRECT("'"&$Q$2&"'!H"&ROW())),"",INDIRECT("'"&$Q$2&"'!H"&ROW())),"")) | J14: =IF(OR(H14="",I14=""),"",H14-I14) | K14: =IFERROR(J14/I14,"") | L14: =IFERROR(D14/C14,"") | M14: =IFERROR(H14/D14*1000,"") | N14: 6468 | O14: =IFERROR(IF(OR(N14="",ISBLANK(INDIRECT("'"&$Q$2&"'!N"&ROW()))),"",N14-INDIRECT("'"&$Q$2&"'!N"&ROW())),"") | S14: =IFERROR(IF(ISBLANK(INDIRECT("'"&$Q$2&"'!G"&ROW())),"",INDIRECT("'"&$Q$2&"'!G"&ROW())),"") | T14: =IF(OR($G14="",$S14=""),"",$G14-$S14) | U14: =IFERROR(IF(ISBLANK(INDIRECT("'"&$Q$2&"'!K"&ROW())),"",INDIRECT("'"&$Q$2&"'!K"&ROW())),"") | V14: =IF(OR($K14="",$U14=""),"",$K14-$U14) | W14: =IFERROR(IF(ISBLANK(INDIRECT("'"&$Q$2&"'!O"&ROW())),"",INDIRECT("'"&$Q$2&"'!O"&ROW())),"") | X14: =IF(OR($O14="",$W14=""),"",$O14-$W14)
A15: ВКонтакте | B15: Красноселькуп | C15: 27 | D15: 33209 | E15: =IF($D15="","",IFERROR(IF(ISBLANK(INDIRECT("'"&$Q$2&"'!D"&ROW())),"",INDIRECT("'"&$Q$2&"'!D"&ROW())),"")) | F15: =IF(OR(D15="",E15=""),"",D15-E15) | G15: =IFERROR(F15/E15,"") | H15: 303 | I15: =IF($H15="","",IFERROR(IF(ISBLANK(INDIRECT("'"&$Q$2&"'!H"&ROW())),"",INDIRECT("'"&$Q$2&"'!H"&ROW())),"")) | J15: =IF(OR(H15="",I15=""),"",H15-I15) | K15: =IFERROR(J15/I15,"") | L15: =IFERROR(D15/C15,"") | M15: =IFERROR(H15/D15*1000,"") | N15: 3699 | O15: =IFERROR(IF(OR(N15="",ISBLANK(INDIRECT("'"&$Q$2&"'!N"&ROW()))),"",N15-INDIRECT("'"&$Q$2&"'!N"&ROW())),"") | S15: =IFERROR(IF(ISBLANK(INDIRECT("'"&$Q$2&"'!G"&ROW())),"",INDIRECT("'"&$Q$2&"'!G"&ROW())),"") | T15: =IF(OR($G15="",$S15=""),"",$G15-$S15) | U15: =IFERROR(IF(ISBLANK(INDIRECT("'"&$Q$2&"'!K"&ROW())),"",INDIRECT("'"&$Q$2&"'!K"&ROW())),"") | V15: =IF(OR($K15="",$U15=""),"",$K15-$U15) | W15: =IFERROR(IF(ISBLANK(INDIRECT("'"&$Q$2&"'!O"&ROW())),"",INDIRECT("'"&$Q$2&"'!O"&ROW())),"") | X15: =IF(OR($O15="",$W15=""),"",$O15-$W15)
A16: ВКонтакте | B16: Ямальский | C16: 46 | D16: 86941 | E16: =IF($D16="","",IFERROR(IF(ISBLANK(INDIRECT("'"&$Q$2&"'!D"&ROW())),"",INDIRECT("'"&$Q$2&"'!D"&ROW())),"")) | F16: =IF(OR(D16="",E16=""),"",D16-E16) | G16: =IFERROR(F16/E16,"") | H16: 723 | I16: =IF($H16="","",IFERROR(IF(ISBLANK(INDIRECT("'"&$Q$2&"'!H"&ROW())),"",INDIRECT("'"&$Q$2&"'!H"&ROW())),"")) | J16: =IF(OR(H16="",I16=""),"",H16-I16) | K16: =IFERROR(J16/I16,"") | L16: =IFERROR(D16/C16,"") | M16: =IFERROR(H16/D16*1000,"") | N16: 12902 | O16: =IFERROR(IF(OR(N16="",ISBLANK(INDIRECT("'"&$Q$2&"'!N"&ROW()))),"",N16-INDIRECT("'"&$Q$2&"'!N"&ROW())),"") | S16: =IFERROR(IF(ISBLANK(INDIRECT("'"&$Q$2&"'!G"&ROW())),"",INDIRECT("'"&$Q$2&"'!G"&ROW())),"") | T16: =IF(OR($G16="",$S16=""),"",$G16-$S16) | U16: =IFERROR(IF(ISBLANK(INDIRECT("'"&$Q$2&"'!K"&ROW())),"",INDIRECT("'"&$Q$2&"'!K"&ROW())),"") | V16: =IF(OR($K16="",$U16=""),"",$K16-$U16) | W16: =IFERROR(IF(ISBLANK(INDIRECT("'"&$Q$2&"'!O"&ROW())),"",INDIRECT("'"&$Q$2&"'!O"&ROW())),"") | X16: =IF(OR($O16="",$W16=""),"",$O16-$W16)
... A29: ВКонтакте | B29: Морошка | C29: 9 | D29: 26347 | E29: =IF($D29="","",IFERROR(IF(ISBLANK(INDIRECT("'"&$Q$2&"'!D"&ROW())),"",INDIRECT("'"&$Q$2&"'!D"&ROW())),"")) | F29: =IF(OR(D29="",E29=""),"",D29-E29) | G29: =IFERROR(F29/E29,"") | H29: 363 | I29: =IF($H29="","",IFERROR(IF(ISBLANK(INDIRECT("'"&$Q$2&"'!H"&ROW())),"",INDIRECT("'"&$Q$2&"'!H"&ROW())),"")) | J29: =IF(OR(H29="",I29=""),"",H29-I29) | K29: =IFERROR(J29/I29,"") | L29: =IFERROR(D29/C29,"") | M29: =IFERROR(H29/D29*1000,"") | N29: 9759 | O29: =IFERROR(IF(OR(N29="",ISBLANK(INDIRECT("'"&$Q$2&"'!N"&ROW()))),"",N29-INDIRECT("'"&$Q$2&"'!N"&ROW())),"") | S29: =IFERROR(IF(ISBLANK(INDIRECT("'"&$Q$2&"'!G"&ROW())),"",INDIRECT("'"&$Q$2&"'!G"&ROW())),"") | T29: =IF(OR($G29="",$S29=""),"",$G29-$S29) | U29: =IFERROR(IF(ISBLANK(INDIRECT("'"&$Q$2&"'!K"&ROW())),"",INDIRECT("'"&$Q$2&"'!K"&ROW())),"") | V29: =IF(OR($K29="",$U29=""),"",$K29-$U29) | W29: =IFERROR(IF(ISBLANK(INDIRECT("'"&$Q$2&"'!O"&ROW())),"",INDIRECT("'"&$Q$2&"'!O"&ROW())),"") | X29: =IF(OR($O29="",$W29=""),"",$O29-$W29)
B30: Итого ВКонтакте | C30: =SUM(C3:C29) | D30: =SUM(D3:D29) | E30: =SUM(E3:E29) | F30: =SUM(F3:F29) | G30: =IF(C30=0,"",IFERROR(F30/E30,"")) | H30: =SUM(H3:H29) | I30: =SUM(I3:I29) | J30: =SUM(J3:J29) | K30: =IF(C30=0,"",IFERROR(J30/I30,"")) | L30: =IFERROR(D30/C30,"") | M30: =IFERROR(H30/D30*1000,"") | N30: =SUM(N3:N29) | O30: =SUM(O3:O29) | S30: =IFERROR(IF(ISBLANK(INDIRECT("'"&$Q$2&"'!G"&ROW())),"",INDIRECT("'"&$Q$2&"'!G"&ROW())),"") | T30: =IF(OR($G30="",$S30=""),"",$G30-$S30) | U30: =IFERROR(IF(ISBLANK(INDIRECT("'"&$Q$2&"'!K"&ROW())),"",INDIRECT("'"&$Q$2&"'!K"&ROW())),"") | V30: =IF(OR($K30="",$U30=""),"",$K30-$U30) | W30: =IFERROR(IF(ISBLANK(INDIRECT("'"&$Q$2&"'!O"&ROW())),"",INDIRECT("'"&$Q$2&"'!O"&ROW())),"") | X30: =IF(OR(C30=0,$O30="",$W30=""),"",$O30-$W30)
A31: Одноклассники | B31: Ямал-Медиа | C31: 114 | D31: 29953 | E31: =IF($D31="","",IFERROR(IF(ISBLANK(INDIRECT("'"&$Q$2&"'!D"&ROW())),"",INDIRECT("'"&$Q$2&"'!D"&ROW())),"")) | F31: =IF(OR(D31="",E31=""),"",D31-E31) | G31: =IFERROR(F31/E31,"") | H31: 158 | I31: =IF($H31="","",IFERROR(IF(ISBLANK(INDIRECT("'"&$Q$2&"'!H"&ROW())),"",INDIRECT("'"&$Q$2&"'!H"&ROW())),"")) | J31: =IF(OR(H31="",I31=""),"",H31-I31) | K31: =IFERROR(J31/I31,"") | L31: =IFERROR(D31/C31,"") | M31: =IFERROR(H31/D31*1000,"") | N31: 32493 | O31: =IFERROR(IF(OR(N31="",ISBLANK(INDIRECT("'"&$Q$2&"'!N"&ROW()))),"",N31-INDIRECT("'"&$Q$2&"'!N"&ROW())),"") | S31: =IFERROR(IF(ISBLANK(INDIRECT("'"&$Q$2&"'!G"&ROW())),"",INDIRECT("'"&$Q$2&"'!G"&ROW())),"") | T31: =IF(OR($G31="",$S31=""),"",$G31-$S31) | U31: =IFERROR(IF(ISBLANK(INDIRECT("'"&$Q$2&"'!K"&ROW())),"",INDIRECT("'"&$Q$2&"'!K"&ROW())),"") | V31: =IF(OR($K31="",$U31=""),"",$K31-$U31) | W31: =IFERROR(IF(ISBLANK(INDIRECT("'"&$Q$2&"'!O"&ROW())),"",INDIRECT("'"&$Q$2&"'!O"&ROW())),"") | X31: =IF(OR($O31="",$W31=""),"",$O31-$W31)
A32: Одноклассники | B32: Север-Пресс | C32: 102 | D32: 35196 | E32: =IF($D32="","",IFERROR(IF(ISBLANK(INDIRECT("'"&$Q$2&"'!D"&ROW())),"",INDIRECT("'"&$Q$2&"'!D"&ROW())),"")) | F32: =IF(OR(D32="",E32=""),"",D32-E32) | G32: =IFERROR(F32/E32,"") | H32: 30 | I32: =IF($H32="","",IFERROR(IF(ISBLANK(INDIRECT("'"&$Q$2&"'!H"&ROW())),"",INDIRECT("'"&$Q$2&"'!H"&ROW())),"")) | J32: =IF(OR(H32="",I32=""),"",H32-I32) | K32: =IFERROR(J32/I32,"") | L32: =IFERROR(D32/C32,"") | M32: =IFERROR(H32/D32*1000,"") | N32: 21739 | O32: =IFERROR(IF(OR(N32="",ISBLANK(INDIRECT("'"&$Q$2&"'!N"&ROW()))),"",N32-INDIRECT("'"&$Q$2&"'!N"&ROW())),"") | S32: =IFERROR(IF(ISBLANK(INDIRECT("'"&$Q$2&"'!G"&ROW())),"",INDIRECT("'"&$Q$2&"'!G"&ROW())),"") | T32: =IF(OR($G32="",$S32=""),"",$G32-$S32) | U32: =IFERROR(IF(ISBLANK(INDIRECT("'"&$Q$2&"'!K"&ROW())),"",INDIRECT("'"&$Q$2&"'!K"&ROW())),"") | V32: =IF(OR($K32="",$U32=""),"",$K32-$U32) | W32: =IFERROR(IF(ISBLANK(INDIRECT("'"&$Q$2&"'!O"&ROW())),"",INDIRECT("'"&$Q$2&"'!O"&ROW())),"") | X32: =IF(OR($O32="",$W32=""),"",$O32-$W32)
A33: Одноклассники | B33: Красный Север | C33: 73 | D33: 24690 | E33: =IF($D33="","",IFERROR(IF(ISBLANK(INDIRECT("'"&$Q$2&"'!D"&ROW())),"",INDIRECT("'"&$Q$2&"'!D"&ROW())),"")) | F33: =IF(OR(D33="",E33=""),"",D33-E33) | G33: =IFERROR(F33/E33,"") | H33: 20 | I33: =IF($H33="","",IFERROR(IF(ISBLANK(INDIRECT("'"&$Q$2&"'!H"&ROW())),"",INDIRECT("'"&$Q$2&"'!H"&ROW())),"")) | J33: =IF(OR(H33="",I33=""),"",H33-I33) | K33: =IFERROR(J33/I33,"") | L33: =IFERROR(D33/C33,"") | M33: =IFERROR(H33/D33*1000,"") | N33: 8964 | O33: =IFERROR(IF(OR(N33="",ISBLANK(INDIRECT("'"&$Q$2&"'!N"&ROW()))),"",N33-INDIRECT("'"&$Q$2&"'!N"&ROW())),"") | S33: =IFERROR(IF(ISBLANK(INDIRECT("'"&$Q$2&"'!G"&ROW())),"",INDIRECT("'"&$Q$2&"'!G"&ROW())),"") | T33: =IF(OR($G33="",$S33=""),"",$G33-$S33) | U33: =IFERROR(IF(ISBLANK(INDIRECT("'"&$Q$2&"'!K"&ROW())),"",INDIRECT("'"&$Q$2&"'!K"&ROW())),"") | V33: =IF(OR($K33="",$U33=""),"",$K33-$U33) | W33: =IFERROR(IF(ISBLANK(INDIRECT("'"&$Q$2&"'!O"&ROW())),"",INDIRECT("'"&$Q$2&"'!O"&ROW())),"") | X33: =IF(OR($O33="",$W33=""),"",$O33-$W33)
A34: Одноклассники | B34: Новый Уренгой | C34: 78 | D34: 583 | E34: =IF($D34="","",IFERROR(IF(ISBLANK(INDIRECT("'"&$Q$2&"'!D"&ROW())),"",INDIRECT("'"&$Q$2&"'!D"&ROW())),"")) | F34: =IF(OR(D34="",E34=""),"",D34-E34) | G34: =IFERROR(F34/E34,"") | H34: 0 | I34: =IF($H34="","",IFERROR(IF(ISBLANK(INDIRECT("'"&$Q$2&"'!H"&ROW())),"",INDIRECT("'"&$Q$2&"'!H"&ROW())),"")) | J34: =IF(OR(H34="",I34=""),"",H34-I34) | K34: =IFERROR(J34/I34,"") | L34: =IFERROR(D34/C34,"") | M34: =IFERROR(H34/D34*1000,"") | N34: 6 | O34: =IFERROR(IF(OR(N34="",ISBLANK(INDIRECT("'"&$Q$2&"'!N"&ROW()))),"",N34-INDIRECT("'"&$Q$2&"'!N"&ROW())),"") | S34: =IFERROR(IF(ISBLANK(INDIRECT("'"&$Q$2&"'!G"&ROW())),"",INDIRECT("'"&$Q$2&"'!G"&ROW())),"") | T34: =IF(OR($G34="",$S34=""),"",$G34-$S34) | U34: =IFERROR(IF(ISBLANK(INDIRECT("'"&$Q$2&"'!K"&ROW())),"",INDIRECT("'"&$Q$2&"'!K"&ROW())),"") | V34: =IF(OR($K34="",$U34=""),"",$K34-$U34) | W34: =IFERROR(IF(ISBLANK(INDIRECT("'"&$Q$2&"'!O"&ROW())),"",INDIRECT("'"&$Q$2&"'!O"&ROW())),"") | X34: =IF(OR($O34="",$W34=""),"",$O34-$W34)
A35: Одноклассники | B35: Надым | C35: 73 | D35: 7094 | E35: =IF($D35="","",IFERROR(IF(ISBLANK(INDIRECT("'"&$Q$2&"'!D"&ROW())),"",INDIRECT("'"&$Q$2&"'!D"&ROW())),"")) | F35: =IF(OR(D35="",E35=""),"",D35-E35) | G35: =IFERROR(F35/E35,"") | H35: 72 | I35: =IF($H35="","",IFERROR(IF(ISBLANK(INDIRECT("'"&$Q$2&"'!H"&ROW())),"",INDIRECT("'"&$Q$2&"'!H"&ROW())),"")) | J35: =IF(OR(H35="",I35=""),"",H35-I35) | K35: =IFERROR(J35/I35,"") | L35: =IFERROR(D35/C35,"") | M35: =IFERROR(H35/D35*1000,"") | N35: 1943 | O35: =IFERROR(IF(OR(N35="",ISBLANK(INDIRECT("'"&$Q$2&"'!N"&ROW()))),"",N35-INDIRECT("'"&$Q$2&"'!N"&ROW())),"") | S35: =IFERROR(IF(ISBLANK(INDIRECT("'"&$Q$2&"'!G"&ROW())),"",INDIRECT("'"&$Q$2&"'!G"&ROW())),"") | T35: =IF(OR($G35="",$S35=""),"",$G35-$S35) | U35: =IFERROR(IF(ISBLANK(INDIRECT("'"&$Q$2&"'!K"&ROW())),"",INDIRECT("'"&$Q$2&"'!K"&ROW())),"") | V35: =IF(OR($K35="",$U35=""),"",$K35-$U35) | W35: =IFERROR(IF(ISBLANK(INDIRECT("'"&$Q$2&"'!O"&ROW())),"",INDIRECT("'"&$Q$2&"'!O"&ROW())),"") | X35: =IF(OR($O35="",$W35=""),"",$O35-$W35)
A36: Одноклассники | B36: Ноябрьск | C36: 83 | D36: 35834 | E36: =IF($D36="","",IFERROR(IF(ISBLANK(INDIRECT("'"&$Q$2&"'!D"&ROW())),"",INDIRECT("'"&$Q$2&"'!D"&ROW())),"")) | F36: =IF(OR(D36="",E36=""),"",D36-E36) | G36: =IFERROR(F36/E36,"") | H36: 491 | I36: =IF($H36="","",IFERROR(IF(ISBLANK(INDIRECT("'"&$Q$2&"'!H"&ROW())),"",INDIRECT("'"&$Q$2&"'!H"&ROW())),"")) | J36: =IF(OR(H36="",I36=""),"",H36-I36) | K36: =IFERROR(J36/I36,"") | L36: =IFERROR(D36/C36,"") | M36: =IFERROR(H36/D36*1000,"") | N36: 5896 | O36: =IFERROR(IF(OR(N36="",ISBLANK(INDIRECT("'"&$Q$2&"'!N"&ROW()))),"",N36-INDIRECT("'"&$Q$2&"'!N"&ROW())),"") | S36: =IFERROR(IF(ISBLANK(INDIRECT("'"&$Q$2&"'!G"&ROW())),"",INDIRECT("'"&$Q$2&"'!G"&ROW())),"") | T36: =IF(OR($G36="",$S36=""),"",$G36-$S36) | U36: =IFERROR(IF(ISBLANK(INDIRECT("'"&$Q$2&"'!K"&ROW())),"",INDIRECT("'"&$Q$2&"'!K"&ROW())),"") | V36: =IF(OR($K36="",$U36=""),"",$K36-$U36) | W36: =IFERROR(IF(ISBLANK(INDIRECT("'"&$Q$2&"'!O"&ROW())),"",INDIRECT("'"&$Q$2&"'!O"&ROW())),"") | X36: =IF(OR($O36="",$W36=""),"",$O36-$W36)
A37: Одноклассники | B37: Салехард | C37: 130 | D37: 7921 | E37: =IF($D37="","",IFERROR(IF(ISBLANK(INDIRECT("'"&$Q$2&"'!D"&ROW())),"",INDIRECT("'"&$Q$2&"'!D"&ROW())),"")) | F37: =IF(OR(D37="",E37=""),"",D37-E37) | G37: =IFERROR(F37/E37,"") | H37: 96 | I37: =IF($H37="","",IFERROR(IF(ISBLANK(INDIRECT("'"&$Q$2&"'!H"&ROW())),"",INDIRECT("'"&$Q$2&"'!H"&ROW())),"")) | J37: =IF(OR(H37="",I37=""),"",H37-I37) | K37: =IFERROR(J37/I37,"") | L37: =IFERROR(D37/C37,"") | M37: =IFERROR(H37/D37*1000,"") | N37: 3239 | O37: =IFERROR(IF(OR(N37="",ISBLANK(INDIRECT("'"&$Q$2&"'!N"&ROW()))),"",N37-INDIRECT("'"&$Q$2&"'!N"&ROW())),"") | S37: =IFERROR(IF(ISBLANK(INDIRECT("'"&$Q$2&"'!G"&ROW())),"",INDIRECT("'"&$Q$2&"'!G"&ROW())),"") | T37: =IF(OR($G37="",$S37=""),"",$G37-$S37) | U37: =IFERROR(IF(ISBLANK(INDIRECT("'"&$Q$2&"'!K"&ROW())),"",INDIRECT("'"&$Q$2&"'!K"&ROW())),"") | V37: =IF(OR($K37="",$U37=""),"",$K37-$U37) | W37: =IFERROR(IF(ISBLANK(INDIRECT("'"&$Q$2&"'!O"&ROW())),"",INDIRECT("'"&$Q$2&"'!O"&ROW())),"") | X37: =IF(OR($O37="",$W37=""),"",$O37-$W37)
A38: Одноклассники | B38: Приуралье | C38: 104 | D38: 10012 | E38: =IF($D38="","",IFERROR(IF(ISBLANK(INDIRECT("'"&$Q$2&"'!D"&ROW())),"",INDIRECT("'"&$Q$2&"'!D"&ROW())),"")) | F38: =IF(OR(D38="",E38=""),"",D38-E38) | G38: =IFERROR(F38/E38,"") | H38: 273 | I38: =IF($H38="","",IFERROR(IF(ISBLANK(INDIRECT("'"&$Q$2&"'!H"&ROW())),"",INDIRECT("'"&$Q$2&"'!H"&ROW())),"")) | J38: =IF(OR(H38="",I38=""),"",H38-I38) | K38: =IFERROR(J38/I38,"") | L38: =IFERROR(D38/C38,"") | M38: =IFERROR(H38/D38*1000,"") | N38: 1716 | O38: =IFERROR(IF(OR(N38="",ISBLANK(INDIRECT("'"&$Q$2&"'!N"&ROW()))),"",N38-INDIRECT("'"&$Q$2&"'!N"&ROW())),"") | S38: =IFERROR(IF(ISBLANK(INDIRECT("'"&$Q$2&"'!G"&ROW())),"",INDIRECT("'"&$Q$2&"'!G"&ROW())),"") | T38: =IF(OR($G38="",$S38=""),"",$G38-$S38) | U38: =IFERROR(IF(ISBLANK(INDIRECT("'"&$Q$2&"'!K"&ROW())),"",INDIRECT("'"&$Q$2&"'!K"&ROW())),"") | V38: =IF(OR($K38="",$U38=""),"",$K38-$U38) | W38: =IFERROR(IF(ISBLANK(INDIRECT("'"&$Q$2&"'!O"&ROW())),"",INDIRECT("'"&$Q$2&"'!O"&ROW())),"") | X38: =IF(OR($O38="",$W38=""),"",$O38-$W38)
A39: Одноклассники | B39: Лабытнанги | C39: 55 | D39: 4149 | E39: =IF($D39="","",IFERROR(IF(ISBLANK(INDIRECT("'"&$Q$2&"'!D"&ROW())),"",INDIRECT("'"&$Q$2&"'!D"&ROW())),"")) | F39: =IF(OR(D39="",E39=""),"",D39-E39) | G39: =IFERROR(F39/E39,"") | H39: 2 | I39: =IF($H39="","",IFERROR(IF(ISBLANK(INDIRECT("'"&$Q$2&"'!H"&ROW())),"",INDIRECT("'"&$Q$2&"'!H"&ROW())),"")) | J39: =IF(OR(H39="",I39=""),"",H39-I39) | K39: =IFERROR(J39/I39,"") | L39: =IFERROR(D39/C39,"") | M39: =IFERROR(H39/D39*1000,"") | N39: 226 | O39: =IFERROR(IF(OR(N39="",ISBLANK(INDIRECT("'"&$Q$2&"'!N"&ROW()))),"",N39-INDIRECT("'"&$Q$2&"'!N"&ROW())),"") | S39: =IFERROR(IF(ISBLANK(INDIRECT("'"&$Q$2&"'!G"&ROW())),"",INDIRECT("'"&$Q$2&"'!G"&ROW())),"") | T39: =IF(OR($G39="",$S39=""),"",$G39-$S39) | U39: =IFERROR(IF(ISBLANK(INDIRECT("'"&$Q$2&"'!K"&ROW())),"",INDIRECT("'"&$Q$2&"'!K"&ROW())),"") | V39: =IF(OR($K39="",$U39=""),"",$K39-$U39) | W39: =IFERROR(IF(ISBLANK(INDIRECT("'"&$Q$2&"'!O"&ROW())),"",INDIRECT("'"&$Q$2&"'!O"&ROW())),"") | X39: =IF(OR($O39="",$W39=""),"",$O39-$W39)
A40: Одноклассники | B40: Пуровский | C40: 37 | D40: 4445 | E40: =IF($D40="","",IFERROR(IF(ISBLANK(INDIRECT("'"&$Q$2&"'!D"&ROW())),"",INDIRECT("'"&$Q$2&"'!D"&ROW())),"")) | F40: =IF(OR(D40="",E40=""),"",D40-E40) | G40: =IFERROR(F40/E40,"") | H40: 51 | I40: =IF($H40="","",IFERROR(IF(ISBLANK(INDIRECT("'"&$Q$2&"'!H"&ROW())),"",INDIRECT("'"&$Q$2&"'!H"&ROW())),"")) | J40: =IF(OR(H40="",I40=""),"",H40-I40) | K40: =IFERROR(J40/I40,"") | L40: =IFERROR(D40/C40,"") | M40: =IFERROR(H40/D40*1000,"") | N40: 4962 | O40: =IFERROR(IF(OR(N40="",ISBLANK(INDIRECT("'"&$Q$2&"'!N"&ROW()))),"",N40-INDIRECT("'"&$Q$2&"'!N"&ROW())),"") | S40: =IFERROR(IF(ISBLANK(INDIRECT("'"&$Q$2&"'!G"&ROW())),"",INDIRECT("'"&$Q$2&"'!G"&ROW())),"") | T40: =IF(OR($G40="",$S40=""),"",$G40-$S40) | U40: =IFERROR(IF(ISBLANK(INDIRECT("'"&$Q$2&"'!K"&ROW())),"",INDIRECT("'"&$Q$2&"'!K"&ROW())),"") | V40: =IF(OR($K40="",$U40=""),"",$K40-$U40) | W40: =IFERROR(IF(ISBLANK(INDIRECT("'"&$Q$2&"'!O"&ROW())),"",INDIRECT("'"&$Q$2&"'!O"&ROW())),"") | X40: =IF(OR($O40="",$W40=""),"",$O40-$W40)
A41: Одноклассники | B41: Тазовский | C41: 55 | D41: 12178 | E41: =IF($D41="","",IFERROR(IF(ISBLANK(INDIRECT("'"&$Q$2&"'!D"&ROW())),"",INDIRECT("'"&$Q$2&"'!D"&ROW())),"")) | F41: =IF(OR(D41="",E41=""),"",D41-E41) | G41: =IFERROR(F41/E41,"") | H41: 109 | I41: =IF($H41="","",IFERROR(IF(ISBLANK(INDIRECT("'"&$Q$2&"'!H"&ROW())),"",INDIRECT("'"&$Q$2&"'!H"&ROW())),"")) | J41: =IF(OR(H41="",I41=""),"",H41-I41) | K41: =IFERROR(J41/I41,"") | L41: =IFERROR(D41/C41,"") | M41: =IFERROR(H41/D41*1000,"") | N41: 3532 | O41: =IFERROR(IF(OR(N41="",ISBLANK(INDIRECT("'"&$Q$2&"'!N"&ROW()))),"",N41-INDIRECT("'"&$Q$2&"'!N"&ROW())),"") | S41: =IFERROR(IF(ISBLANK(INDIRECT("'"&$Q$2&"'!G"&ROW())),"",INDIRECT("'"&$Q$2&"'!G"&ROW())),"") | T41: =IF(OR($G41="",$S41=""),"",$G41-$S41) | U41: =IFERROR(IF(ISBLANK(INDIRECT("'"&$Q$2&"'!K"&ROW())),"",INDIRECT("'"&$Q$2&"'!K"&ROW())),"") | V41: =IF(OR($K41="",$U41=""),"",$K41-$U41) | W41: =IFERROR(IF(ISBLANK(INDIRECT("'"&$Q$2&"'!O"&ROW())),"",INDIRECT("'"&$Q$2&"'!O"&ROW())),"") | X41: =IF(OR($O41="",$W41=""),"",$O41-$W41)
A42: Одноклассники | B42: Красноселькуп | C42: 24 | D42: 5911 | E42: =IF($D42="","",IFERROR(IF(ISBLANK(INDIRECT("'"&$Q$2&"'!D"&ROW())),"",INDIRECT("'"&$Q$2&"'!D"&ROW())),"")) | F42: =IF(OR(D42="",E42=""),"",D42-E42) | G42: =IFERROR(F42/E42,"") | H42: 82 | I42: =IF($H42="","",IFERROR(IF(ISBLANK(INDIRECT("'"&$Q$2&"'!H"&ROW())),"",INDIRECT("'"&$Q$2&"'!H"&ROW())),"")) | J42: =IF(OR(H42="",I42=""),"",H42-I42) | K42: =IFERROR(J42/I42,"") | L42: =IFERROR(D42/C42,"") | M42: =IFERROR(H42/D42*1000,"") | N42: 655 | O42: =IFERROR(IF(OR(N42="",ISBLANK(INDIRECT("'"&$Q$2&"'!N"&ROW()))),"",N42-INDIRECT("'"&$Q$2&"'!N"&ROW())),"") | S42: =IFERROR(IF(ISBLANK(INDIRECT("'"&$Q$2&"'!G"&ROW())),"",INDIRECT("'"&$Q$2&"'!G"&ROW())),"") | T42: =IF(OR($G42="",$S42=""),"",$G42-$S42) | U42: =IFERROR(IF(ISBLANK(INDIRECT("'"&$Q$2&"'!K"&ROW())),"",INDIRECT("'"&$Q$2&"'!K"&ROW())),"") | V42: =IF(OR($K42="",$U42=""),"",$K42-$U42) | W42: =IFERROR(IF(ISBLANK(INDIRECT("'"&$Q$2&"'!O"&ROW())),"",INDIRECT("'"&$Q$2&"'!O"&ROW())),"") | X42: =IF(OR($O42="",$W42=""),"",$O42-$W42)
... A50: Одноклассники | B50: Морошка | C50: 5 | D50: 388 | E50: =IF($D50="","",IFERROR(IF(ISBLANK(INDIRECT("'"&$Q$2&"'!D"&ROW())),"",INDIRECT("'"&$Q$2&"'!D"&ROW())),"")) | F50: =IF(OR(D50="",E50=""),"",D50-E50) | G50: =IFERROR(F50/E50,"") | H50: 2 | I50: =IF($H50="","",IFERROR(IF(ISBLANK(INDIRECT("'"&$Q$2&"'!H"&ROW())),"",INDIRECT("'"&$Q$2&"'!H"&ROW())),"")) | J50: =IF(OR(H50="",I50=""),"",H50-I50) | K50: =IFERROR(J50/I50,"") | L50: =IFERROR(D50/C50,"") | M50: =IFERROR(H50/D50*1000,"") | N50: 43 | O50: =IFERROR(IF(OR(N50="",ISBLANK(INDIRECT("'"&$Q$2&"'!N"&ROW()))),"",N50-INDIRECT("'"&$Q$2&"'!N"&ROW())),"") | S50: =IFERROR(IF(ISBLANK(INDIRECT("'"&$Q$2&"'!G"&ROW())),"",INDIRECT("'"&$Q$2&"'!G"&ROW())),"") | T50: =IF(OR($G50="",$S50=""),"",$G50-$S50) | U50: =IFERROR(IF(ISBLANK(INDIRECT("'"&$Q$2&"'!K"&ROW())),"",INDIRECT("'"&$Q$2&"'!K"&ROW())),"") | V50: =IF(OR($K50="",$U50=""),"",$K50-$U50) | W50: =IFERROR(IF(ISBLANK(INDIRECT("'"&$Q$2&"'!O"&ROW())),"",INDIRECT("'"&$Q$2&"'!O"&ROW())),"") | X50: =IF(OR($O50="",$W50=""),"",$O50-$W50)
B51: Итого Одноклассники | C51: =SUM(C31:C50) | D51: =SUM(D31:D50) | E51: =SUM(E31:E50) | F51: =SUM(F31:F50) | G51: =IF(C51=0,"",IFERROR(F51/E51,"")) | H51: =SUM(H31:H50) | I51: =SUM(I31:I50) | J51: =SUM(J31:J50) | K51: =IF(C51=0,"",IFERROR(J51/I51,"")) | L51: =IFERROR(D51/C51,"") | M51: =IFERROR(H51/D51*1000,"") | N51: =SUM(N31:N50) | O51: =SUM(O31:O50) | S51: =IFERROR(IF(ISBLANK(INDIRECT("'"&$Q$2&"'!G"&ROW())),"",INDIRECT("'"&$Q$2&"'!G"&ROW())),"") | T51: =IF(OR($G51="",$S51=""),"",$G51-$S51) | U51: =IFERROR(IF(ISBLANK(INDIRECT("'"&$Q$2&"'!K"&ROW())),"",INDIRECT("'"&$Q$2&"'!K"&ROW())),"") | V51: =IF(OR($K51="",$U51=""),"",$K51-$U51) | W51: =IFERROR(IF(ISBLANK(INDIRECT("'"&$Q$2&"'!O"&ROW())),"",INDIRECT("'"&$Q$2&"'!O"&ROW())),"") | X51: =IF(OR(C51=0,$O51="",$W51=""),"",$O51-$W51)
A52: Telegram | B52: Ямал-Медиа | C52: 140 | D52: 57464 | E52: =IF($D52="","",IFERROR(IF(ISBLANK(INDIRECT("'"&$Q$2&"'!D"&ROW())),"",INDIRECT("'"&$Q$2&"'!D"&ROW())),"")) | F52: =IF(OR(D52="",E52=""),"",D52-E52) | G52: =IFERROR(F52/E52,"") | H52: 262 | I52: =IF($H52="","",IFERROR(IF(ISBLANK(INDIRECT("'"&$Q$2&"'!H"&ROW())),"",INDIRECT("'"&$Q$2&"'!H"&ROW())),"")) | J52: =IF(OR(H52="",I52=""),"",H52-I52) | K52: =IFERROR(J52/I52,"") | L52: =IFERROR(D52/C52,"") | M52: =IFERROR(H52/D52*1000,"") | N52: 11741 | O52: =IFERROR(IF(OR(N52="",ISBLANK(INDIRECT("'"&$Q$2&"'!N"&ROW()))),"",N52-INDIRECT("'"&$Q$2&"'!N"&ROW())),"") | S52: =IFERROR(IF(ISBLANK(INDIRECT("'"&$Q$2&"'!G"&ROW())),"",INDIRECT("'"&$Q$2&"'!G"&ROW())),"") | T52: =IF(OR($G52="",$S52=""),"",$G52-$S52) | U52: =IFERROR(IF(ISBLANK(INDIRECT("'"&$Q$2&"'!K"&ROW())),"",INDIRECT("'"&$Q$2&"'!K"&ROW())),"") | V52: =IF(OR($K52="",$U52=""),"",$K52-$U52) | W52: =IFERROR(IF(ISBLANK(INDIRECT("'"&$Q$2&"'!O"&ROW())),"",INDIRECT("'"&$Q$2&"'!O"&ROW())),"") | X52: =IF(OR($O52="",$W52=""),"",$O52-$W52)
A53: Telegram | B53: Север-Пресс | C53: 135 | D53: 43678 | E53: =IF($D53="","",IFERROR(IF(ISBLANK(INDIRECT("'"&$Q$2&"'!D"&ROW())),"",INDIRECT("'"&$Q$2&"'!D"&ROW())),"")) | F53: =IF(OR(D53="",E53=""),"",D53-E53) | G53: =IFERROR(F53/E53,"") | H53: 41 | I53: =IF($H53="","",IFERROR(IF(ISBLANK(INDIRECT("'"&$Q$2&"'!H"&ROW())),"",INDIRECT("'"&$Q$2&"'!H"&ROW())),"")) | J53: =IF(OR(H53="",I53=""),"",H53-I53) | K53: =IFERROR(J53/I53,"") | L53: =IFERROR(D53/C53,"") | M53: =IFERROR(H53/D53*1000,"") | N53: 4790 | O53: =IFERROR(IF(OR(N53="",ISBLANK(INDIRECT("'"&$Q$2&"'!N"&ROW()))),"",N53-INDIRECT("'"&$Q$2&"'!N"&ROW())),"") | S53: =IFERROR(IF(ISBLANK(INDIRECT("'"&$Q$2&"'!G"&ROW())),"",INDIRECT("'"&$Q$2&"'!G"&ROW())),"") | T53: =IF(OR($G53="",$S53=""),"",$G53-$S53) | U53: =IFERROR(IF(ISBLANK(INDIRECT("'"&$Q$2&"'!K"&ROW())),"",INDIRECT("'"&$Q$2&"'!K"&ROW())),"") | V53: =IF(OR($K53="",$U53=""),"",$K53-$U53) | W53: =IFERROR(IF(ISBLANK(INDIRECT("'"&$Q$2&"'!O"&ROW())),"",INDIRECT("'"&$Q$2&"'!O"&ROW())),"") | X53: =IF(OR($O53="",$W53=""),"",$O53-$W53)
A54: Telegram | B54: Красный Север | C54: 85 | D54: 1927 | E54: =IF($D54="","",IFERROR(IF(ISBLANK(INDIRECT("'"&$Q$2&"'!D"&ROW())),"",INDIRECT("'"&$Q$2&"'!D"&ROW())),"")) | F54: =IF(OR(D54="",E54=""),"",D54-E54) | G54: =IFERROR(F54/E54,"") | H54: 2 | I54: =IF($H54="","",IFERROR(IF(ISBLANK(INDIRECT("'"&$Q$2&"'!H"&ROW())),"",INDIRECT("'"&$Q$2&"'!H"&ROW())),"")) | J54: =IF(OR(H54="",I54=""),"",H54-I54) | K54: =IFERROR(J54/I54,"") | L54: =IFERROR(D54/C54,"") | M54: =IFERROR(H54/D54*1000,"") | N54: 868 | O54: =IFERROR(IF(OR(N54="",ISBLANK(INDIRECT("'"&$Q$2&"'!N"&ROW()))),"",N54-INDIRECT("'"&$Q$2&"'!N"&ROW())),"") | S54: =IFERROR(IF(ISBLANK(INDIRECT("'"&$Q$2&"'!G"&ROW())),"",INDIRECT("'"&$Q$2&"'!G"&ROW())),"") | T54: =IF(OR($G54="",$S54=""),"",$G54-$S54) | U54: =IFERROR(IF(ISBLANK(INDIRECT("'"&$Q$2&"'!K"&ROW())),"",INDIRECT("'"&$Q$2&"'!K"&ROW())),"") | V54: =IF(OR($K54="",$U54=""),"",$K54-$U54) | W54: =IFERROR(IF(ISBLANK(INDIRECT("'"&$Q$2&"'!O"&ROW())),"",INDIRECT("'"&$Q$2&"'!O"&ROW())),"") | X54: =IF(OR($O54="",$W54=""),"",$O54-$W54)
A55: Telegram | B55: СМП | C55: 9 | D55: 6726 | E55: =IF($D55="","",IFERROR(IF(ISBLANK(INDIRECT("'"&$Q$2&"'!D"&ROW())),"",INDIRECT("'"&$Q$2&"'!D"&ROW())),"")) | F55: =IF(OR(D55="",E55=""),"",D55-E55) | G55: =IFERROR(F55/E55,"") | H55: 28 | I55: =IF($H55="","",IFERROR(IF(ISBLANK(INDIRECT("'"&$Q$2&"'!H"&ROW())),"",INDIRECT("'"&$Q$2&"'!H"&ROW())),"")) | J55: =IF(OR(H55="",I55=""),"",H55-I55) | K55: =IFERROR(J55/I55,"") | L55: =IFERROR(D55/C55,"") | M55: =IFERROR(H55/D55*1000,"") | N55: 13804 | O55: =IFERROR(IF(OR(N55="",ISBLANK(INDIRECT("'"&$Q$2&"'!N"&ROW()))),"",N55-INDIRECT("'"&$Q$2&"'!N"&ROW())),"") | S55: =IFERROR(IF(ISBLANK(INDIRECT("'"&$Q$2&"'!G"&ROW())),"",INDIRECT("'"&$Q$2&"'!G"&ROW())),"") | T55: =IF(OR($G55="",$S55=""),"",$G55-$S55) | U55: =IFERROR(IF(ISBLANK(INDIRECT("'"&$Q$2&"'!K"&ROW())),"",INDIRECT("'"&$Q$2&"'!K"&ROW())),"") | V55: =IF(OR($K55="",$U55=""),"",$K55-$U55) | W55: =IFERROR(IF(ISBLANK(INDIRECT("'"&$Q$2&"'!O"&ROW())),"",INDIRECT("'"&$Q$2&"'!O"&ROW())),"") | X55: =IF(OR($O55="",$W55=""),"",$O55-$W55)
A56: Telegram | B56: СШХ | C56: 10 | D56: 2676 | E56: =IF($D56="","",IFERROR(IF(ISBLANK(INDIRECT("'"&$Q$2&"'!D"&ROW())),"",INDIRECT("'"&$Q$2&"'!D"&ROW())),"")) | F56: =IF(OR(D56="",E56=""),"",D56-E56) | G56: =IFERROR(F56/E56,"") | H56: 24 | I56: =IF($H56="","",IFERROR(IF(ISBLANK(INDIRECT("'"&$Q$2&"'!H"&ROW())),"",INDIRECT("'"&$Q$2&"'!H"&ROW())),"")) | J56: =IF(OR(H56="",I56=""),"",H56-I56) | K56: =IFERROR(J56/I56,"") | L56: =IFERROR(D56/C56,"") | M56: =IFERROR(H56/D56*1000,"") | N56: 8653 | O56: =IFERROR(IF(OR(N56="",ISBLANK(INDIRECT("'"&$Q$2&"'!N"&ROW()))),"",N56-INDIRECT("'"&$Q$2&"'!N"&ROW())),"") | S56: =IFERROR(IF(ISBLANK(INDIRECT("'"&$Q$2&"'!G"&ROW())),"",INDIRECT("'"&$Q$2&"'!G"&ROW())),"") | T56: =IF(OR($G56="",$S56=""),"",$G56-$S56) | U56: =IFERROR(IF(ISBLANK(INDIRECT("'"&$Q$2&"'!K"&ROW())),"",INDIRECT("'"&$Q$2&"'!K"&ROW())),"") | V56: =IF(OR($K56="",$U56=""),"",$K56-$U56) | W56: =IFERROR(IF(ISBLANK(INDIRECT("'"&$Q$2&"'!O"&ROW())),"",INDIRECT("'"&$Q$2&"'!O"&ROW())),"") | X56: =IF(OR($O56="",$W56=""),"",$O56-$W56)
A57: Telegram | B57: Новый Уренгой | C57: 103 | D57: 53833 | E57: =IF($D57="","",IFERROR(IF(ISBLANK(INDIRECT("'"&$Q$2&"'!D"&ROW())),"",INDIRECT("'"&$Q$2&"'!D"&ROW())),"")) | F57: =IF(OR(D57="",E57=""),"",D57-E57) | G57: =IFERROR(F57/E57,"") | H57: 201 | I57: =IF($H57="","",IFERROR(IF(ISBLANK(INDIRECT("'"&$Q$2&"'!H"&ROW())),"",INDIRECT("'"&$Q$2&"'!H"&ROW())),"")) | J57: =IF(OR(H57="",I57=""),"",H57-I57) | K57: =IFERROR(J57/I57,"") | L57: =IFERROR(D57/C57,"") | M57: =IFERROR(H57/D57*1000,"") | N57: 10864 | O57: =IFERROR(IF(OR(N57="",ISBLANK(INDIRECT("'"&$Q$2&"'!N"&ROW()))),"",N57-INDIRECT("'"&$Q$2&"'!N"&ROW())),"") | S57: =IFERROR(IF(ISBLANK(INDIRECT("'"&$Q$2&"'!G"&ROW())),"",INDIRECT("'"&$Q$2&"'!G"&ROW())),"") | T57: =IF(OR($G57="",$S57=""),"",$G57-$S57) | U57: =IFERROR(IF(ISBLANK(INDIRECT("'"&$Q$2&"'!K"&ROW())),"",INDIRECT("'"&$Q$2&"'!K"&ROW())),"") | V57: =IF(OR($K57="",$U57=""),"",$K57-$U57) | W57: =IFERROR(IF(ISBLANK(INDIRECT("'"&$Q$2&"'!O"&ROW())),"",INDIRECT("'"&$Q$2&"'!O"&ROW())),"") | X57: =IF(OR($O57="",$W57=""),"",$O57-$W57)
A58: Telegram | B58: Надым | C58: 82 | D58: 18052 | E58: =IF($D58="","",IFERROR(IF(ISBLANK(INDIRECT("'"&$Q$2&"'!D"&ROW())),"",INDIRECT("'"&$Q$2&"'!D"&ROW())),"")) | F58: =IF(OR(D58="",E58=""),"",D58-E58) | G58: =IFERROR(F58/E58,"") | H58: 315 | I58: =IF($H58="","",IFERROR(IF(ISBLANK(INDIRECT("'"&$Q$2&"'!H"&ROW())),"",INDIRECT("'"&$Q$2&"'!H"&ROW())),"")) | J58: =IF(OR(H58="",I58=""),"",H58-I58) | K58: =IFERROR(J58/I58,"") | L58: =IFERROR(D58/C58,"") | M58: =IFERROR(H58/D58*1000,"") | N58: 4095 | O58: =IFERROR(IF(OR(N58="",ISBLANK(INDIRECT("'"&$Q$2&"'!N"&ROW()))),"",N58-INDIRECT("'"&$Q$2&"'!N"&ROW())),"") | S58: =IFERROR(IF(ISBLANK(INDIRECT("'"&$Q$2&"'!G"&ROW())),"",INDIRECT("'"&$Q$2&"'!G"&ROW())),"") | T58: =IF(OR($G58="",$S58=""),"",$G58-$S58) | U58: =IFERROR(IF(ISBLANK(INDIRECT("'"&$Q$2&"'!K"&ROW())),"",INDIRECT("'"&$Q$2&"'!K"&ROW())),"") | V58: =IF(OR($K58="",$U58=""),"",$K58-$U58) | W58: =IFERROR(IF(ISBLANK(INDIRECT("'"&$Q$2&"'!O"&ROW())),"",INDIRECT("'"&$Q$2&"'!O"&ROW())),"") | X58: =IF(OR($O58="",$W58=""),"",$O58-$W58)
A59: Telegram | B59: Ноябрьск | C59: 91 | D59: 29628 | E59: =IF($D59="","",IFERROR(IF(ISBLANK(INDIRECT("'"&$Q$2&"'!D"&ROW())),"",INDIRECT("'"&$Q$2&"'!D"&ROW())),"")) | F59: =IF(OR(D59="",E59=""),"",D59-E59) | G59: =IFERROR(F59/E59,"") | H59: 148 | I59: =IF($H59="","",IFERROR(IF(ISBLANK(INDIRECT("'"&$Q$2&"'!H"&ROW())),"",INDIRECT("'"&$Q$2&"'!H"&ROW())),"")) | J59: =IF(OR(H59="",I59=""),"",H59-I59) | K59: =IFERROR(J59/I59,"") | L59: =IFERROR(D59/C59,"") | M59: =IFERROR(H59/D59*1000,"") | N59: 5504 | O59: =IFERROR(IF(OR(N59="",ISBLANK(INDIRECT("'"&$Q$2&"'!N"&ROW()))),"",N59-INDIRECT("'"&$Q$2&"'!N"&ROW())),"") | S59: =IFERROR(IF(ISBLANK(INDIRECT("'"&$Q$2&"'!G"&ROW())),"",INDIRECT("'"&$Q$2&"'!G"&ROW())),"") | T59: =IF(OR($G59="",$S59=""),"",$G59-$S59) | U59: =IFERROR(IF(ISBLANK(INDIRECT("'"&$Q$2&"'!K"&ROW())),"",INDIRECT("'"&$Q$2&"'!K"&ROW())),"") | V59: =IF(OR($K59="",$U59=""),"",$K59-$U59) | W59: =IFERROR(IF(ISBLANK(INDIRECT("'"&$Q$2&"'!O"&ROW())),"",INDIRECT("'"&$Q$2&"'!O"&ROW())),"") | X59: =IF(OR($O59="",$W59=""),"",$O59-$W59)
...

Sheet 21-27.09
A1: Недельный съём · 21–27.09.2026 | Q1: Лист прошлой недели (питает колонки E, I, O):
A2: Площадка | B2: Ресурс | C2: Публикаций | D2: Просмотры | E2: Просмотры пред. неделя | F2: Δ просмотров | G2: Δ % | H2: Лайки | I2: Лайки пред. неделя | J2: Δ лайков | K2: Δ % | L2: Ср. просмотров на пост | M2: Лайков на 1000 просмотров | N2: Подписчики | O2: Прирост подписчиков | Q2: 14-20.09 | S2: Δ % просмотров пред. неделя | T2: Ускорение просмотров, п.п. | U2: Δ % лайков пред. неделя | V2: Ускорение лайков, п.п. | W2: Прирост подписч. пред. неделя | X2: Ускорение подписчиков, чел.
A3: ВКонтакте | B3: Ямал-Медиа | C3: 114 | D3: 1913477 | E3: =IF($D3="","",IFERROR(IF(ISBLANK(INDIRECT("'"&$Q$2&"'!D"&ROW())),"",INDIRECT("'"&$Q$2&"'!D"&ROW())),"")) | F3: =IF(OR(D3="",E3=""),"",D3-E3) | G3: =IFERROR(F3/E3,"") | H3: 4474 | I3: =IF($H3="","",IFERROR(IF(ISBLANK(INDIRECT("'"&$Q$2&"'!H"&ROW())),"",INDIRECT("'"&$Q$2&"'!H"&ROW())),"")) | J3: =IF(OR(H3="",I3=""),"",H3-I3) | K3: =IFERROR(J3/I3,"") | L3: =IFERROR(D3/C3,"") | M3: =IFERROR(H3/D3*1000,"") | N3: 89358 | O3: =IFERROR(IF(OR(N3="",ISBLANK(INDIRECT("'"&$Q$2&"'!N"&ROW()))),"",N3-INDIRECT("'"&$Q$2&"'!N"&ROW())),"") | Q3: Колонки E и I берут прошлую неделю только по строкам, снятым в текущей — сравнение идёт по сопоставимому периметру. | S3: =IFERROR(IF(ISBLANK(INDIRECT("'"&$Q$2&"'!G"&ROW())),"",INDIRECT("'"&$Q$2&"'!G"&ROW())),"") | T3: =IF(OR($G3="",$S3=""),"",$G3-$S3) | U3: =IFERROR(IF(ISBLANK(INDIRECT("'"&$Q$2&"'!K"&ROW())),"",INDIRECT("'"&$Q$2&"'!K"&ROW())),"") | V3: =IF(OR($K3="",$U3=""),"",$K3-$U3) | W3: =IFERROR(IF(ISBLANK(INDIRECT("'"&$Q$2&"'!O"&ROW())),"",INDIRECT("'"&$Q$2&"'!O"&ROW())),"") | X3: =IF(OR($O3="",$W3=""),"",$O3-$W3)
A4: ВКонтакте | B4: Север-Пресс | C4: 129 | D4: 126444 | E4: =IF($D4="","",IFERROR(IF(ISBLANK(INDIRECT("'"&$Q$2&"'!D"&ROW())),"",INDIRECT("'"&$Q$2&"'!D"&ROW())),"")) | F4: =IF(OR(D4="",E4=""),"",D4-E4) | G4: =IFERROR(F4/E4,"") | H4: 528 | I4: =IF($H4="","",IFERROR(IF(ISBLANK(INDIRECT("'"&$Q$2&"'!H"&ROW())),"",INDIRECT("'"&$Q$2&"'!H"&ROW())),"")) | J4: =IF(OR(H4="",I4=""),"",H4-I4) | K4: =IFERROR(J4/I4,"") | L4: =IFERROR(D4/C4,"") | M4: =IFERROR(H4/D4*1000,"") | N4: 26260 | O4: =IFERROR(IF(OR(N4="",ISBLANK(INDIRECT("'"&$Q$2&"'!N"&ROW()))),"",N4-INDIRECT("'"&$Q$2&"'!N"&ROW())),"") | Q4: ОК: «просмотры» = VIEWS листа Topics, лайки = сумма LIKES листа Actions (по группе, как в прошлых съёмах). | S4: =IFERROR(IF(ISBLANK(INDIRECT("'"&$Q$2&"'!G"&ROW())),"",INDIRECT("'"&$Q$2&"'!G"&ROW())),"") | T4: =IF(OR($G4="",$S4=""),"",$G4-$S4) | U4: =IFERROR(IF(ISBLANK(INDIRECT("'"&$Q$2&"'!K"&ROW())),"",INDIRECT("'"&$Q$2&"'!K"&ROW())),"") | V4: =IF(OR($K4="",$U4=""),"",$K4-$U4) | W4: =IFERROR(IF(ISBLANK(INDIRECT("'"&$Q$2&"'!O"&ROW())),"",INDIRECT("'"&$Q$2&"'!O"&ROW())),"") | X4: =IF(OR($O4="",$W4=""),"",$O4-$W4)
A5: ВКонтакте | B5: Лента СП | C5: 243 | D5: 3977 | E5: =IF($D5="","",IFERROR(IF(ISBLANK(INDIRECT("'"&$Q$2&"'!D"&ROW())),"",INDIRECT("'"&$Q$2&"'!D"&ROW())),"")) | F5: =IF(OR(D5="",E5=""),"",D5-E5) | G5: =IFERROR(F5/E5,"") | H5: 12 | I5: =IF($H5="","",IFERROR(IF(ISBLANK(INDIRECT("'"&$Q$2&"'!H"&ROW())),"",INDIRECT("'"&$Q$2&"'!H"&ROW())),"")) | J5: =IF(OR(H5="",I5=""),"",H5-I5) | K5: =IFERROR(J5/I5,"") | L5: =IFERROR(D5/C5,"") | M5: =IFERROR(H5/D5*1000,"") | N5: 3500 | O5: =IFERROR(IF(OR(N5="",ISBLANK(INDIRECT("'"&$Q$2&"'!N"&ROW()))),"",N5-INDIRECT("'"&$Q$2&"'!N"&ROW())),"") | S5: =IFERROR(IF(ISBLANK(INDIRECT("'"&$Q$2&"'!G"&ROW())),"",INDIRECT("'"&$Q$2&"'!G"&ROW())),"") | T5: =IF(OR($G5="",$S5=""),"",$G5-$S5) | U5: =IFERROR(IF(ISBLANK(INDIRECT("'"&$Q$2&"'!K"&ROW())),"",INDIRECT("'"&$Q$2&"'!K"&ROW())),"") | V5: =IF(OR($K5="",$U5=""),"",$K5-$U5) | W5: =IFERROR(IF(ISBLANK(INDIRECT("'"&$Q$2&"'!O"&ROW())),"",INDIRECT("'"&$Q$2&"'!O"&ROW())),"") | X5: =IF(OR($O5="",$W5=""),"",$O5-$W5)
A6: ВКонтакте | B6: Красный Север | C6: 87 | D6: 63285 | E6: =IF($D6="","",IFERROR(IF(ISBLANK(INDIRECT("'"&$Q$2&"'!D"&ROW())),"",INDIRECT("'"&$Q$2&"'!D"&ROW())),"")) | F6: =IF(OR(D6="",E6=""),"",D6-E6) | G6: =IFERROR(F6/E6,"") | H6: 343 | I6: =IF($H6="","",IFERROR(IF(ISBLANK(INDIRECT("'"&$Q$2&"'!H"&ROW())),"",INDIRECT("'"&$Q$2&"'!H"&ROW())),"")) | J6: =IF(OR(H6="",I6=""),"",H6-I6) | K6: =IFERROR(J6/I6,"") | L6: =IFERROR(D6/C6,"") | M6: =IFERROR(H6/D6*1000,"") | N6: 22932 | O6: =IFERROR(IF(OR(N6="",ISBLANK(INDIRECT("'"&$Q$2&"'!N"&ROW()))),"",N6-INDIRECT("'"&$Q$2&"'!N"&ROW())),"") | S6: =IFERROR(IF(ISBLANK(INDIRECT("'"&$Q$2&"'!G"&ROW())),"",INDIRECT("'"&$Q$2&"'!G"&ROW())),"") | T6: =IF(OR($G6="",$S6=""),"",$G6-$S6) | U6: =IFERROR(IF(ISBLANK(INDIRECT("'"&$Q$2&"'!K"&ROW())),"",INDIRECT("'"&$Q$2&"'!K"&ROW())),"") | V6: =IF(OR($K6="",$U6=""),"",$K6-$U6) | W6: =IFERROR(IF(ISBLANK(INDIRECT("'"&$Q$2&"'!O"&ROW())),"",INDIRECT("'"&$Q$2&"'!O"&ROW())),"") | X6: =IF(OR($O6="",$W6=""),"",$O6-$W6)
A7: ВКонтакте | B7: Новый Уренгой | C7: 98 | D7: 78870 | E7: =IF($D7="","",IFERROR(IF(ISBLANK(INDIRECT("'"&$Q$2&"'!D"&ROW())),"",INDIRECT("'"&$Q$2&"'!D"&ROW())),"")) | F7: =IF(OR(D7="",E7=""),"",D7-E7) | G7: =IFERROR(F7/E7,"") | H7: 796 | I7: =IF($H7="","",IFERROR(IF(ISBLANK(INDIRECT("'"&$Q$2&"'!H"&ROW())),"",INDIRECT("'"&$Q$2&"'!H"&ROW())),"")) | J7: =IF(OR(H7="",I7=""),"",H7-I7) | K7: =IFERROR(J7/I7,"") | L7: =IFERROR(D7/C7,"") | M7: =IFERROR(H7/D7*1000,"") | N7: 24868 | O7: =IFERROR(IF(OR(N7="",ISBLANK(INDIRECT("'"&$Q$2&"'!N"&ROW()))),"",N7-INDIRECT("'"&$Q$2&"'!N"&ROW())),"") | S7: =IFERROR(IF(ISBLANK(INDIRECT("'"&$Q$2&"'!G"&ROW())),"",INDIRECT("'"&$Q$2&"'!G"&ROW())),"") | T7: =IF(OR($G7="",$S7=""),"",$G7-$S7) | U7: =IFERROR(IF(ISBLANK(INDIRECT("'"&$Q$2&"'!K"&ROW())),"",INDIRECT("'"&$Q$2&"'!K"&ROW())),"") | V7: =IF(OR($K7="",$U7=""),"",$K7-$U7) | W7: =IFERROR(IF(ISBLANK(INDIRECT("'"&$Q$2&"'!O"&ROW())),"",INDIRECT("'"&$Q$2&"'!O"&ROW())),"") | X7: =IF(OR($O7="",$W7=""),"",$O7-$W7)
A8: ВКонтакте | B8: Надым | C8: 87 | D8: 296983 | E8: =IF($D8="","",IFERROR(IF(ISBLANK(INDIRECT("'"&$Q$2&"'!D"&ROW())),"",INDIRECT("'"&$Q$2&"'!D"&ROW())),"")) | F8: =IF(OR(D8="",E8=""),"",D8-E8) | G8: =IFERROR(F8/E8,"") | H8: 3566 | I8: =IF($H8="","",IFERROR(IF(ISBLANK(INDIRECT("'"&$Q$2&"'!H"&ROW())),"",INDIRECT("'"&$Q$2&"'!H"&ROW())),"")) | J8: =IF(OR(H8="",I8=""),"",H8-I8) | K8: =IFERROR(J8/I8,"") | L8: =IFERROR(D8/C8,"") | M8: =IFERROR(H8/D8*1000,"") | N8: 21744 | O8: =IFERROR(IF(OR(N8="",ISBLANK(INDIRECT("'"&$Q$2&"'!N"&ROW()))),"",N8-INDIRECT("'"&$Q$2&"'!N"&ROW())),"") | S8: =IFERROR(IF(ISBLANK(INDIRECT("'"&$Q$2&"'!G"&ROW())),"",INDIRECT("'"&$Q$2&"'!G"&ROW())),"") | T8: =IF(OR($G8="",$S8=""),"",$G8-$S8) | U8: =IFERROR(IF(ISBLANK(INDIRECT("'"&$Q$2&"'!K"&ROW())),"",INDIRECT("'"&$Q$2&"'!K"&ROW())),"") | V8: =IF(OR($K8="",$U8=""),"",$K8-$U8) | W8: =IFERROR(IF(ISBLANK(INDIRECT("'"&$Q$2&"'!O"&ROW())),"",INDIRECT("'"&$Q$2&"'!O"&ROW())),"") | X8: =IF(OR($O8="",$W8=""),"",$O8-$W8)
A9: ВКонтакте | B9: Ноябрьск | C9: 96 | D9: 322545 | E9: =IF($D9="","",IFERROR(IF(ISBLANK(INDIRECT("'"&$Q$2&"'!D"&ROW())),"",INDIRECT("'"&$Q$2&"'!D"&ROW())),"")) | F9: =IF(OR(D9="",E9=""),"",D9-E9) | G9: =IFERROR(F9/E9,"") | H9: 4156 | I9: =IF($H9="","",IFERROR(IF(ISBLANK(INDIRECT("'"&$Q$2&"'!H"&ROW())),"",INDIRECT("'"&$Q$2&"'!H"&ROW())),"")) | J9: =IF(OR(H9="",I9=""),"",H9-I9) | K9: =IFERROR(J9/I9,"") | L9: =IFERROR(D9/C9,"") | M9: =IFERROR(H9/D9*1000,"") | N9: 31330 | O9: =IFERROR(IF(OR(N9="",ISBLANK(INDIRECT("'"&$Q$2&"'!N"&ROW()))),"",N9-INDIRECT("'"&$Q$2&"'!N"&ROW())),"") | S9: =IFERROR(IF(ISBLANK(INDIRECT("'"&$Q$2&"'!G"&ROW())),"",INDIRECT("'"&$Q$2&"'!G"&ROW())),"") | T9: =IF(OR($G9="",$S9=""),"",$G9-$S9) | U9: =IFERROR(IF(ISBLANK(INDIRECT("'"&$Q$2&"'!K"&ROW())),"",INDIRECT("'"&$Q$2&"'!K"&ROW())),"") | V9: =IF(OR($K9="",$U9=""),"",$K9-$U9) | W9: =IFERROR(IF(ISBLANK(INDIRECT("'"&$Q$2&"'!O"&ROW())),"",INDIRECT("'"&$Q$2&"'!O"&ROW())),"") | X9: =IF(OR($O9="",$W9=""),"",$O9-$W9)
A10: ВКонтакте | B10: Салехард | C10: 135 | D10: 167913 | E10: =IF($D10="","",IFERROR(IF(ISBLANK(INDIRECT("'"&$Q$2&"'!D"&ROW())),"",INDIRECT("'"&$Q$2&"'!D"&ROW())),"")) | F10: =IF(OR(D10="",E10=""),"",D10-E10) | G10: =IFERROR(F10/E10,"") | H10: 1192 | I10: =IF($H10="","",IFERROR(IF(ISBLANK(INDIRECT("'"&$Q$2&"'!H"&ROW())),"",INDIRECT("'"&$Q$2&"'!H"&ROW())),"")) | J10: =IF(OR(H10="",I10=""),"",H10-I10) | K10: =IFERROR(J10/I10,"") | L10: =IFERROR(D10/C10,"") | M10: =IFERROR(H10/D10*1000,"") | N10: 21586 | O10: =IFERROR(IF(OR(N10="",ISBLANK(INDIRECT("'"&$Q$2&"'!N"&ROW()))),"",N10-INDIRECT("'"&$Q$2&"'!N"&ROW())),"") | S10: =IFERROR(IF(ISBLANK(INDIRECT("'"&$Q$2&"'!G"&ROW())),"",INDIRECT("'"&$Q$2&"'!G"&ROW())),"") | T10: =IF(OR($G10="",$S10=""),"",$G10-$S10) | U10: =IFERROR(IF(ISBLANK(INDIRECT("'"&$Q$2&"'!K"&ROW())),"",INDIRECT("'"&$Q$2&"'!K"&ROW())),"") | V10: =IF(OR($K10="",$U10=""),"",$K10-$U10) | W10: =IFERROR(IF(ISBLANK(INDIRECT("'"&$Q$2&"'!O"&ROW())),"",INDIRECT("'"&$Q$2&"'!O"&ROW())),"") | X10: =IF(OR($O10="",$W10=""),"",$O10-$W10)
A11: ВКонтакте | B11: Приуралье | C11: 106 | D11: 407601 | E11: =IF($D11="","",IFERROR(IF(ISBLANK(INDIRECT("'"&$Q$2&"'!D"&ROW())),"",INDIRECT("'"&$Q$2&"'!D"&ROW())),"")) | F11: =IF(OR(D11="",E11=""),"",D11-E11) | G11: =IFERROR(F11/E11,"") | H11: 3694 | I11: =IF($H11="","",IFERROR(IF(ISBLANK(INDIRECT("'"&$Q$2&"'!H"&ROW())),"",INDIRECT("'"&$Q$2&"'!H"&ROW())),"")) | J11: =IF(OR(H11="",I11=""),"",H11-I11) | K11: =IFERROR(J11/I11,"") | L11: =IFERROR(D11/C11,"") | M11: =IFERROR(H11/D11*1000,"") | N11: 20797 | O11: =IFERROR(IF(OR(N11="",ISBLANK(INDIRECT("'"&$Q$2&"'!N"&ROW()))),"",N11-INDIRECT("'"&$Q$2&"'!N"&ROW())),"") | S11: =IFERROR(IF(ISBLANK(INDIRECT("'"&$Q$2&"'!G"&ROW())),"",INDIRECT("'"&$Q$2&"'!G"&ROW())),"") | T11: =IF(OR($G11="",$S11=""),"",$G11-$S11) | U11: =IFERROR(IF(ISBLANK(INDIRECT("'"&$Q$2&"'!K"&ROW())),"",INDIRECT("'"&$Q$2&"'!K"&ROW())),"") | V11: =IF(OR($K11="",$U11=""),"",$K11-$U11) | W11: =IFERROR(IF(ISBLANK(INDIRECT("'"&$Q$2&"'!O"&ROW())),"",INDIRECT("'"&$Q$2&"'!O"&ROW())),"") | X11: =IF(OR($O11="",$W11=""),"",$O11-$W11)
A12: ВКонтакте | B12: Лабытнанги | C12: 66 | D12: 111561 | E12: =IF($D12="","",IFERROR(IF(ISBLANK(INDIRECT("'"&$Q$2&"'!D"&ROW())),"",INDIRECT("'"&$Q$2&"'!D"&ROW())),"")) | F12: =IF(OR(D12="",E12=""),"",D12-E12) | G12: =IFERROR(F12/E12,"") | H12: 1930 | I12: =IF($H12="","",IFERROR(IF(ISBLANK(INDIRECT("'"&$Q$2&"'!H"&ROW())),"",INDIRECT("'"&$Q$2&"'!H"&ROW())),"")) | J12: =IF(OR(H12="",I12=""),"",H12-I12) | K12: =IFERROR(J12/I12,"") | L12: =IFERROR(D12/C12,"") | M12: =IFERROR(H12/D12*1000,"") | N12: 15498 | O12: =IFERROR(IF(OR(N12="",ISBLANK(INDIRECT("'"&$Q$2&"'!N"&ROW()))),"",N12-INDIRECT("'"&$Q$2&"'!N"&ROW())),"") | S12: =IFERROR(IF(ISBLANK(INDIRECT("'"&$Q$2&"'!G"&ROW())),"",INDIRECT("'"&$Q$2&"'!G"&ROW())),"") | T12: =IF(OR($G12="",$S12=""),"",$G12-$S12) | U12: =IFERROR(IF(ISBLANK(INDIRECT("'"&$Q$2&"'!K"&ROW())),"",INDIRECT("'"&$Q$2&"'!K"&ROW())),"") | V12: =IF(OR($K12="",$U12=""),"",$K12-$U12) | W12: =IFERROR(IF(ISBLANK(INDIRECT("'"&$Q$2&"'!O"&ROW())),"",INDIRECT("'"&$Q$2&"'!O"&ROW())),"") | X12: =IF(OR($O12="",$W12=""),"",$O12-$W12)
A13: ВКонтакте | B13: Пуровский | C13: 49 | D13: 33284 | E13: =IF($D13="","",IFERROR(IF(ISBLANK(INDIRECT("'"&$Q$2&"'!D"&ROW())),"",INDIRECT("'"&$Q$2&"'!D"&ROW())),"")) | F13: =IF(OR(D13="",E13=""),"",D13-E13) | G13: =IFERROR(F13/E13,"") | H13: 353 | I13: =IF($H13="","",IFERROR(IF(ISBLANK(INDIRECT("'"&$Q$2&"'!H"&ROW())),"",INDIRECT("'"&$Q$2&"'!H"&ROW())),"")) | J13: =IF(OR(H13="",I13=""),"",H13-I13) | K13: =IFERROR(J13/I13,"") | L13: =IFERROR(D13/C13,"") | M13: =IFERROR(H13/D13*1000,"") | N13: 16443 | O13: =IFERROR(IF(OR(N13="",ISBLANK(INDIRECT("'"&$Q$2&"'!N"&ROW()))),"",N13-INDIRECT("'"&$Q$2&"'!N"&ROW())),"") | S13: =IFERROR(IF(ISBLANK(INDIRECT("'"&$Q$2&"'!G"&ROW())),"",INDIRECT("'"&$Q$2&"'!G"&ROW())),"") | T13: =IF(OR($G13="",$S13=""),"",$G13-$S13) | U13: =IFERROR(IF(ISBLANK(INDIRECT("'"&$Q$2&"'!K"&ROW())),"",INDIRECT("'"&$Q$2&"'!K"&ROW())),"") | V13: =IF(OR($K13="",$U13=""),"",$K13-$U13) | W13: =IFERROR(IF(ISBLANK(INDIRECT("'"&$Q$2&"'!O"&ROW())),"",INDIRECT("'"&$Q$2&"'!O"&ROW())),"") | X13: =IF(OR($O13="",$W13=""),"",$O13-$W13)
A14: ВКонтакте | B14: Тазовский | C14: 56 | D14: 48840 | E14: =IF($D14="","",IFERROR(IF(ISBLANK(INDIRECT("'"&$Q$2&"'!D"&ROW())),"",INDIRECT("'"&$Q$2&"'!D"&ROW())),"")) | F14: =IF(OR(D14="",E14=""),"",D14-E14) | G14: =IFERROR(F14/E14,"") | H14: 534 | I14: =IF($H14="","",IFERROR(IF(ISBLANK(INDIRECT("'"&$Q$2&"'!H"&ROW())),"",INDIRECT("'"&$Q$2&"'!H"&ROW())),"")) | J14: =IF(OR(H14="",I14=""),"",H14-I14) | K14: =IFERROR(J14/I14,"") | L14: =IFERROR(D14/C14,"") | M14: =IFERROR(H14/D14*1000,"") | N14: 6439 | O14: =IFERROR(IF(OR(N14="",ISBLANK(INDIRECT("'"&$Q$2&"'!N"&ROW()))),"",N14-INDIRECT("'"&$Q$2&"'!N"&ROW())),"") | S14: =IFERROR(IF(ISBLANK(INDIRECT("'"&$Q$2&"'!G"&ROW())),"",INDIRECT("'"&$Q$2&"'!G"&ROW())),"") | T14: =IF(OR($G14="",$S14=""),"",$G14-$S14) | U14: =IFERROR(IF(ISBLANK(INDIRECT("'"&$Q$2&"'!K"&ROW())),"",INDIRECT("'"&$Q$2&"'!K"&ROW())),"") | V14: =IF(OR($K14="",$U14=""),"",$K14-$U14) | W14: =IFERROR(IF(ISBLANK(INDIRECT("'"&$Q$2&"'!O"&ROW())),"",INDIRECT("'"&$Q$2&"'!O"&ROW())),"") | X14: =IF(OR($O14="",$W14=""),"",$O14-$W14)
A15: ВКонтакте | B15: Красноселькуп | C15: 29 | D15: 30735 | E15: =IF($D15="","",IFERROR(IF(ISBLANK(INDIRECT("'"&$Q$2&"'!D"&ROW())),"",INDIRECT("'"&$Q$2&"'!D"&ROW())),"")) | F15: =IF(OR(D15="",E15=""),"",D15-E15) | G15: =IFERROR(F15/E15,"") | H15: 302 | I15: =IF($H15="","",IFERROR(IF(ISBLANK(INDIRECT("'"&$Q$2&"'!H"&ROW())),"",INDIRECT("'"&$Q$2&"'!H"&ROW())),"")) | J15: =IF(OR(H15="",I15=""),"",H15-I15) | K15: =IFERROR(J15/I15,"") | L15: =IFERROR(D15/C15,"") | M15: =IFERROR(H15/D15*1000,"") | N15: 3687 | O15: =IFERROR(IF(OR(N15="",ISBLANK(INDIRECT("'"&$Q$2&"'!N"&ROW()))),"",N15-INDIRECT("'"&$Q$2&"'!N"&ROW())),"") | S15: =IFERROR(IF(ISBLANK(INDIRECT("'"&$Q$2&"'!G"&ROW())),"",INDIRECT("'"&$Q$2&"'!G"&ROW())),"") | T15: =IF(OR($G15="",$S15=""),"",$G15-$S15) | U15: =IFERROR(IF(ISBLANK(INDIRECT("'"&$Q$2&"'!K"&ROW())),"",INDIRECT("'"&$Q$2&"'!K"&ROW())),"") | V15: =IF(OR($K15="",$U15=""),"",$K15-$U15) | W15: =IFERROR(IF(ISBLANK(INDIRECT("'"&$Q$2&"'!O"&ROW())),"",INDIRECT("'"&$Q$2&"'!O"&ROW())),"") | X15: =IF(OR($O15="",$W15=""),"",$O15-$W15)
A16: ВКонтакте | B16: Ямальский | C16: 50 | D16: 99250 | E16: =IF($D16="","",IFERROR(IF(ISBLANK(INDIRECT("'"&$Q$2&"'!D"&ROW())),"",INDIRECT("'"&$Q$2&"'!D"&ROW())),"")) | F16: =IF(OR(D16="",E16=""),"",D16-E16) | G16: =IFERROR(F16/E16,"") | H16: 1001 | I16: =IF($H16="","",IFERROR(IF(ISBLANK(INDIRECT("'"&$Q$2&"'!H"&ROW())),"",INDIRECT("'"&$Q$2&"'!H"&ROW())),"")) | J16: =IF(OR(H16="",I16=""),"",H16-I16) | K16: =IFERROR(J16/I16,"") | L16: =IFERROR(D16/C16,"") | M16: =IFERROR(H16/D16*1000,"") | N16: 12813 | O16: =IFERROR(IF(OR(N16="",ISBLANK(INDIRECT("'"&$Q$2&"'!N"&ROW()))),"",N16-INDIRECT("'"&$Q$2&"'!N"&ROW())),"") | S16: =IFERROR(IF(ISBLANK(INDIRECT("'"&$Q$2&"'!G"&ROW())),"",INDIRECT("'"&$Q$2&"'!G"&ROW())),"") | T16: =IF(OR($G16="",$S16=""),"",$G16-$S16) | U16: =IFERROR(IF(ISBLANK(INDIRECT("'"&$Q$2&"'!K"&ROW())),"",INDIRECT("'"&$Q$2&"'!K"&ROW())),"") | V16: =IF(OR($K16="",$U16=""),"",$K16-$U16) | W16: =IFERROR(IF(ISBLANK(INDIRECT("'"&$Q$2&"'!O"&ROW())),"",INDIRECT("'"&$Q$2&"'!O"&ROW())),"") | X16: =IF(OR($O16="",$W16=""),"",$O16-$W16)
