Workbook

Sheet Сводка
A1: Еженедельный съём соцсетей
A2: Текущая неделя — лист: | B2: 05-11.10
A3: Прошлая неделя — лист: | B3: 28.09-04.10
A4: снято 12.10.2026 · ВК 27/27 (Барков), ТГ 22/22 (Барков), МАКС 21/21 (MaxStat), ОК 20/20 (админские выгрузки)
A6: Площадка | B6: Публикаций | C6: Просмотры | D6: Просмотры пред. неделя (сопост. периметр) | E6: Δ % | F6: Лайки | G6: Лайки пред. неделя (сопост. периметр) | H6: Δ % | I6: Лайков на 1000 просмотров | J6: Подписчики | K6: Прирост подписчиков | L6: Δ % просмотров пред. неделя | M6: Ускорение просмотров, п.п. | N6: Δ % лайков пред. неделя | O6: Ускорение лайков, п.п. | P6: Прирост подписч. пред. неделя | Q6: Ускорение подписчиков, чел.
A7: ВКонтакте | B7: {=INDIRECT("'"&$B$2&"'!C30")} -> 1808 | C7: {=IF($B7=0,"",INDIRECT("'"&$B$2&"'!D30"))} -> 4157980 | D7: {=IF($B7=0,"",INDIRECT("'"&$B$2&"'!E30"))} -> 5072194 | E7: =IF(B7=0,"",IFERROR(C7/D7-1,"")) -> -0.18024035 | F7: {=IF($B7=0,"",INDIRECT("'"&$B$2&"'!H30"))} -> 30049 | G7: {=IF($B7=0,"",INDIRECT("'"&$B$2&"'!I30"))} -> 33669 | H7: =IF(B7=0,"",IFERROR(F7/G7-1,"")) -> -0.1075173 | I7: =IFERROR(F7/C7*1000,"") -> 7.2268265 | J7: {=IF($B7=0,"",INDIRECT("'"&$B$2&"'!N30"))} -> 467357 | K7: {=IF($B7=0,"",INDIRECT("'"&$B$2&"'!O30"))} -> 1035 | L7: {=IFERROR(IF(INDIRECT("'"&$B$3&"'!G30")="","",INDIRECT("'"&$B$3&"'!G30")),"")} -> 0.18691152 | M7: =IF(OR($E7="",$L7=""),"",$E7-$L7) -> -0.36715187 | N7: {=IFERROR(IF(INDIRECT("'"&$B$3&"'!K30")="","",INDIRECT("'"&$B$3&"'!K30")),"")} -> 0.12578995 | O7: =IF(OR($H7="",$N7=""),"",$H7-$N7) -> -0.23330725 | P7: {=IFERROR(IF(INDIRECT("'"&$B$3&"'!O30")="","",INDIRECT("'"&$B$3&"'!O30")),"")} -> 1041 | Q7: =IF(OR($B7=0,$K7="",$P7=""),"",$K7-$P7) -> -6
A8: Одноклассники | B8: {=INDIRECT("'"&$B$2&"'!C51")} -> 1386 | C8: {=IF($B8=0,"",INDIRECT("'"&$B$2&"'!D51"))} -> 438012 | D8: {=IF($B8=0,"",INDIRECT("'"&$B$2&"'!E51"))} -> 244021 | E8: =IF(B8=0,"",IFERROR(C8/D8-1,"")) -> 0.79497666 | F8: {=IF($B8=0,"",INDIRECT("'"&$B$2&"'!H51"))} -> 2376 | G8: {=IF($B8=0,"",INDIRECT("'"&$B$2&"'!I51"))} -> 2293 | H8: =IF(B8=0,"",IFERROR(F8/G8-1,"")) -> 0.036197122 | I8: =IFERROR(F8/C8*1000,"") -> 5.4245089 | J8: {=IF($B8=0,"",INDIRECT("'"&$B$2&"'!N51"))} -> 107120 | K8: {=IF($B8=0,"",INDIRECT("'"&$B$2&"'!O51"))} -> 48 | L8: {=IFERROR(IF(INDIRECT("'"&$B$3&"'!G51")="","",INDIRECT("'"&$B$3&"'!G51")),"")} -> 0.072161355 | M8: =IF(OR($E8="",$L8=""),"",$E8-$L8) -> 0.72281531 | N8: {=IFERROR(IF(INDIRECT("'"&$B$3&"'!K51")="","",INDIRECT("'"&$B$3&"'!K51")),"")} -> 0.17495712 | O8: =IF(OR($H8="",$N8=""),"",$H8-$N8) -> -0.13876 | P8: {=IFERROR(IF(INDIRECT("'"&$B$3&"'!O51")="","",INDIRECT("'"&$B$3&"'!O51")),"")} -> 31 | Q8: =IF(OR($B8=0,$K8="",$P8=""),"",$K8-$P8) -> 17
A9: Telegram | B9: {=INDIRECT("'"&$B$2&"'!C74")} -> 1677 | C9: {=IF($B9=0,"",INDIRECT("'"&$B$2&"'!D74"))} -> 427060 | D9: {=IF($B9=0,"",INDIRECT("'"&$B$2&"'!E74"))} -> 424843 | E9: =IF(B9=0,"",IFERROR(C9/D9-1,"")) -> 0.0052183983 | F9: {=IF($B9=0,"",INDIRECT("'"&$B$2&"'!H74"))} -> 2736 | G9: {=IF($B9=0,"",INDIRECT("'"&$B$2&"'!I74"))} -> 2377 | H9: =IF(B9=0,"",IFERROR(F9/G9-1,"")) -> 0.15103071 | I9: =IFERROR(F9/C9*1000,"") -> 6.4065939 | J9: {=IF($B9=0,"",INDIRECT("'"&$B$2&"'!N74"))} -> 97774 | K9: {=IF($B9=0,"",INDIRECT("'"&$B$2&"'!O74"))} -> -164 | L9: {=IFERROR(IF(INDIRECT("'"&$B$3&"'!G74")="","",INDIRECT("'"&$B$3&"'!G74")),"")} -> 0.012017685 | M9: =IF(OR($E9="",$L9=""),"",$E9-$L9) -> -0.0067992864 | N9: {=IFERROR(IF(INDIRECT("'"&$B$3&"'!K74")="","",INDIRECT("'"&$B$3&"'!K74")),"")} -> -0.110737 | O9: =IF(OR($H9="",$N9=""),"",$H9-$N9) -> 0.26176771 | P9: {=IFERROR(IF(INDIRECT("'"&$B$3&"'!O74")="","",INDIRECT("'"&$B$3&"'!O74")),"")} -> -171 | Q9: =IF(OR($B9=0,$K9="",$P9=""),"",$K9-$P9) -> 7
A10: МАКС | B10: {=INDIRECT("'"&$B$2&"'!C96")} -> 1456 | C10: {=IF($B10=0,"",INDIRECT("'"&$B$2&"'!D96"))} -> 1030049 | D10: {=IF($B10=0,"",INDIRECT("'"&$B$2&"'!E96"))} -> 940640 | E10: =IF(B10=0,"",IFERROR(C10/D10-1,"")) -> 0.095051242 | F10: {=IF($B10=0,"",INDIRECT("'"&$B$2&"'!H96"))} -> 13921 | G10: {=IF($B10=0,"",INDIRECT("'"&$B$2&"'!I96"))} -> 13037 | H10: =IF(B10=0,"",IFERROR(F10/G10-1,"")) -> 0.067807011 | I10: =IFERROR(F10/C10*1000,"") -> 13.514891 | J10: {=IF($B10=0,"",INDIRECT("'"&$B$2&"'!N96"))} -> 31996 | K10: {=IF($B10=0,"",INDIRECT("'"&$B$2&"'!O96"))} -> 428 | L10: {=IFERROR(IF(INDIRECT("'"&$B$3&"'!G96")="","",INDIRECT("'"&$B$3&"'!G96")),"")} -> -0.062651966 | M10: =IF(OR($E10="",$L10=""),"",$E10-$L10) -> 0.15770321 | N10: {=IFERROR(IF(INDIRECT("'"&$B$3&"'!K96")="","",INDIRECT("'"&$B$3&"'!K96")),"")} -> -0.059650894 | O10: =IF(OR($H10="",$N10=""),"",$H10-$N10) -> 0.12745791 | P10: {=IFERROR(IF(INDIRECT("'"&$B$3&"'!O96")="","",INDIRECT("'"&$B$3&"'!O96")),"")} -> 270 | Q10: =IF(OR($B10=0,$K10="",$P10=""),"",$K10-$P10) -> 158
A11: ИТОГО | B11: =SUM(B7:B10) -> 6327 | C11: =SUM(C7:C10) -> 6053101 | D11: =SUM(D7:D10) -> 6681698 | E11: =IF(OR(B7=0,B8=0,B9=0,B10=0),"",IFERROR(C11/D11-1,"")) -> -0.094077434 | F11: =SUM(F7:F10) -> 49082 | G11: =SUM(G7:G10) -> 51376 | H11: =IF(OR(B7=0,B8=0,B9=0,B10=0),"",IFERROR(F11/G11-1,"")) -> -0.044651199 | I11: =IFERROR(F11/C11*1000,"") -> 8.1085711 | J11: =SUM(J7:J10) -> 704247 | K11: =SUM(K7:K10) -> 1347 | L11: {=IFERROR(IF(INDIRECT("'"&$B$3&"'!G97")="","",INDIRECT("'"&$B$3&"'!G97")),"")} -> 0.12830824 | M11: =IF(OR($E11="",$L11=""),"",$E11-$L11) -> -0.22238568 | N11: {=IFERROR(IF(INDIRECT("'"&$B$3&"'!K97")="","",INDIRECT("'"&$B$3&"'!K97")),"")} -> 0.059714346 | O11: =IF(OR($H11="",$N11=""),"",$H11-$N11) -> -0.10436554 | P11: {=IFERROR(IF(INDIRECT("'"&$B$3&"'!O97")="","",INDIRECT("'"&$B$3&"'!O97")),"")} -> 1171 | Q11: =IF(OR(B7=0,B8=0,B9=0,B10=0),"",$K11-$P11) -> 176
A13: ускорение = насколько прирост этой недели отличается от прироста прошлой, в процентных пунктах.
A14: Плюс — рост ускорился, минус — рост замедлился (или падение усилилось). Считается от Δ % листа прошлой недели.

Sheet 05-11.10
A1: Недельный съём · 05–11.10.2026 | Q1: Лист прошлой недели (питает колонки E, I, O):
A2: Площадка | B2: Ресурс | C2: Публикаций | D2: Просмотры | E2: Просмотры пред. неделя | F2: Δ просмотров | G2: Δ % | H2: Лайки | I2: Лайки пред. неделя | J2: Δ лайков | K2: Δ % | L2: Ср. просмотров на пост | M2: Лайков на 1000 просмотров | N2: Подписчики | O2: Прирост подписчиков | Q2: 28.09-04.10 | S2: Δ % просмотров пред. неделя | T2: Ускорение просмотров, п.п. | U2: Δ % лайков пред. неделя | V2: Ускорение лайков, п.п. | W2: Прирост подписч. пред. неделя | X2: Ускорение подписчиков, чел.
A3: ВКонтакте | B3: Ямал-Медиа | C3: 111 | D3: 1832889 | E3: =IF($D3="","",IFERROR(IF(ISBLANK(INDIRECT("'"&$Q$2&"'!D"&ROW())),"",INDIRECT("'"&$Q$2&"'!D"&ROW())),"")) -> 2647589 | F3: =IF(OR(D3="",E3=""),"",D3-E3) -> -814700 | G3: =IFERROR(F3/E3,"") -> -0.30771392 | H3: 4521 | I3: =IF($H3="","",IFERROR(IF(ISBLANK(INDIRECT("'"&$Q$2&"'!H"&ROW())),"",INDIRECT("'"&$Q$2&"'!H"&ROW())),"")) -> 5901 | J3: =IF(OR(H3="",I3=""),"",H3-I3) -> -1380 | K3: =IFERROR(J3/I3,"") -> -0.23385867 | L3: =IFERROR(D3/C3,"") -> 16512.514 | M3: =IFERROR(H3/D3*1000,"") -> 2.4665978 | N3: 89891 | O3: =IFERROR(IF(OR(N3="",ISBLANK(INDIRECT("'"&$Q$2&"'!N"&ROW()))),"",N3-INDIRECT("'"&$Q$2&"'!N"&ROW())),"") -> 241 | Q3: Колонки E и I берут прошлую неделю только по строкам, снятым в текущей — сравнение идёт по сопоставимому периметру. | S3: =IFERROR(IF(ISBLANK(INDIRECT("'"&$Q$2&"'!G"&ROW())),"",INDIRECT("'"&$Q$2&"'!G"&ROW())),"") -> 0.38365342 | T3: =IF(OR($G3="",$S3=""),"",$G3-$S3) -> -0.69136735 | U3: =IFERROR(IF(ISBLANK(INDIRECT("'"&$Q$2&"'!K"&ROW())),"",INDIRECT("'"&$Q$2&"'!K"&ROW())),"") -> 0.31895396 | V3: =IF(OR($K3="",$U3=""),"",$K3-$U3) -> -0.55281262 | W3: =IFERROR(IF(ISBLANK(INDIRECT("'"&$Q$2&"'!O"&ROW())),"",INDIRECT("'"&$Q$2&"'!O"&ROW())),"") -> 292 | X3: =IF(OR($O3="",$W3=""),"",$O3-$W3) -> -51
A4: ВКонтакте | B4: Север-Пресс | C4: 124 | D4: 93897 | E4: =IF($D4="","",IFERROR(IF(ISBLANK(INDIRECT("'"&$Q$2&"'!D"&ROW())),"",INDIRECT("'"&$Q$2&"'!D"&ROW())),"")) -> 218156 | F4: =IF(OR(D4="",E4=""),"",D4-E4) -> -124259 | G4: =IFERROR(F4/E4,"") -> -0.56958782 | H4: 326 | I4: =IF($H4="","",IFERROR(IF(ISBLANK(INDIRECT("'"&$Q$2&"'!H"&ROW())),"",INDIRECT("'"&$Q$2&"'!H"&ROW())),"")) -> 672 | J4: =IF(OR(H4="",I4=""),"",H4-I4) -> -346 | K4: =IFERROR(J4/I4,"") -> -0.51488095 | L4: =IFERROR(D4/C4,"") -> 757.23387 | M4: =IFERROR(H4/D4*1000,"") -> 3.4718894 | N4: 26299 | O4: =IFERROR(IF(OR(N4="",ISBLANK(INDIRECT("'"&$Q$2&"'!N"&ROW()))),"",N4-INDIRECT("'"&$Q$2&"'!N"&ROW())),"") -> 8 | Q4: ОК: «просмотры» = VIEWS листа Topics, лайки = сумма LIKES листа Actions (по группе, как в прошлых съёмах). | S4: =IFERROR(IF(ISBLANK(INDIRECT("'"&$Q$2&"'!G"&ROW())),"",INDIRECT("'"&$Q$2&"'!G"&ROW())),"") -> 0.72531714 | T4: =IF(OR($G4="",$S4=""),"",$G4-$S4) -> -1.294905 | U4: =IFERROR(IF(ISBLANK(INDIRECT("'"&$Q$2&"'!K"&ROW())),"",INDIRECT("'"&$Q$2&"'!K"&ROW())),"") -> 0.27272727 | V4: =IF(OR($K4="",$U4=""),"",$K4-$U4) -> -0.78760823 | W4: =IFERROR(IF(ISBLANK(INDIRECT("'"&$Q$2&"'!O"&ROW())),"",INDIRECT("'"&$Q$2&"'!O"&ROW())),"") -> 31 | X4: =IF(OR($O4="",$W4=""),"",$O4-$W4) -> -23
A5: ВКонтакте | B5: Лента СП | C5: 151 | D5: 3132 | E5: =IF($D5="","",IFERROR(IF(ISBLANK(INDIRECT("'"&$Q$2&"'!D"&ROW())),"",INDIRECT("'"&$Q$2&"'!D"&ROW())),"")) -> 2991 | F5: =IF(OR(D5="",E5=""),"",D5-E5) -> 141 | G5: =IFERROR(F5/E5,"") -> 0.047141424 | H5: 10 | I5: =IF($H5="","",IFERROR(IF(ISBLANK(INDIRECT("'"&$Q$2&"'!H"&ROW())),"",INDIRECT("'"&$Q$2&"'!H"&ROW())),"")) -> 12 | J5: =IF(OR(H5="",I5=""),"",H5-I5) -> -2 | K5: =IFERROR(J5/I5,"") -> -0.16666667 | L5: =IFERROR(D5/C5,"") -> 20.741722 | M5: =IFERROR(H5/D5*1000,"") -> 3.192848 | N5: 3506 | O5: =IFERROR(IF(OR(N5="",ISBLANK(INDIRECT("'"&$Q$2&"'!N"&ROW()))),"",N5-INDIRECT("'"&$Q$2&"'!N"&ROW())),"") -> 3 | S5: =IFERROR(IF(ISBLANK(INDIRECT("'"&$Q$2&"'!G"&ROW())),"",INDIRECT("'"&$Q$2&"'!G"&ROW())),"") -> -0.24792557 | T5: =IF(OR($G5="",$S5=""),"",$G5-$S5) -> 0.295067 | U5: =IFERROR(IF(ISBLANK(INDIRECT("'"&$Q$2&"'!K"&ROW())),"",INDIRECT("'"&$Q$2&"'!K"&ROW())),"") -> 0 | V5: =IF(OR($K5="",$U5=""),"",$K5-$U5) -> -0.16666667 | W5: =IFERROR(IF(ISBLANK(INDIRECT("'"&$Q$2&"'!O"&ROW())),"",INDIRECT("'"&$Q$2&"'!O"&ROW())),"") -> 3 | X5: =IF(OR($O5="",$W5=""),"",$O5-$W5) -> 0
A6: ВКонтакте | B6: Красный Север | C6: 85 | D6: 59201 | E6: =IF($D6="","",IFERROR(IF(ISBLANK(INDIRECT("'"&$Q$2&"'!D"&ROW())),"",INDIRECT("'"&$Q$2&"'!D"&ROW())),"")) -> 79350 | F6: =IF(OR(D6="",E6=""),"",D6-E6) -> -20149 | G6: =IFERROR(F6/E6,"") -> -0.25392565 | H6: 453 | I6: =IF($H6="","",IFERROR(IF(ISBLANK(INDIRECT("'"&$Q$2&"'!H"&ROW())),"",INDIRECT("'"&$Q$2&"'!H"&ROW())),"")) -> 466 | J6: =IF(OR(H6="",I6=""),"",H6-I6) -> -13 | K6: =IFERROR(J6/I6,"") -> -0.027896996 | L6: =IFERROR(D6/C6,"") -> 696.48235 | M6: =IFERROR(H6/D6*1000,"") -> 7.6518978 | N6: 22953 | O6: =IFERROR(IF(OR(N6="",ISBLANK(INDIRECT("'"&$Q$2&"'!N"&ROW()))),"",N6-INDIRECT("'"&$Q$2&"'!N"&ROW())),"") -> 4 | S6: =IFERROR(IF(ISBLANK(INDIRECT("'"&$Q$2&"'!G"&ROW())),"",INDIRECT("'"&$Q$2&"'!G"&ROW())),"") -> 0.25385162 | T6: =IF(OR($G6="",$S6=""),"",$G6-$S6) -> -0.50777727 | U6: =IFERROR(IF(ISBLANK(INDIRECT("'"&$Q$2&"'!K"&ROW())),"",INDIRECT("'"&$Q$2&"'!K"&ROW())),"") -> 0.35860058 | V6: =IF(OR($K6="",$U6=""),"",$K6-$U6) -> -0.38649758 | W6: =IFERROR(IF(ISBLANK(INDIRECT("'"&$Q$2&"'!O"&ROW())),"",INDIRECT("'"&$Q$2&"'!O"&ROW())),"") -> 17 | X6: =IF(OR($O6="",$W6=""),"",$O6-$W6) -> -13
A7: ВКонтакте | B7: Новый Уренгой | C7: 104 | D7: 112105 | E7: =IF($D7="","",IFERROR(IF(ISBLANK(INDIRECT("'"&$Q$2&"'!D"&ROW())),"",INDIRECT("'"&$Q$2&"'!D"&ROW())),"")) -> 84352 | F7: =IF(OR(D7="",E7=""),"",D7-E7) -> 27753 | G7: =IFERROR(F7/E7,"") -> 0.32901413 | H7: 916 | I7: =IF($H7="","",IFERROR(IF(ISBLANK(INDIRECT("'"&$Q$2&"'!H"&ROW())),"",INDIRECT("'"&$Q$2&"'!H"&ROW())),"")) -> 1068 | J7: =IF(OR(H7="",I7=""),"",H7-I7) -> -152 | K7: =IFERROR(J7/I7,"") -> -0.1423221 | L7: =IFERROR(D7/C7,"") -> 1077.9327 | M7: =IFERROR(H7/D7*1000,"") -> 8.1709112 | N7: 24948 | O7: =IFERROR(IF(OR(N7="",ISBLANK(INDIRECT("'"&$Q$2&"'!N"&ROW()))),"",N7-INDIRECT("'"&$Q$2&"'!N"&ROW())),"") -> 47 | S7: =IFERROR(IF(ISBLANK(INDIRECT("'"&$Q$2&"'!G"&ROW())),"",INDIRECT("'"&$Q$2&"'!G"&ROW())),"") -> 0.069506783 | T7: =IF(OR($G7="",$S7=""),"",$G7-$S7) -> 0.25950735 | U7: =IFERROR(IF(ISBLANK(INDIRECT("'"&$Q$2&"'!K"&ROW())),"",INDIRECT("'"&$Q$2&"'!K"&ROW())),"") -> 0.34170854 | V7: =IF(OR($K7="",$U7=""),"",$K7-$U7) -> -0.48403064 | W7: =IFERROR(IF(ISBLANK(INDIRECT("'"&$Q$2&"'!O"&ROW())),"",INDIRECT("'"&$Q$2&"'!O"&ROW())),"") -> 33 | X7: =IF(OR($O7="",$W7=""),"",$O7-$W7) -> 14
A8: ВКонтакте | B8: Надым | C8: 82 | D8: 184234 | E8: =IF($D8="","",IFERROR(IF(ISBLANK(INDIRECT("'"&$Q$2&"'!D"&ROW())),"",INDIRECT("'"&$Q$2&"'!D"&ROW())),"")) -> 196212 | F8: =IF(OR(D8="",E8=""),"",D8-E8) -> -11978 | G8: =IFERROR(F8/E8,"") -> -0.061046215 | H8: 2347 | I8: =IF($H8="","",IFERROR(IF(ISBLANK(INDIRECT("'"&$Q$2&"'!H"&ROW())),"",INDIRECT("'"&$Q$2&"'!H"&ROW())),"")) -> 2605 | J8: =IF(OR(H8="",I8=""),"",H8-I8) -> -258 | K8: =IFERROR(J8/I8,"") -> -0.099040307 | L8: =IFERROR(D8/C8,"") -> 2246.7561 | M8: =IFERROR(H8/D8*1000,"") -> 12.739234 | N8: 21807 | O8: =IFERROR(IF(OR(N8="",ISBLANK(INDIRECT("'"&$Q$2&"'!N"&ROW()))),"",N8-INDIRECT("'"&$Q$2&"'!N"&ROW())),"") -> 38 | S8: =IFERROR(IF(ISBLANK(INDIRECT("'"&$Q$2&"'!G"&ROW())),"",INDIRECT("'"&$Q$2&"'!G"&ROW())),"") -> -0.33931572 | T8: =IF(OR($G8="",$S8=""),"",$G8-$S8) -> 0.2782695 | U8: =IFERROR(IF(ISBLANK(INDIRECT("'"&$Q$2&"'!K"&ROW())),"",INDIRECT("'"&$Q$2&"'!K"&ROW())),"") -> -0.26948962 | V8: =IF(OR($K8="",$U8=""),"",$K8-$U8) -> 0.17044932 | W8: =IFERROR(IF(ISBLANK(INDIRECT("'"&$Q$2&"'!O"&ROW())),"",INDIRECT("'"&$Q$2&"'!O"&ROW())),"") -> 25 | X8: =IF(OR($O8="",$W8=""),"",$O8-$W8) -> 13
A9: ВКонтакте | B9: Ноябрьск | C9: 89 | D9: 214009 | E9: =IF($D9="","",IFERROR(IF(ISBLANK(INDIRECT("'"&$Q$2&"'!D"&ROW())),"",INDIRECT("'"&$Q$2&"'!D"&ROW())),"")) -> 320603 | F9: =IF(OR(D9="",E9=""),"",D9-E9) -> -106594 | G9: =IFERROR(F9/E9,"") -> -0.33247973 | H9: 2868 | I9: =IF($H9="","",IFERROR(IF(ISBLANK(INDIRECT("'"&$Q$2&"'!H"&ROW())),"",INDIRECT("'"&$Q$2&"'!H"&ROW())),"")) -> 4182 | J9: =IF(OR(H9="",I9=""),"",H9-I9) -> -1314 | K9: =IFERROR(J9/I9,"") -> -0.31420373 | L9: =IFERROR(D9/C9,"") -> 2404.5955 | M9: =IFERROR(H9/D9*1000,"") -> 13.401306 | N9: 31360 | O9: =IFERROR(IF(OR(N9="",ISBLANK(INDIRECT("'"&$Q$2&"'!N"&ROW()))),"",N9-INDIRECT("'"&$Q$2&"'!N"&ROW())),"") -> 14 | S9: =IFERROR(IF(ISBLANK(INDIRECT("'"&$Q$2&"'!G"&ROW())),"",INDIRECT("'"&$Q$2&"'!G"&ROW())),"") -> -0.0060208653 | T9: =IF(OR($G9="",$S9=""),"",$G9-$S9) -> -0.32645887 | U9: =IFERROR(IF(ISBLANK(INDIRECT("'"&$Q$2&"'!K"&ROW())),"",INDIRECT("'"&$Q$2&"'!K"&ROW())),"") -> 0.0062560154 | V9: =IF(OR($K9="",$U9=""),"",$K9-$U9) -> -0.32045975 | W9: =IFERROR(IF(ISBLANK(INDIRECT("'"&$Q$2&"'!O"&ROW())),"",INDIRECT("'"&$Q$2&"'!O"&ROW())),"") -> 16 | X9: =IF(OR($O9="",$W9=""),"",$O9-$W9) -> -2
A10: ВКонтакте | B10: Салехард | C10: 148 | D10: 169334 | E10: =IF($D10="","",IFERROR(IF(ISBLANK(INDIRECT("'"&$Q$2&"'!D"&ROW())),"",INDIRECT("'"&$Q$2&"'!D"&ROW())),"")) -> 197099 | F10: =IF(OR(D10="",E10=""),"",D10-E10) -> -27765 | G10: =IFERROR(F10/E10,"") -> -0.14086829 | H10: 1168 | I10: =IF($H10="","",IFERROR(IF(ISBLANK(INDIRECT("'"&$Q$2&"'!H"&ROW())),"",INDIRECT("'"&$Q$2&"'!H"&ROW())),"")) -> 2190 | J10: =IF(OR(H10="",I10=""),"",H10-I10) -> -1022 | K10: =IFERROR(J10/I10,"") -> -0.46666667 | L10: =IFERROR(D10/C10,"") -> 1144.1486 | M10: =IFERROR(H10/D10*1000,"") -> 6.8976106 | N10: 21638 | O10: =IFERROR(IF(OR(N10="",ISBLANK(INDIRECT("'"&$Q$2&"'!N"&ROW()))),"",N10-INDIRECT("'"&$Q$2&"'!N"&ROW())),"") -> 25 | S10: =IFERROR(IF(ISBLANK(INDIRECT("'"&$Q$2&"'!G"&ROW())),"",INDIRECT("'"&$Q$2&"'!G"&ROW())),"") -> 0.1738162 | T10: =IF(OR($G10="",$S10=""),"",$G10-$S10) -> -0.3146845 | U10: =IFERROR(IF(ISBLANK(INDIRECT("'"&$Q$2&"'!K"&ROW())),"",INDIRECT("'"&$Q$2&"'!K"&ROW())),"") -> 0.83724832 | V10: =IF(OR($K10="",$U10=""),"",$K10-$U10) -> -1.303915 | W10: =IFERROR(IF(ISBLANK(INDIRECT("'"&$Q$2&"'!O"&ROW())),"",INDIRECT("'"&$Q$2&"'!O"&ROW())),"") -> 27 | X10: =IF(OR($O10="",$W10=""),"",$O10-$W10) -> -2
A11: ВКонтакте | B11: Приуралье | C11: 104 | D11: 387676 | E11: =IF($D11="","",IFERROR(IF(ISBLANK(INDIRECT("'"&$Q$2&"'!D"&ROW())),"",INDIRECT("'"&$Q$2&"'!D"&ROW())),"")) -> 366428 | F11: =IF(OR(D11="",E11=""),"",D11-E11) -> 21248 | G11: =IFERROR(F11/E11,"") -> 0.057986835 | H11: 3546 | I11: =IF($H11="","",IFERROR(IF(ISBLANK(INDIRECT("'"&$Q$2&"'!H"&ROW())),"",INDIRECT("'"&$Q$2&"'!H"&ROW())),"")) -> 2775 | J11: =IF(OR(H11="",I11=""),"",H11-I11) -> 771 | K11: =IFERROR(J11/I11,"") -> 0.27783784 | L11: =IFERROR(D11/C11,"") -> 3727.6538 | M11: =IFERROR(H11/D11*1000,"") -> 9.1468133 | N11: 20852 | O11: =IFERROR(IF(OR(N11="",ISBLANK(INDIRECT("'"&$Q$2&"'!N"&ROW()))),"",N11-INDIRECT("'"&$Q$2&"'!N"&ROW())),"") -> 37 | S11: =IFERROR(IF(ISBLANK(INDIRECT("'"&$Q$2&"'!G"&ROW())),"",INDIRECT("'"&$Q$2&"'!G"&ROW())),"") -> -0.101013 | T11: =IF(OR($G11="",$S11=""),"",$G11-$S11) -> 0.15899984 | U11: =IFERROR(IF(ISBLANK(INDIRECT("'"&$Q$2&"'!K"&ROW())),"",INDIRECT("'"&$Q$2&"'!K"&ROW())),"") -> -0.24878181 | V11: =IF(OR($K11="",$U11=""),"",$K11-$U11) -> 0.52661965 | W11: =IFERROR(IF(ISBLANK(INDIRECT("'"&$Q$2&"'!O"&ROW())),"",INDIRECT("'"&$Q$2&"'!O"&ROW())),"") -> 18 | X11: =IF(OR($O11="",$W11=""),"",$O11-$W11) -> 19
A12: ВКонтакте | B12: Лабытнанги | C12: 71 | D12: 182432 | E12: =IF($D12="","",IFERROR(IF(ISBLANK(INDIRECT("'"&$Q$2&"'!D"&ROW())),"",INDIRECT("'"&$Q$2&"'!D"&ROW())),"")) -> 119193 | F12: =IF(OR(D12="",E12=""),"",D12-E12) -> 63239 | G12: =IFERROR(F12/E12,"") -> 0.53055968 | H12: 2953 | I12: =IF($H12="","",IFERROR(IF(ISBLANK(INDIRECT("'"&$Q$2&"'!H"&ROW())),"",INDIRECT("'"&$Q$2&"'!H"&ROW())),"")) -> 1839 | J12: =IF(OR(H12="",I12=""),"",H12-I12) -> 1114 | K12: =IFERROR(J12/I12,"") -> 0.605764 | L12: =IFERROR(D12/C12,"") -> 2569.4648 | M12: =IFERROR(H12/D12*1000,"") -> 16.186853 | N12: 15687 | O12: =IFERROR(IF(OR(N12="",ISBLANK(INDIRECT("'"&$Q$2&"'!N"&ROW()))),"",N12-INDIRECT("'"&$Q$2&"'!N"&ROW())),"") -> 129 | S12: =IFERROR(IF(ISBLANK(INDIRECT("'"&$Q$2&"'!G"&ROW())),"",INDIRECT("'"&$Q$2&"'!G"&ROW())),"") -> 0.068411004 | T12: =IF(OR($G12="",$S12=""),"",$G12-$S12) -> 0.46214868 | U12: =IFERROR(IF(ISBLANK(INDIRECT("'"&$Q$2&"'!K"&ROW())),"",INDIRECT("'"&$Q$2&"'!K"&ROW())),"") -> -0.047150259 | V12: =IF(OR($K12="",$U12=""),"",$K12-$U12) -> 0.65291426 | W12: =IFERROR(IF(ISBLANK(INDIRECT("'"&$Q$2&"'!O"&ROW())),"",INDIRECT("'"&$Q$2&"'!O"&ROW())),"") -> 60 | X12: =IF(OR($O12="",$W12=""),"",$O12-$W12) -> 69
A13: ВКонтакте | B13: Пуровский | C13: 54 | D13: 22648 | E13: =IF($D13="","",IFERROR(IF(ISBLANK(INDIRECT("'"&$Q$2&"'!D"&ROW())),"",INDIRECT("'"&$Q$2&"'!D"&ROW())),"")) -> 19819 | F13: =IF(OR(D13="",E13=""),"",D13-E13) -> 2829 | G13: =IFERROR(F13/E13,"") -> 0.14274181 | H13: 380 | I13: =IF($H13="","",IFERROR(IF(ISBLANK(INDIRECT("'"&$Q$2&"'!H"&ROW())),"",INDIRECT("'"&$Q$2&"'!H"&ROW())),"")) -> 287 | J13: =IF(OR(H13="",I13=""),"",H13-I13) -> 93 | K13: =IFERROR(J13/I13,"") -> 0.32404181 | L13: =IFERROR(D13/C13,"") -> 419.40741 | M13: =IFERROR(H13/D13*1000,"") -> 16.778523 | N13: 16421 | O13: =IFERROR(IF(OR(N13="",ISBLANK(INDIRECT("'"&$Q$2&"'!N"&ROW()))),"",N13-INDIRECT("'"&$Q$2&"'!N"&ROW())),"") -> -8 | S13: =IFERROR(IF(ISBLANK(INDIRECT("'"&$Q$2&"'!G"&ROW())),"",INDIRECT("'"&$Q$2&"'!G"&ROW())),"") -> -0.40454873 | T13: =IF(OR($G13="",$S13=""),"",$G13-$S13) -> 0.54729055 | U13: =IFERROR(IF(ISBLANK(INDIRECT("'"&$Q$2&"'!K"&ROW())),"",INDIRECT("'"&$Q$2&"'!K"&ROW())),"") -> -0.18696884 | V13: =IF(OR($K13="",$U13=""),"",$K13-$U13) -> 0.51101065 | W13: =IFERROR(IF(ISBLANK(INDIRECT("'"&$Q$2&"'!O"&ROW())),"",INDIRECT("'"&$Q$2&"'!O"&ROW())),"") -> -14 | X13: =IF(OR($O13="",$W13=""),"",$O13-$W13) -> 6
A14: ВКонтакте | B14: Тазовский | C14: 62 | D14: 54222 | E14: =IF($D14="","",IFERROR(IF(ISBLANK(INDIRECT("'"&$Q$2&"'!D"&ROW())),"",INDIRECT("'"&$Q$2&"'!D"&ROW())),"")) -> 58490 | F14: =IF(OR(D14="",E14=""),"",D14-E14) -> -4268 | G14: =IFERROR(F14/E14,"") -> -0.072969738 | H14: 545 | I14: =IF($H14="","",IFERROR(IF(ISBLANK(INDIRECT("'"&$Q$2&"'!H"&ROW())),"",INDIRECT("'"&$Q$2&"'!H"&ROW())),"")) -> 798 | J14: =IF(OR(H14="",I14=""),"",H14-I14) -> -253 | K14: =IFERROR(J14/I14,"") -> -0.31704261 | L14: =IFERROR(D14/C14,"") -> 874.54839 | M14: =IFERROR(H14/D14*1000,"") -> 10.051271 | N14: 6499 | O14: =IFERROR(IF(OR(N14="",ISBLANK(INDIRECT("'"&$Q$2&"'!N"&ROW()))),"",N14-INDIRECT("'"&$Q$2&"'!N"&ROW())),"") -> 31 | S14: =IFERROR(IF(ISBLANK(INDIRECT("'"&$Q$2&"'!G"&ROW())),"",INDIRECT("'"&$Q$2&"'!G"&ROW())),"") -> 0.19758395 | T14: =IF(OR($G14="",$S14=""),"",$G14-$S14) -> -0.27055369 | U14: =IFERROR(IF(ISBLANK(INDIRECT("'"&$Q$2&"'!K"&ROW())),"",INDIRECT("'"&$Q$2&"'!K"&ROW())),"") -> 0.49438202 | V14: =IF(OR($K14="",$U14=""),"",$K14-$U14) -> -0.81142463 | W14: =IFERROR(IF(ISBLANK(INDIRECT("'"&$Q$2&"'!O"&ROW())),"",INDIRECT("'"&$Q$2&"'!O"&ROW())),"") -> 29 | X14: =IF(OR($O14="",$W14=""),"",$O14-$W14) -> 2
A15: ВКонтакте | B15: Красноселькуп | C15: 27 | D15: 33116 | E15: =IF($D15="","",IFERROR(IF(ISBLANK(INDIRECT("'"&$Q$2&"'!D"&ROW())),"",INDIRECT("'"&$Q$2&"'!D"&ROW())),"")) -> 33209 | F15: =IF(OR(D15="",E15=""),"",D15-E15) -> -93 | G15: =IFERROR(F15/E15,"") -> -0.0028004457 | H15: 387 | I15: =IF($H15="","",IFERROR(IF(ISBLANK(INDIRECT("'"&$Q$2&"'!H"&ROW())),"",INDIRECT("'"&$Q$2&"'!H"&ROW())),"")) -> 303 | J15: =IF(OR(H15="",I15=""),"",H15-I15) -> 84 | K15: =IFERROR(J15/I15,"") -> 0.27722772 | L15: =IFERROR(D15/C15,"") -> 1226.5185 | M15: =IFERROR(H15/D15*1000,"") -> 11.686194 | N15: 3712 | O15: =IFERROR(IF(OR(N15="",ISBLANK(INDIRECT("'"&$Q$2&"'!N"&ROW()))),"",N15-INDIRECT("'"&$Q$2&"'!N"&ROW())),"") -> 13 | S15: =IFERROR(IF(ISBLANK(INDIRECT("'"&$Q$2&"'!G"&ROW())),"",INDIRECT("'"&$Q$2&"'!G"&ROW())),"") -> 0.08049455 | T15: =IF(OR($G15="",$S15=""),"",$G15-$S15) -> -0.083294996 | U15: =IFERROR(IF(ISBLANK(INDIRECT("'"&$Q$2&"'!K"&ROW())),"",INDIRECT("'"&$Q$2&"'!K"&ROW())),"") -> 0.0033112583 | V15: =IF(OR($K15="",$U15=""),"",$K15-$U15) -> 0.27391646 | W15: =IFERROR(IF(ISBLANK(INDIRECT("'"&$Q$2&"'!O"&ROW())),"",INDIRECT("'"&$Q$2&"'!O"&ROW())),"") -> 12 | X15: =IF(OR($O15="",$W15=""),"",$O15-$W15) -> 1
A16: ВКонтакте | B16: Ямальский | C16: 59 | D16: 118008 | E16: =IF($D16="","",IFERROR(IF(ISBLANK(INDIRECT("'"&$Q$2&"'!D"&ROW())),"",INDIRECT("'"&$Q$2&"'!D"&ROW())),"")) -> 86941 | F16: =IF(OR(D16="",E16=""),"",D16-E16) -> 31067 | G16: =IFERROR(F16/E16,"") -> 0.35733428 | H16: 1068 | I16: =IF($H16="","",IFERROR(IF(ISBLANK(INDIRECT("'"&$Q$2&"'!H"&ROW())),"",INDIRECT("'"&$Q$2&"'!H"&ROW())),"")) -> 723 | J16: =IF(OR(H16="",I16=""),"",H16-I16) -> 345 | K16: =IFERROR(J16/I16,"") -> 0.47717842 | L16: =IFERROR(D16/C16,"") -> 2000.1356 | M16: =IFERROR(H16/D16*1000,"") -> 9.0502339 | N16: 12938 | O16: =IFERROR(IF(OR(N16="",ISBLANK(INDIRECT("'"&$Q$2&"'!N"&ROW()))),"",N16-INDIRECT("'"&$Q$2&"'!N"&ROW())),"") -> 36 | S16: =IFERROR(IF(ISBLANK(INDIRECT("'"&$Q$2&"'!G"&ROW())),"",INDIRECT("'"&$Q$2&"'!G"&ROW())),"") -> -0.12402015 | T16: =IF(OR($G16="",$S16=""),"",$G16-$S16) -> 0.48135444 | U16: =IFERROR(IF(ISBLANK(INDIRECT("'"&$Q$2&"'!K"&ROW())),"",INDIRECT("'"&$Q$2&"'!K"&ROW())),"") -> -0.27772228 | V16: =IF(OR($K16="",$U16=""),"",$K16-$U16) -> 0.7549007 | W16: =IFERROR(IF(ISBLANK(INDIRECT("'"&$Q$2&"'!O"&ROW())),"",INDIRECT("'"&$Q$2&"'!O"&ROW())),"") -> 89 | X16: =IF(OR($O16="",$W16=""),"",$O16-$W16) -> -53
... A29: ВКонтакте | B29: Морошка | C29: 10 | D29: 15009 | E29: =IF($D29="","",IFERROR(IF(ISBLANK(INDIRECT("'"&$Q$2&"'!D"&ROW())),"",INDIRECT("'"&$Q$2&"'!D"&ROW())),"")) -> 26347 | F29: =IF(OR(D29="",E29=""),"",D29-E29) -> -11338 | G29: =IFERROR(F29/E29,"") -> -0.43033362 | H29: 177 | I29: =IF($H29="","",IFERROR(IF(ISBLANK(INDIRECT("'"&$Q$2&"'!H"&ROW())),"",INDIRECT("'"&$Q$2&"'!H"&ROW())),"")) -> 363 | J29: =IF(OR(H29="",I29=""),"",H29-I29) -> -186 | K29: =IFERROR(J29/I29,"") -> -0.51239669 | L29: =IFERROR(D29/C29,"") -> 1500.9 | M29: =IFERROR(H29/D29*1000,"") -> 11.792924 | N29: 9872 | O29: =IFERROR(IF(OR(N29="",ISBLANK(INDIRECT("'"&$Q$2&"'!N"&ROW()))),"",N29-INDIRECT("'"&$Q$2&"'!N"&ROW())),"") -> 113 | S29: =IFERROR(IF(ISBLANK(INDIRECT("'"&$Q$2&"'!G"&ROW())),"",INDIRECT("'"&$Q$2&"'!G"&ROW())),"") -> 1.4565967 | T29: =IF(OR($G29="",$S29=""),"",$G29-$S29) -> -1.8869304 | U29: =IFERROR(IF(ISBLANK(INDIRECT("'"&$Q$2&"'!K"&ROW())),"",INDIRECT("'"&$Q$2&"'!K"&ROW())),"") -> 0.43478261 | V29: =IF(OR($K29="",$U29=""),"",$K29-$U29) -> -0.9471793 | W29: =IFERROR(IF(ISBLANK(INDIRECT("'"&$Q$2&"'!O"&ROW())),"",INDIRECT("'"&$Q$2&"'!O"&ROW())),"") -> 134 | X29: =IF(OR($O29="",$W29=""),"",$O29-$W29) -> -21
B30: Итого ВКонтакте | C30: =SUM(C3:C29) -> 1808 | D30: =SUM(D3:D29) -> 4157980 | E30: =SUM(E3:E29) -> 5072194 | F30: =SUM(F3:F29) -> -914214 | G30: =IF(C30=0,"",IFERROR(F30/E30,"")) -> -0.18024035 | H30: =SUM(H3:H29) -> 30049 | I30: =SUM(I3:I29) -> 33669 | J30: =SUM(J3:J29) -> -3620 | K30: =IF(C30=0,"",IFERROR(J30/I30,"")) -> -0.1075173 | L30: =IFERROR(D30/C30,"") -> 2299.7677 | M30: =IFERROR(H30/D30*1000,"") -> 7.2268265 | N30: =SUM(N3:N29) -> 467357 | O30: =SUM(O3:O29) -> 1035 | S30: =IFERROR(IF(ISBLANK(INDIRECT("'"&$Q$2&"'!G"&ROW())),"",INDIRECT("'"&$Q$2&"'!G"&ROW())),"") -> 0.18691152 | T30: =IF(OR($G30="",$S30=""),"",$G30-$S30) -> -0.36715187 | U30: =IFERROR(IF(ISBLANK(INDIRECT("'"&$Q$2&"'!K"&ROW())),"",INDIRECT("'"&$Q$2&"'!K"&ROW())),"") -> 0.12578995 | V30: =IF(OR($K30="",$U30=""),"",$K30-$U30) -> -0.23330725 | W30: =IFERROR(IF(ISBLANK(INDIRECT("'"&$Q$2&"'!O"&ROW())),"",INDIRECT("'"&$Q$2&"'!O"&ROW())),"") -> 1041 | X30: =IF(OR(C30=0,$O30="",$W30=""),"",$O30-$W30) -> -6
A31: Одноклассники | B31: Ямал-Медиа | C31: 117 | D31: 35824 | E31: =IF($D31="","",IFERROR(IF(ISBLANK(INDIRECT("'"&$Q$2&"'!D"&ROW())),"",INDIRECT("'"&$Q$2&"'!D"&ROW())),"")) -> 29953 | F31: =IF(OR(D31="",E31=""),"",D31-E31) -> 5871 | G31: =IFERROR(F31/E31,"") -> 0.19600708 | H31: 109 | I31: =IF($H31="","",IFERROR(IF(ISBLANK(INDIRECT("'"&$Q$2&"'!H"&ROW())),"",INDIRECT("'"&$Q$2&"'!H"&ROW())),"")) -> 158 | J31: =IF(OR(H31="",I31=""),"",H31-I31) -> -49 | K31: =IFERROR(J31/I31,"") -> -0.31012658 | L31: =IFERROR(D31/C31,"") -> 306.18803 | M31: =IFERROR(H31/D31*1000,"") -> 3.042653 | N31: 32496 | O31: =IFERROR(IF(OR(N31="",ISBLANK(INDIRECT("'"&$Q$2&"'!N"&ROW()))),"",N31-INDIRECT("'"&$Q$2&"'!N"&ROW())),"") -> 3 | S31: =IFERROR(IF(ISBLANK(INDIRECT("'"&$Q$2&"'!G"&ROW())),"",INDIRECT("'"&$Q$2&"'!G"&ROW())),"") -> 0.19391741 | T31: =IF(OR($G31="",$S31=""),"",$G31-$S31) -> 0.002089667 | U31: =IFERROR(IF(ISBLANK(INDIRECT("'"&$Q$2&"'!K"&ROW())),"",INDIRECT("'"&$Q$2&"'!K"&ROW())),"") -> 0.41071429 | V31: =IF(OR($K31="",$U31=""),"",$K31-$U31) -> -0.72084087 | W31: =IFERROR(IF(ISBLANK(INDIRECT("'"&$Q$2&"'!O"&ROW())),"",INDIRECT("'"&$Q$2&"'!O"&ROW())),"") -> 2 | X31: =IF(OR($O31="",$W31=""),"",$O31-$W31) -> 1
A32: Одноклассники | B32: Север-Пресс | C32: 108 | D32: 234396 | E32: =IF($D32="","",IFERROR(IF(ISBLANK(INDIRECT("'"&$Q$2&"'!D"&ROW())),"",INDIRECT("'"&$Q$2&"'!D"&ROW())),"")) -> 35196 | F32: =IF(OR(D32="",E32=""),"",D32-E32) -> 199200 | G32: =IFERROR(F32/E32,"") -> 5.6597341 | H32: 54 | I32: =IF($H32="","",IFERROR(IF(ISBLANK(INDIRECT("'"&$Q$2&"'!H"&ROW())),"",INDIRECT("'"&$Q$2&"'!H"&ROW())),"")) -> 30 | J32: =IF(OR(H32="",I32=""),"",H32-I32) -> 24 | K32: =IFERROR(J32/I32,"") -> 0.8 | L32: =IFERROR(D32/C32,"") -> 2170.3333 | M32: =IFERROR(H32/D32*1000,"") -> 0.23037936 | N32: 21745 | O32: =IFERROR(IF(OR(N32="",ISBLANK(INDIRECT("'"&$Q$2&"'!N"&ROW()))),"",N32-INDIRECT("'"&$Q$2&"'!N"&ROW())),"") -> 6 | S32: =IFERROR(IF(ISBLANK(INDIRECT("'"&$Q$2&"'!G"&ROW())),"",INDIRECT("'"&$Q$2&"'!G"&ROW())),"") -> 0.13072252 | T32: =IF(OR($G32="",$S32=""),"",$G32-$S32) -> 5.5290115 | U32: =IFERROR(IF(ISBLANK(INDIRECT("'"&$Q$2&"'!K"&ROW())),"",INDIRECT("'"&$Q$2&"'!K"&ROW())),"") -> -0.14285714 | V32: =IF(OR($K32="",$U32=""),"",$K32-$U32) -> 0.94285714 | W32: =IFERROR(IF(ISBLANK(INDIRECT("'"&$Q$2&"'!O"&ROW())),"",INDIRECT("'"&$Q$2&"'!O"&ROW())),"") -> 1 | X32: =IF(OR($O32="",$W32=""),"",$O32-$W32) -> 5
A33: Одноклассники | B33: Красный Север | C33: 76 | D33: 20354 | E33: =IF($D33="","",IFERROR(IF(ISBLANK(INDIRECT("'"&$Q$2&"'!D"&ROW())),"",INDIRECT("'"&$Q$2&"'!D"&ROW())),"")) -> 24690 | F33: =IF(OR(D33="",E33=""),"",D33-E33) -> -4336 | G33: =IFERROR(F33/E33,"") -> -0.17561766 | H33: 8 | I33: =IF($H33="","",IFERROR(IF(ISBLANK(INDIRECT("'"&$Q$2&"'!H"&ROW())),"",INDIRECT("'"&$Q$2&"'!H"&ROW())),"")) -> 20 | J33: =IF(OR(H33="",I33=""),"",H33-I33) -> -12 | K33: =IFERROR(J33/I33,"") -> -0.6 | L33: =IFERROR(D33/C33,"") -> 267.81579 | M33: =IFERROR(H33/D33*1000,"") -> 0.39304314 | N33: 8964 | O33: =IFERROR(IF(OR(N33="",ISBLANK(INDIRECT("'"&$Q$2&"'!N"&ROW()))),"",N33-INDIRECT("'"&$Q$2&"'!N"&ROW())),"") -> 0 | S33: =IFERROR(IF(ISBLANK(INDIRECT("'"&$Q$2&"'!G"&ROW())),"",INDIRECT("'"&$Q$2&"'!G"&ROW())),"") -> 0.0014602093 | T33: =IF(OR($G33="",$S33=""),"",$G33-$S33) -> -0.17707787 | U33: =IFERROR(IF(ISBLANK(INDIRECT("'"&$Q$2&"'!K"&ROW())),"",INDIRECT("'"&$Q$2&"'!K"&ROW())),"") -> 0.11111111 | V33: =IF(OR($K33="",$U33=""),"",$K33-$U33) -> -0.71111111 | W33: =IFERROR(IF(ISBLANK(INDIRECT("'"&$Q$2&"'!O"&ROW())),"",INDIRECT("'"&$Q$2&"'!O"&ROW())),"") -> 6 | X33: =IF(OR($O33="",$W33=""),"",$O33-$W33) -> -6
A34: Одноклассники | B34: Новый Уренгой | C34: 81 | D34: 742 | E34: =IF($D34="","",IFERROR(IF(ISBLANK(INDIRECT("'"&$Q$2&"'!D"&ROW())),"",INDIRECT("'"&$Q$2&"'!D"&ROW())),"")) -> 583 | F34: =IF(OR(D34="",E34=""),"",D34-E34) -> 159 | G34: =IFERROR(F34/E34,"") -> 0.27272727 | H34: 0 | I34: =IF($H34="","",IFERROR(IF(ISBLANK(INDIRECT("'"&$Q$2&"'!H"&ROW())),"",INDIRECT("'"&$Q$2&"'!H"&ROW())),"")) -> 0 | J34: =IF(OR(H34="",I34=""),"",H34-I34) -> 0 | K34: =IFERROR(J34/I34,"") | L34: =IFERROR(D34/C34,"") -> 9.1604938 | M34: =IFERROR(H34/D34*1000,"") -> 0 | N34: 6 | O34: =IFERROR(IF(OR(N34="",ISBLANK(INDIRECT("'"&$Q$2&"'!N"&ROW()))),"",N34-INDIRECT("'"&$Q$2&"'!N"&ROW())),"") -> 0 | S34: =IFERROR(IF(ISBLANK(INDIRECT("'"&$Q$2&"'!G"&ROW())),"",INDIRECT("'"&$Q$2&"'!G"&ROW())),"") -> -0.034768212 | T34: =IF(OR($G34="",$S34=""),"",$G34-$S34) -> 0.30749548 | U34: =IFERROR(IF(ISBLANK(INDIRECT("'"&$Q$2&"'!K"&ROW())),"",INDIRECT("'"&$Q$2&"'!K"&ROW())),"") | V34: =IF(OR($K34="",$U34=""),"",$K34-$U34) | W34: =IFERROR(IF(ISBLANK(INDIRECT("'"&$Q$2&"'!O"&ROW())),"",INDIRECT("'"&$Q$2&"'!O"&ROW())),"") -> 0 | X34: =IF(OR($O34="",$W34=""),"",$O34-$W34) -> 0
A35: Одноклассники | B35: Надым | C35: 74 | D35: 8077 | E35: =IF($D35="","",IFERROR(IF(ISBLANK(INDIRECT("'"&$Q$2&"'!D"&ROW())),"",INDIRECT("'"&$Q$2&"'!D"&ROW())),"")) -> 7094 | F35: =IF(OR(D35="",E35=""),"",D35-E35) -> 983 | G35: =IFERROR(F35/E35,"") -> 0.1385678 | H35: 93 | I35: =IF($H35="","",IFERROR(IF(ISBLANK(INDIRECT("'"&$Q$2&"'!H"&ROW())),"",INDIRECT("'"&$Q$2&"'!H"&ROW())),"")) -> 72 | J35: =IF(OR(H35="",I35=""),"",H35-I35) -> 21 | K35: =IFERROR(J35/I35,"") -> 0.29166667 | L35: =IFERROR(D35/C35,"") -> 109.14865 | M35: =IFERROR(H35/D35*1000,"") -> 11.514176 | N35: 1945 | O35: =IFERROR(IF(OR(N35="",ISBLANK(INDIRECT("'"&$Q$2&"'!N"&ROW()))),"",N35-INDIRECT("'"&$Q$2&"'!N"&ROW())),"") -> 2 | S35: =IFERROR(IF(ISBLANK(INDIRECT("'"&$Q$2&"'!G"&ROW())),"",INDIRECT("'"&$Q$2&"'!G"&ROW())),"") -> -0.19923242 | T35: =IF(OR($G35="",$S35=""),"",$G35-$S35) -> 0.33780022 | U35: =IFERROR(IF(ISBLANK(INDIRECT("'"&$Q$2&"'!K"&ROW())),"",INDIRECT("'"&$Q$2&"'!K"&ROW())),"") -> 0.028571429 | V35: =IF(OR($K35="",$U35=""),"",$K35-$U35) -> 0.26309524 | W35: =IFERROR(IF(ISBLANK(INDIRECT("'"&$Q$2&"'!O"&ROW())),"",INDIRECT("'"&$Q$2&"'!O"&ROW())),"") -> 2 | X35: =IF(OR($O35="",$W35=""),"",$O35-$W35) -> 0
A36: Одноклассники | B36: Ноябрьск | C36: 81 | D36: 27190 | E36: =IF($D36="","",IFERROR(IF(ISBLANK(INDIRECT("'"&$Q$2&"'!D"&ROW())),"",INDIRECT("'"&$Q$2&"'!D"&ROW())),"")) -> 35834 | F36: =IF(OR(D36="",E36=""),"",D36-E36) -> -8644 | G36: =IFERROR(F36/E36,"") -> -0.24122342 | H36: 374 | I36: =IF($H36="","",IFERROR(IF(ISBLANK(INDIRECT("'"&$Q$2&"'!H"&ROW())),"",INDIRECT("'"&$Q$2&"'!H"&ROW())),"")) -> 491 | J36: =IF(OR(H36="",I36=""),"",H36-I36) -> -117 | K36: =IFERROR(J36/I36,"") -> -0.23828921 | L36: =IFERROR(D36/C36,"") -> 335.67901 | M36: =IFERROR(H36/D36*1000,"") -> 13.755057 | N36: 5902 | O36: =IFERROR(IF(OR(N36="",ISBLANK(INDIRECT("'"&$Q$2&"'!N"&ROW()))),"",N36-INDIRECT("'"&$Q$2&"'!N"&ROW())),"") -> 6 | S36: =IFERROR(IF(ISBLANK(INDIRECT("'"&$Q$2&"'!G"&ROW())),"",INDIRECT("'"&$Q$2&"'!G"&ROW())),"") | T36: =IF(OR($G36="",$S36=""),"",$G36-$S36) | U36: =IFERROR(IF(ISBLANK(INDIRECT("'"&$Q$2&"'!K"&ROW())),"",INDIRECT("'"&$Q$2&"'!K"&ROW())),"") | V36: =IF(OR($K36="",$U36=""),"",$K36-$U36) | W36: =IFERROR(IF(ISBLANK(INDIRECT("'"&$Q$2&"'!O"&ROW())),"",INDIRECT("'"&$Q$2&"'!O"&ROW())),"") | X36: =IF(OR($O36="",$W36=""),"",$O36-$W36)
A37: Одноклассники | B37: Салехард | C37: 129 | D37: 5941 | E37: =IF($D37="","",IFERROR(IF(ISBLANK(INDIRECT("'"&$Q$2&"'!D"&ROW())),"",INDIRECT("'"&$Q$2&"'!D"&ROW())),"")) -> 7921 | F37: =IF(OR(D37="",E37=""),"",D37-E37) -> -1980 | G37: =IFERROR(F37/E37,"") -> -0.24996844 | H37: 68 | I37: =IF($H37="","",IFERROR(IF(ISBLANK(INDIRECT("'"&$Q$2&"'!H"&ROW())),"",INDIRECT("'"&$Q$2&"'!H"&ROW())),"")) -> 96 | J37: =IF(OR(H37="",I37=""),"",H37-I37) -> -28 | K37: =IFERROR(J37/I37,"") -> -0.29166667 | L37: =IFERROR(D37/C37,"") -> 46.054264 | M37: =IFERROR(H37/D37*1000,"") -> 11.445885 | N37: 3240 | O37: =IFERROR(IF(OR(N37="",ISBLANK(INDIRECT("'"&$Q$2&"'!N"&ROW()))),"",N37-INDIRECT("'"&$Q$2&"'!N"&ROW())),"") -> 1 | S37: =IFERROR(IF(ISBLANK(INDIRECT("'"&$Q$2&"'!G"&ROW())),"",INDIRECT("'"&$Q$2&"'!G"&ROW())),"") -> 0.41269841 | T37: =IF(OR($G37="",$S37=""),"",$G37-$S37) -> -0.66266685 | U37: =IFERROR(IF(ISBLANK(INDIRECT("'"&$Q$2&"'!K"&ROW())),"",INDIRECT("'"&$Q$2&"'!K"&ROW())),"") -> 4.3333333 | V37: =IF(OR($K37="",$U37=""),"",$K37-$U37) -> -4.625 | W37: =IFERROR(IF(ISBLANK(INDIRECT("'"&$Q$2&"'!O"&ROW())),"",INDIRECT("'"&$Q$2&"'!O"&ROW())),"") -> 1 | X37: =IF(OR($O37="",$W37=""),"",$O37-$W37) -> 0
A38: Одноклассники | B38: Приуралье | C38: 92 | D38: 7964 | E38: =IF($D38="","",IFERROR(IF(ISBLANK(INDIRECT("'"&$Q$2&"'!D"&ROW())),"",INDIRECT("'"&$Q$2&"'!D"&ROW())),"")) -> 10012 | F38: =IF(OR(D38="",E38=""),"",D38-E38) -> -2048 | G38: =IFERROR(F38/E38,"") -> -0.20455453 | H38: 201 | I38: =IF($H38="","",IFERROR(IF(ISBLANK(INDIRECT("'"&$Q$2&"'!H"&ROW())),"",INDIRECT("'"&$Q$2&"'!H"&ROW())),"")) -> 273 | J38: =IF(OR(H38="",I38=""),"",H38-I38) -> -72 | K38: =IFERROR(J38/I38,"") -> -0.26373626 | L38: =IFERROR(D38/C38,"") -> 86.565217 | M38: =IFERROR(H38/D38*1000,"") -> 25.238574 | N38: 1724 | O38: =IFERROR(IF(OR(N38="",ISBLANK(INDIRECT("'"&$Q$2&"'!N"&ROW()))),"",N38-INDIRECT("'"&$Q$2&"'!N"&ROW())),"") -> 8 | S38: =IFERROR(IF(ISBLANK(INDIRECT("'"&$Q$2&"'!G"&ROW())),"",INDIRECT("'"&$Q$2&"'!G"&ROW())),"") -> 0.094088078 | T38: =IF(OR($G38="",$S38=""),"",$G38-$S38) -> -0.29864261 | U38: =IFERROR(IF(ISBLANK(INDIRECT("'"&$Q$2&"'!K"&ROW())),"",INDIRECT("'"&$Q$2&"'!K"&ROW())),"") -> 0.80794702 | V38: =IF(OR($K38="",$U38=""),"",$K38-$U38) -> -1.0716833 | W38: =IFERROR(IF(ISBLANK(INDIRECT("'"&$Q$2&"'!O"&ROW())),"",INDIRECT("'"&$Q$2&"'!O"&ROW())),"") -> 5 | X38: =IF(OR($O38="",$W38=""),"",$O38-$W38) -> 3
A39: Одноклассники | B39: Лабытнанги | C39: 56 | D39: 4837 | E39: =IF($D39="","",IFERROR(IF(ISBLANK(INDIRECT("'"&$Q$2&"'!D"&ROW())),"",INDIRECT("'"&$Q$2&"'!D"&ROW())),"")) -> 4149 | F39: =IF(OR(D39="",E39=""),"",D39-E39) -> 688 | G39: =IFERROR(F39/E39,"") -> 0.16582309 | H39: 18 | I39: =IF($H39="","",IFERROR(IF(ISBLANK(INDIRECT("'"&$Q$2&"'!H"&ROW())),"",INDIRECT("'"&$Q$2&"'!H"&ROW())),"")) -> 2 | J39: =IF(OR(H39="",I39=""),"",H39-I39) -> 16 | K39: =IFERROR(J39/I39,"") -> 8 | L39: =IFERROR(D39/C39,"") -> 86.375 | M39: =IFERROR(H39/D39*1000,"") -> 3.7213149 | N39: 227 | O39: =IFERROR(IF(OR(N39="",ISBLANK(INDIRECT("'"&$Q$2&"'!N"&ROW()))),"",N39-INDIRECT("'"&$Q$2&"'!N"&ROW())),"") -> 1 | S39: =IFERROR(IF(ISBLANK(INDIRECT("'"&$Q$2&"'!G"&ROW())),"",INDIRECT("'"&$Q$2&"'!G"&ROW())),"") -> -0.0095488183 | T39: =IF(OR($G39="",$S39=""),"",$G39-$S39) -> 0.17537191 | U39: =IFERROR(IF(ISBLANK(INDIRECT("'"&$Q$2&"'!K"&ROW())),"",INDIRECT("'"&$Q$2&"'!K"&ROW())),"") -> -0.33333333 | V39: =IF(OR($K39="",$U39=""),"",$K39-$U39) -> 8.3333333 | W39: =IFERROR(IF(ISBLANK(INDIRECT("'"&$Q$2&"'!O"&ROW())),"",INDIRECT("'"&$Q$2&"'!O"&ROW())),"") -> 1 | X39: =IF(OR($O39="",$W39=""),"",$O39-$W39) -> 0
A40: Одноклассники | B40: Пуровский | C40: 47 | D40: 4555 | E40: =IF($D40="","",IFERROR(IF(ISBLANK(INDIRECT("'"&$Q$2&"'!D"&ROW())),"",INDIRECT("'"&$Q$2&"'!D"&ROW())),"")) -> 4445 | F40: =IF(OR(D40="",E40=""),"",D40-E40) -> 110 | G40: =IFERROR(F40/E40,"") -> 0.024746907 | H40: 49 | I40: =IF($H40="","",IFERROR(IF(ISBLANK(INDIRECT("'"&$Q$2&"'!H"&ROW())),"",INDIRECT("'"&$Q$2&"'!H"&ROW())),"")) -> 51 | J40: =IF(OR(H40="",I40=""),"",H40-I40) -> -2 | K40: =IFERROR(J40/I40,"") -> -0.039215686 | L40: =IFERROR(D40/C40,"") -> 96.914894 | M40: =IFERROR(H40/D40*1000,"") -> 10.757409 | N40: 4962 | O40: =IFERROR(IF(OR(N40="",ISBLANK(INDIRECT("'"&$Q$2&"'!N"&ROW()))),"",N40-INDIRECT("'"&$Q$2&"'!N"&ROW())),"") -> 0 | S40: =IFERROR(IF(ISBLANK(INDIRECT("'"&$Q$2&"'!G"&ROW())),"",INDIRECT("'"&$Q$2&"'!G"&ROW())),"") | T40: =IF(OR($G40="",$S40=""),"",$G40-$S40) | U40: =IFERROR(IF(ISBLANK(INDIRECT("'"&$Q$2&"'!K"&ROW())),"",INDIRECT("'"&$Q$2&"'!K"&ROW())),"") | V40: =IF(OR($K40="",$U40=""),"",$K40-$U40) | W40: =IFERROR(IF(ISBLANK(INDIRECT("'"&$Q$2&"'!O"&ROW())),"",INDIRECT("'"&$Q$2&"'!O"&ROW())),"") | X40: =IF(OR($O40="",$W40=""),"",$O40-$W40)
A41: Одноклассники | B41: Тазовский | C41: 51 | D41: 14510 | E41: =IF($D41="","",IFERROR(IF(ISBLANK(INDIRECT("'"&$Q$2&"'!D"&ROW())),"",INDIRECT("'"&$Q$2&"'!D"&ROW())),"")) -> 12178 | F41: =IF(OR(D41="",E41=""),"",D41-E41) -> 2332 | G41: =IFERROR(F41/E41,"") -> 0.19149286 | H41: 203 | I41: =IF($H41="","",IFERROR(IF(ISBLANK(INDIRECT("'"&$Q$2&"'!H"&ROW())),"",INDIRECT("'"&$Q$2&"'!H"&ROW())),"")) -> 109 | J41: =IF(OR(H41="",I41=""),"",H41-I41) -> 94 | K41: =IFERROR(J41/I41,"") -> 0.86238532 | L41: =IFERROR(D41/C41,"") -> 284.5098 | M41: =IFERROR(H41/D41*1000,"") -> 13.990351 | N41: 3534 | O41: =IFERROR(IF(OR(N41="",ISBLANK(INDIRECT("'"&$Q$2&"'!N"&ROW()))),"",N41-INDIRECT("'"&$Q$2&"'!N"&ROW())),"") -> 2 | S41: =IFERROR(IF(ISBLANK(INDIRECT("'"&$Q$2&"'!G"&ROW())),"",INDIRECT("'"&$Q$2&"'!G"&ROW())),"") -> -0.017110573 | T41: =IF(OR($G41="",$S41=""),"",$G41-$S41) -> 0.20860343 | U41: =IFERROR(IF(ISBLANK(INDIRECT("'"&$Q$2&"'!K"&ROW())),"",INDIRECT("'"&$Q$2&"'!K"&ROW())),"") -> -0.099173554 | V41: =IF(OR($K41="",$U41=""),"",$K41-$U41) -> 0.96155887 | W41: =IFERROR(IF(ISBLANK(INDIRECT("'"&$Q$2&"'!O"&ROW())),"",INDIRECT("'"&$Q$2&"'!O"&ROW())),"") -> 1 | X41: =IF(OR($O41="",$W41=""),"",$O41-$W41) -> 1
A42: Одноклассники | B42: Красноселькуп | C42: 23 | D42: 7493 | E42: =IF($D42="","",IFERROR(IF(ISBLANK(INDIRECT("'"&$Q$2&"'!D"&ROW())),"",INDIRECT("'"&$Q$2&"'!D"&ROW())),"")) -> 5911 | F42: =IF(OR(D42="",E42=""),"",D42-E42) -> 1582 | G42: =IFERROR(F42/E42,"") -> 0.26763661 | H42: 157 | I42: =IF($H42="","",IFERROR(IF(ISBLANK(INDIRECT("'"&$Q$2&"'!H"&ROW())),"",INDIRECT("'"&$Q$2&"'!H"&ROW())),"")) -> 82 | J42: =IF(OR(H42="",I42=""),"",H42-I42) -> 75 | K42: =IFERROR(J42/I42,"") -> 0.91463415 | L42: =IFERROR(D42/C42,"") -> 325.78261 | M42: =IFERROR(H42/D42*1000,"") -> 20.952889 | N42: 657 | O42: =IFERROR(IF(OR(N42="",ISBLANK(INDIRECT("'"&$Q$2&"'!N"&ROW()))),"",N42-INDIRECT("'"&$Q$2&"'!N"&ROW())),"") -> 2 | S42: =IFERROR(IF(ISBLANK(INDIRECT("'"&$Q$2&"'!G"&ROW())),"",INDIRECT("'"&$Q$2&"'!G"&ROW())),"") -> -0.10357901 | T42: =IF(OR($G42="",$S42=""),"",$G42-$S42) -> 0.37121562 | U42: =IFERROR(IF(ISBLANK(INDIRECT("'"&$Q$2&"'!K"&ROW())),"",INDIRECT("'"&$Q$2&"'!K"&ROW())),"") -> -0.012048193 | V42: =IF(OR($K42="",$U42=""),"",$K42-$U42) -> 0.92668234 | W42: =IFERROR(IF(ISBLANK(INDIRECT("'"&$Q$2&"'!O"&ROW())),"",INDIRECT("'"&$Q$2&"'!O"&ROW())),"") -> 2 | X42: =IF(OR($O42="",$W42=""),"",$O42-$W42) -> 0
... A50: Одноклассники | B50: Морошка | C50: 7 | D50: 837 | E50: =IF($D50="","",IFERROR(IF(ISBLANK(INDIRECT("'"&$Q$2&"'!D"&ROW())),"",INDIRECT("'"&$Q$2&"'!D"&ROW())),"")) -> 388 | F50: =IF(OR(D50="",E50=""),"",D50-E50) -> 449 | G50: =IFERROR(F50/E50,"") -> 1.1572165 | H50: 6 | I50: =IF($H50="","",IFERROR(IF(ISBLANK(INDIRECT("'"&$Q$2&"'!H"&ROW())),"",INDIRECT("'"&$Q$2&"'!H"&ROW())),"")) -> 2 | J50: =IF(OR(H50="",I50=""),"",H50-I50) -> 4 | K50: =IFERROR(J50/I50,"") -> 2 | L50: =IFERROR(D50/C50,"") -> 119.57143 | M50: =IFERROR(H50/D50*1000,"") -> 7.1684588 | N50: 44 | O50: =IFERROR(IF(OR(N50="",ISBLANK(INDIRECT("'"&$Q$2&"'!N"&ROW()))),"",N50-INDIRECT("'"&$Q$2&"'!N"&ROW())),"") -> 1 | S50: =IFERROR(IF(ISBLANK(INDIRECT("'"&$Q$2&"'!G"&ROW())),"",INDIRECT("'"&$Q$2&"'!G"&ROW())),"") | T50: =IF(OR($G50="",$S50=""),"",$G50-$S50) | U50: =IFERROR(IF(ISBLANK(INDIRECT("'"&$Q$2&"'!K"&ROW())),"",INDIRECT("'"&$Q$2&"'!K"&ROW())),"") | V50: =IF(OR($K50="",$U50=""),"",$K50-$U50) | W50: =IFERROR(IF(ISBLANK(INDIRECT("'"&$Q$2&"'!O"&ROW())),"",INDIRECT("'"&$Q$2&"'!O"&ROW())),"") | X50: =IF(OR($O50="",$W50=""),"",$O50-$W50)
B51: Итого Одноклассники | C51: =SUM(C31:C50) -> 1386 | D51: =SUM(D31:D50) -> 438012 | E51: =SUM(E31:E50) -> 244021 | F51: =SUM(F31:F50) -> 193991 | G51: =IF(C51=0,"",IFERROR(F51/E51,"")) -> 0.79497666 | H51: =SUM(H31:H50) -> 2376 | I51: =SUM(I31:I50) -> 2293 | J51: =SUM(J31:J50) -> 83 | K51: =IF(C51=0,"",IFERROR(J51/I51,"")) -> 0.036197122 | L51: =IFERROR(D51/C51,"") -> 316.02597 | M51: =IFERROR(H51/D51*1000,"") -> 5.4245089 | N51: =SUM(N31:N50) -> 107120 | O51: =SUM(O31:O50) -> 48 | S51: =IFERROR(IF(ISBLANK(INDIRECT("'"&$Q$2&"'!G"&ROW())),"",INDIRECT("'"&$Q$2&"'!G"&ROW())),"") -> 0.072161355 | T51: =IF(OR($G51="",$S51=""),"",$G51-$S51) -> 0.72281531 | U51: =IFERROR(IF(ISBLANK(INDIRECT("'"&$Q$2&"'!K"&ROW())),"",INDIRECT("'"&$Q$2&"'!K"&ROW())),"") -> 0.17495712 | V51: =IF(OR($K51="",$U51=""),"",$K51-$U51) -> -0.13876 | W51: =IFERROR(IF(ISBLANK(INDIRECT("'"&$Q$2&"'!O"&ROW())),"",INDIRECT("'"&$Q$2&"'!O"&ROW())),"") -> 31 | X51: =IF(OR(C51=0,$O51="",$W51=""),"",$O51-$W51) -> 17
A52: Telegram | B52: Ямал-Медиа | C52: 139 | D52: 36166 | E52: =IF($D52="","",IFERROR(IF(ISBLANK(INDIRECT("'"&$Q$2&"'!D"&ROW())),"",INDIRECT("'"&$Q$2&"'!D"&ROW())),"")) -> 57464 | F52: =IF(OR(D52="",E52=""),"",D52-E52) -> -21298 | G52: =IFERROR(F52/E52,"") -> -0.37063205 | H52: 267 | I52: =IF($H52="","",IFERROR(IF(ISBLANK(INDIRECT("'"&$Q$2&"'!H"&ROW())),"",INDIRECT("'"&$Q$2&"'!H"&ROW())),"")) -> 262 | J52: =IF(OR(H52="",I52=""),"",H52-I52) -> 5 | K52: =IFERROR(J52/I52,"") -> 0.019083969 | L52: =IFERROR(D52/C52,"") -> 260.18705 | M52: =IFERROR(H52/D52*1000,"") -> 7.3826246 | N52: 11727 | O52: =IFERROR(IF(OR(N52="",ISBLANK(INDIRECT("'"&$Q$2&"'!N"&ROW()))),"",N52-INDIRECT("'"&$Q$2&"'!N"&ROW())),"") -> -14 | S52: =IFERROR(IF(ISBLANK(INDIRECT("'"&$Q$2&"'!G"&ROW())),"",INDIRECT("'"&$Q$2&"'!G"&ROW())),"") -> -0.33832301 | T52: =IF(OR($G52="",$S52=""),"",$G52-$S52) -> -0.032309039 | U52: =IFERROR(IF(ISBLANK(INDIRECT("'"&$Q$2&"'!K"&ROW())),"",INDIRECT("'"&$Q$2&"'!K"&ROW())),"") -> 0 | V52: =IF(OR($K52="",$U52=""),"",$K52-$U52) -> 0.019083969 | W52: =IFERROR(IF(ISBLANK(INDIRECT("'"&$Q$2&"'!O"&ROW())),"",INDIRECT("'"&$Q$2&"'!O"&ROW())),"") -> -23 | X52: =IF(OR($O52="",$W52=""),"",$O52-$W52) -> 9
A53: Telegram | B53: Север-Пресс | C53: 130 | D53: 43966 | E53: =IF($D53="","",IFERROR(IF(ISBLANK(INDIRECT("'"&$Q$2&"'!D"&ROW())),"",INDIRECT("'"&$Q$2&"'!D"&ROW())),"")) -> 43678 | F53: =IF(OR(D53="",E53=""),"",D53-E53) -> 288 | G53: =IFERROR(F53/E53,"") -> 0.0065937085 | H53: 41 | I53: =IF($H53="","",IFERROR(IF(ISBLANK(INDIRECT("'"&$Q$2&"'!H"&ROW())),"",INDIRECT("'"&$Q$2&"'!H"&ROW())),"")) -> 41 | J53: =IF(OR(H53="",I53=""),"",H53-I53) -> 0 | K53: =IFERROR(J53/I53,"") -> 0 | L53: =IFERROR(D53/C53,"") -> 338.2 | M53: =IFERROR(H53/D53*1000,"") -> 0.93253878 | N53: 4781 | O53: =IFERROR(IF(OR(N53="",ISBLANK(INDIRECT("'"&$Q$2&"'!N"&ROW()))),"",N53-INDIRECT("'"&$Q$2&"'!N"&ROW())),"") -> -9 | S53: =IFERROR(IF(ISBLANK(INDIRECT("'"&$Q$2&"'!G"&ROW())),"",INDIRECT("'"&$Q$2&"'!G"&ROW())),"") -> 1.7730303 | T53: =IF(OR($G53="",$S53=""),"",$G53-$S53) -> -1.7664366 | U53: =IFERROR(IF(ISBLANK(INDIRECT("'"&$Q$2&"'!K"&ROW())),"",INDIRECT("'"&$Q$2&"'!K"&ROW())),"") -> -0.29310345 | V53: =IF(OR($K53="",$U53=""),"",$K53-$U53) -> 0.29310345 | W53: =IFERROR(IF(ISBLANK(INDIRECT("'"&$Q$2&"'!O"&ROW())),"",INDIRECT("'"&$Q$2&"'!O"&ROW())),"") -> -21 | X53: =IF(OR($O53="",$W53=""),"",$O53-$W53) -> 12
A54: Telegram | B54: Красный Север | C54: 83 | D54: 1844 | E54: =IF($D54="","",IFERROR(IF(ISBLANK(INDIRECT("'"&$Q$2&"'!D"&ROW())),"",INDIRECT("'"&$Q$2&"'!D"&ROW())),"")) -> 1927 | F54: =IF(OR(D54="",E54=""),"",D54-E54) -> -83 | G54: =IFERROR(F54/E54,"") -> -0.043072133 | H54: 5 | I54: =IF($H54="","",IFERROR(IF(ISBLANK(INDIRECT("'"&$Q$2&"'!H"&ROW())),"",INDIRECT("'"&$Q$2&"'!H"&ROW())),"")) -> 2 | J54: =IF(OR(H54="",I54=""),"",H54-I54) -> 3 | K54: =IFERROR(J54/I54,"") -> 1.5 | L54: =IFERROR(D54/C54,"") -> 22.216867 | M54: =IFERROR(H54/D54*1000,"") -> 2.7114967 | N54: 867 | O54: =IFERROR(IF(OR(N54="",ISBLANK(INDIRECT("'"&$Q$2&"'!N"&ROW()))),"",N54-INDIRECT("'"&$Q$2&"'!N"&ROW())),"") -> -1 | S54: =IFERROR(IF(ISBLANK(INDIRECT("'"&$Q$2&"'!G"&ROW())),"",INDIRECT("'"&$Q$2&"'!G"&ROW())),"") -> -0.055854973 | T54: =IF(OR($G54="",$S54=""),"",$G54-$S54) -> 0.01278284 | U54: =IFERROR(IF(ISBLANK(INDIRECT("'"&$Q$2&"'!K"&ROW())),"",INDIRECT("'"&$Q$2&"'!K"&ROW())),"") -> 0 | V54: =IF(OR($K54="",$U54=""),"",$K54-$U54) -> 1.5 | W54: =IFERROR(IF(ISBLANK(INDIRECT("'"&$Q$2&"'!O"&ROW())),"",INDIRECT("'"&$Q$2&"'!O"&ROW())),"") -> -2 | X54: =IF(OR($O54="",$W54=""),"",$O54-$W54) -> 1
A55: Telegram | B55: СМП | C55: 9 | D55: 8837 | E55: =IF($D55="","",IFERROR(IF(ISBLANK(INDIRECT("'"&$Q$2&"'!D"&ROW())),"",INDIRECT("'"&$Q$2&"'!D"&ROW())),"")) -> 6726 | F55: =IF(OR(D55="",E55=""),"",D55-E55) -> 2111 | G55: =IFERROR(F55/E55,"") -> 0.31385668 | H55: 48 | I55: =IF($H55="","",IFERROR(IF(ISBLANK(INDIRECT("'"&$Q$2&"'!H"&ROW())),"",INDIRECT("'"&$Q$2&"'!H"&ROW())),"")) -> 28 | J55: =IF(OR(H55="",I55=""),"",H55-I55) -> 20 | K55: =IFERROR(J55/I55,"") -> 0.71428571 | L55: =IFERROR(D55/C55,"") -> 981.88889 | M55: =IFERROR(H55/D55*1000,"") -> 5.4317076 | N55: 13774 | O55: =IFERROR(IF(OR(N55="",ISBLANK(INDIRECT("'"&$Q$2&"'!N"&ROW()))),"",N55-INDIRECT("'"&$Q$2&"'!N"&ROW())),"") -> -30 | S55: =IFERROR(IF(ISBLANK(INDIRECT("'"&$Q$2&"'!G"&ROW())),"",INDIRECT("'"&$Q$2&"'!G"&ROW())),"") -> 0.044409938 | T55: =IF(OR($G55="",$S55=""),"",$G55-$S55) -> 0.26944674 | U55: =IFERROR(IF(ISBLANK(INDIRECT("'"&$Q$2&"'!K"&ROW())),"",INDIRECT("'"&$Q$2&"'!K"&ROW())),"") -> -0.52542373 | V55: =IF(OR($K55="",$U55=""),"",$K55-$U55) -> 1.2397094 | W55: =IFERROR(IF(ISBLANK(INDIRECT("'"&$Q$2&"'!O"&ROW())),"",INDIRECT("'"&$Q$2&"'!O"&ROW())),"") -> 5 | X55: =IF(OR($O55="",$W55=""),"",$O55-$W55) -> -35
A56: Telegram | B56: СШХ | C56: 7 | D56: 310 | E56: =IF($D56="","",IFERROR(IF(ISBLANK(INDIRECT("'"&$Q$2&"'!D"&ROW())),"",INDIRECT("'"&$Q$2&"'!D"&ROW())),"")) -> 2676 | F56: =IF(OR(D56="",E56=""),"",D56-E56) -> -2366 | G56: =IFERROR(F56/E56,"") -> -0.88415546 | H56: 11 | I56: =IF($H56="","",IFERROR(IF(ISBLANK(INDIRECT("'"&$Q$2&"'!H"&ROW())),"",INDIRECT("'"&$Q$2&"'!H"&ROW())),"")) -> 24 | J56: =IF(OR(H56="",I56=""),"",H56-I56) -> -13 | K56: =IFERROR(J56/I56,"") -> -0.54166667 | L56: =IFERROR(D56/C56,"") -> 44.285714 | M56: =IFERROR(H56/D56*1000,"") -> 35.483871 | N56: 8643 | O56: =IFERROR(IF(OR(N56="",ISBLANK(INDIRECT("'"&$Q$2&"'!N"&ROW()))),"",N56-INDIRECT("'"&$Q$2&"'!N"&ROW())),"") -> -10 | S56: =IFERROR(IF(ISBLANK(INDIRECT("'"&$Q$2&"'!G"&ROW())),"",INDIRECT("'"&$Q$2&"'!G"&ROW())),"") -> 0.17471466 | T56: =IF(OR($G56="",$S56=""),"",$G56-$S56) -> -1.0588701 | U56: =IFERROR(IF(ISBLANK(INDIRECT("'"&$Q$2&"'!K"&ROW())),"",INDIRECT("'"&$Q$2&"'!K"&ROW())),"") -> 1 | V56: =IF(OR($K56="",$U56=""),"",$K56-$U56) -> -1.5416667 | W56: =IFERROR(IF(ISBLANK(INDIRECT("'"&$Q$2&"'!O"&ROW())),"",INDIRECT("'"&$Q$2&"'!O"&ROW())),"") -> -5 | X56: =IF(OR($O56="",$W56=""),"",$O56-$W56) -> -5
A57: Telegram | B57: Новый Уренгой | C57: 111 | D57: 65072 | E57: =IF($D57="","",IFERROR(IF(ISBLANK(INDIRECT("'"&$Q$2&"'!D"&ROW())),"",INDIRECT("'"&$Q$2&"'!D"&ROW())),"")) -> 53833 | F57: =IF(OR(D57="",E57=""),"",D57-E57) -> 11239 | G57: =IFERROR(F57/E57,"") -> 0.20877529 | H57: 255 | I57: =IF($H57="","",IFERROR(IF(ISBLANK(INDIRECT("'"&$Q$2&"'!H"&ROW())),"",INDIRECT("'"&$Q$2&"'!H"&ROW())),"")) -> 201 | J57: =IF(OR(H57="",I57=""),"",H57-I57) -> 54 | K57: =IFERROR(J57/I57,"") -> 0.26865672 | L57: =IFERROR(D57/C57,"") -> 586.23423 | M57: =IFERROR(H57/D57*1000,"") -> 3.9187362 | N57: 10852 | O57: =IFERROR(IF(OR(N57="",ISBLANK(INDIRECT("'"&$Q$2&"'!N"&ROW()))),"",N57-INDIRECT("'"&$Q$2&"'!N"&ROW())),"") -> -12 | S57: =IFERROR(IF(ISBLANK(INDIRECT("'"&$Q$2&"'!G"&ROW())),"",INDIRECT("'"&$Q$2&"'!G"&ROW())),"") -> -0.15251649 | T57: =IF(OR($G57="",$S57=""),"",$G57-$S57) -> 0.36129178 | U57: =IFERROR(IF(ISBLANK(INDIRECT("'"&$Q$2&"'!K"&ROW())),"",INDIRECT("'"&$Q$2&"'!K"&ROW())),"") -> -0.19277108 | V57: =IF(OR($K57="",$U57=""),"",$K57-$U57) -> 0.4614278 | W57: =IFERROR(IF(ISBLANK(INDIRECT("'"&$Q$2&"'!O"&ROW())),"",INDIRECT("'"&$Q$2&"'!O"&ROW())),"") -> -17 | X57: =IF(OR($O57="",$W57=""),"",$O57-$W57) -> 5
A58: Telegram | B58: Надым | C58: 89 | D58: 18992 | E58: =IF($D58="","",IFERROR(IF(ISBLANK(INDIRECT("'"&$Q$2&"'!D"&ROW())),"",INDIRECT("'"&$Q$2&"'!D"&ROW())),"")) -> 18052 | F58: =IF(OR(D58="",E58=""),"",D58-E58) -> 940 | G58: =IFERROR(F58/E58,"") -> 0.052071793 | H58: 294 | I58: =IF($H58="","",IFERROR(IF(ISBLANK(INDIRECT("'"&$Q$2&"'!H"&ROW())),"",INDIRECT("'"&$Q$2&"'!H"&ROW())),"")) -> 315 | J58: =IF(OR(H58="",I58=""),"",H58-I58) -> -21 | K58: =IFERROR(J58/I58,"") -> -0.066666667 | L58: =IFERROR(D58/C58,"") -> 213.39326 | M58: =IFERROR(H58/D58*1000,"") -> 15.480202 | N58: 4077 | O58: =IFERROR(IF(OR(N58="",ISBLANK(INDIRECT("'"&$Q$2&"'!N"&ROW()))),"",N58-INDIRECT("'"&$Q$2&"'!N"&ROW())),"") -> -18 | S58: =IFERROR(IF(ISBLANK(INDIRECT("'"&$Q$2&"'!G"&ROW())),"",INDIRECT("'"&$Q$2&"'!G"&ROW())),"") -> -0.16784216 | T58: =IF(OR($G58="",$S58=""),"",$G58-$S58) -> 0.21991395 | U58: =IFERROR(IF(ISBLANK(INDIRECT("'"&$Q$2&"'!K"&ROW())),"",INDIRECT("'"&$Q$2&"'!K"&ROW())),"") -> -0.12256267 | V58: =IF(OR($K58="",$U58=""),"",$K58-$U58) -> 0.055896007 | W58: =IFERROR(IF(ISBLANK(INDIRECT("'"&$Q$2&"'!O"&ROW())),"",INDIRECT("'"&$Q$2&"'!O"&ROW())),"") -> -6 | X58: =IF(OR($O58="",$W58=""),"",$O58-$W58) -> -12
A59: Telegram | B59: Ноябрьск | C59: 92 | D59: 30303 | E59: =IF($D59="","",IFERROR(IF(ISBLANK(INDIRECT("'"&$Q$2&"'!D"&ROW())),"",INDIRECT("'"&$Q$2&"'!D"&ROW())),"")) -> 29628 | F59: =IF(OR(D59="",E59=""),"",D59-E59) -> 675 | G59: =IFERROR(F59/E59,"") -> 0.022782503 | H59: 212 | I59: =IF($H59="","",IFERROR(IF(ISBLANK(INDIRECT("'"&$Q$2&"'!H"&ROW())),"",INDIRECT("'"&$Q$2&"'!H"&ROW())),"")) -> 148 | J59: =IF(OR(H59="",I59=""),"",H59-I59) -> 64 | K59: =IFERROR(J59/I59,"") -> 0.43243243 | L59: =IFERROR(D59/C59,"") -> 329.38043 | M59: =IFERROR(H59/D59*1000,"") -> 6.996007 | N59: 5495 | O59: =IFERROR(IF(OR(N59="",ISBLANK(INDIRECT("'"&$Q$2&"'!N"&ROW()))),"",N59-INDIRECT("'"&$Q$2&"'!N"&ROW())),"") -> -9 | S59: =IFERROR(IF(ISBLANK(INDIRECT("'"&$Q$2&"'!G"&ROW())),"",INDIRECT("'"&$Q$2&"'!G"&ROW())),"") -> -0.12317254 | T59: =IF(OR($G59="",$S59=""),"",$G59-$S59) -> 0.14595504 | U59: =IFERROR(IF(ISBLANK(INDIRECT("'"&$Q$2&"'!K"&ROW())),"",INDIRECT("'"&$Q$2&"'!K"&ROW())),"") -> -0.42635659 | V59: =IF(OR($K59="",$U59=""),"",$K59-$U59) -> 0.85878902 | W59: =IFERROR(IF(ISBLANK(INDIRECT("'"&$Q$2&"'!O"&ROW())),"",INDIRECT("'"&$Q$2&"'!O"&ROW())),"") -> -15 | X59: =IF(OR($O59="",$W59=""),"",$O59-$W59) -> 6
...

Sheet 28.09-04.10
A1: Недельный съём · 28.09–04.10.2026 | Q1: Лист прошлой недели (питает колонки E, I, O):
A2: Площадка | B2: Ресурс | C2: Публикаций | D2: Просмотры | E2: Просмотры пред. неделя | F2: Δ просмотров | G2: Δ % | H2: Лайки | I2: Лайки пред. неделя | J2: Δ лайков | K2: Δ % | L2: Ср. просмотров на пост | M2: Лайков на 1000 просмотров | N2: Подписчики | O2: Прирост подписчиков | Q2: 21-27.09 | S2: Δ % просмотров пред. неделя | T2: Ускорение просмотров, п.п. | U2: Δ % лайков пред. неделя | V2: Ускорение лайков, п.п. | W2: Прирост подписч. пред. неделя | X2: Ускорение подписчиков, чел.
A3: ВКонтакте | B3: Ямал-Медиа | C3: 110 | D3: 2647589 | E3: =IF($D3="","",IFERROR(IF(ISBLANK(INDIRECT("'"&$Q$2&"'!D"&ROW())),"",INDIRECT("'"&$Q$2&"'!D"&ROW())),"")) -> 1913477 | F3: =IF(OR(D3="",E3=""),"",D3-E3) -> 734112 | G3: =IFERROR(F3/E3,"") -> 0.38365342 | H3: 5901 | I3: =IF($H3="","",IFERROR(IF(ISBLANK(INDIRECT("'"&$Q$2&"'!H"&ROW())),"",INDIRECT("'"&$Q$2&"'!H"&ROW())),"")) -> 4474 | J3: =IF(OR(H3="",I3=""),"",H3-I3) -> 1427 | K3: =IFERROR(J3/I3,"") -> 0.31895396 | L3: =IFERROR(D3/C3,"") -> 24068.991 | M3: =IFERROR(H3/D3*1000,"") -> 2.2288203 | N3: 89650 | O3: =IFERROR(IF(OR(N3="",ISBLANK(INDIRECT("'"&$Q$2&"'!N"&ROW()))),"",N3-INDIRECT("'"&$Q$2&"'!N"&ROW())),"") -> 292 | Q3: Колонки E и I берут прошлую неделю только по строкам, снятым в текущей — сравнение идёт по сопоставимому периметру. | S3: =IFERROR(IF(ISBLANK(INDIRECT("'"&$Q$2&"'!G"&ROW())),"",INDIRECT("'"&$Q$2&"'!G"&ROW())),"") -> 2.7020111 | T3: =IF(OR($G3="",$S3=""),"",$G3-$S3) -> -2.3183577 | U3: =IFERROR(IF(ISBLANK(INDIRECT("'"&$Q$2&"'!K"&ROW())),"",INDIRECT("'"&$Q$2&"'!K"&ROW())),"") -> 1.3026248 | V3: =IF(OR($K3="",$U3=""),"",$K3-$U3) -> -0.98367085 | W3: =IFERROR(IF(ISBLANK(INDIRECT("'"&$Q$2&"'!O"&ROW())),"",INDIRECT("'"&$Q$2&"'!O"&ROW())),"") -> 282 | X3: =IF(OR($O3="",$W3=""),"",$O3-$W3) -> 10
A4: ВКонтакте | B4: Север-Пресс | C4: 120 | D4: 218156 | E4: =IF($D4="","",IFERROR(IF(ISBLANK(INDIRECT("'"&$Q$2&"'!D"&ROW())),"",INDIRECT("'"&$Q$2&"'!D"&ROW())),"")) -> 126444 | F4: =IF(OR(D4="",E4=""),"",D4-E4) -> 91712 | G4: =IFERROR(F4/E4,"") -> 0.72531714 | H4: 672 | I4: =IF($H4="","",IFERROR(IF(ISBLANK(INDIRECT("'"&$Q$2&"'!H"&ROW())),"",INDIRECT("'"&$Q$2&"'!H"&ROW())),"")) -> 528 | J4: =IF(OR(H4="",I4=""),"",H4-I4) -> 144 | K4: =IFERROR(J4/I4,"") -> 0.27272727 | L4: =IFERROR(D4/C4,"") -> 1817.9667 | M4: =IFERROR(H4/D4*1000,"") -> 3.0803645 | N4: 26291 | O4: =IFERROR(IF(OR(N4="",ISBLANK(INDIRECT("'"&$Q$2&"'!N"&ROW()))),"",N4-INDIRECT("'"&$Q$2&"'!N"&ROW())),"") -> 31 | Q4: ОК: «просмотры» = VIEWS листа Topics, лайки = сумма LIKES листа Actions (по группе, как в прошлых съёмах). | S4: =IFERROR(IF(ISBLANK(INDIRECT("'"&$Q$2&"'!G"&ROW())),"",INDIRECT("'"&$Q$2&"'!G"&ROW())),"") -> -0.41516616 | T4: =IF(OR($G4="",$S4=""),"",$G4-$S4) -> 1.1404833 | U4: =IFERROR(IF(ISBLANK(INDIRECT("'"&$Q$2&"'!K"&ROW())),"",INDIRECT("'"&$Q$2&"'!K"&ROW())),"") -> -0.24028777 | V4: =IF(OR($K4="",$U4=""),"",$K4-$U4) -> 0.51301504 | W4: =IFERROR(IF(ISBLANK(INDIRECT("'"&$Q$2&"'!O"&ROW())),"",INDIRECT("'"&$Q$2&"'!O"&ROW())),"") -> 11 | X4: =IF(OR($O4="",$W4=""),"",$O4-$W4) -> 20
A5: ВКонтакте | B5: Лента СП | C5: 171 | D5: 2991 | E5: =IF($D5="","",IFERROR(IF(ISBLANK(INDIRECT("'"&$Q$2&"'!D"&ROW())),"",INDIRECT("'"&$Q$2&"'!D"&ROW())),"")) -> 3977 | F5: =IF(OR(D5="",E5=""),"",D5-E5) -> -986 | G5: =IFERROR(F5/E5,"") -> -0.24792557 | H5: 12 | I5: =IF($H5="","",IFERROR(IF(ISBLANK(INDIRECT("'"&$Q$2&"'!H"&ROW())),"",INDIRECT("'"&$Q$2&"'!H"&ROW())),"")) -> 12 | J5: =IF(OR(H5="",I5=""),"",H5-I5) -> 0 | K5: =IFERROR(J5/I5,"") -> 0 | L5: =IFERROR(D5/C5,"") -> 17.491228 | M5: =IFERROR(H5/D5*1000,"") -> 4.0120361 | N5: 3503 | O5: =IFERROR(IF(OR(N5="",ISBLANK(INDIRECT("'"&$Q$2&"'!N"&ROW()))),"",N5-INDIRECT("'"&$Q$2&"'!N"&ROW())),"") -> 3 | S5: =IFERROR(IF(ISBLANK(INDIRECT("'"&$Q$2&"'!G"&ROW())),"",INDIRECT("'"&$Q$2&"'!G"&ROW())),"") -> -0.058252427 | T5: =IF(OR($G5="",$S5=""),"",$G5-$S5) -> -0.18967314 | U5: =IFERROR(IF(ISBLANK(INDIRECT("'"&$Q$2&"'!K"&ROW())),"",INDIRECT("'"&$Q$2&"'!K"&ROW())),"") -> 0.2 | V5: =IF(OR($K5="",$U5=""),"",$K5-$U5) -> -0.2 | W5: =IFERROR(IF(ISBLANK(INDIRECT("'"&$Q$2&"'!O"&ROW())),"",INDIRECT("'"&$Q$2&"'!O"&ROW())),"") -> -1 | X5: =IF(OR($O5="",$W5=""),"",$O5-$W5) -> 4
A6: ВКонтакте | B6: Красный Север | C6: 83 | D6: 79350 | E6: =IF($D6="","",IFERROR(IF(ISBLANK(INDIRECT("'"&$Q$2&"'!D"&ROW())),"",INDIRECT("'"&$Q$2&"'!D"&ROW())),"")) -> 63285 | F6: =IF(OR(D6="",E6=""),"",D6-E6) -> 16065 | G6: =IFERROR(F6/E6,"") -> 0.25385162 | H6: 466 | I6: =IF($H6="","",IFERROR(IF(ISBLANK(INDIRECT("'"&$Q$2&"'!H"&ROW())),"",INDIRECT("'"&$Q$2&"'!H"&ROW())),"")) -> 343 | J6: =IF(OR(H6="",I6=""),"",H6-I6) -> 123 | K6: =IFERROR(J6/I6,"") -> 0.35860058 | L6: =IFERROR(D6/C6,"") -> 956.0241 | M6: =IFERROR(H6/D6*1000,"") -> 5.8727158 | N6: 22949 | O6: =IFERROR(IF(OR(N6="",ISBLANK(INDIRECT("'"&$Q$2&"'!N"&ROW()))),"",N6-INDIRECT("'"&$Q$2&"'!N"&ROW())),"") -> 17 | S6: =IFERROR(IF(ISBLANK(INDIRECT("'"&$Q$2&"'!G"&ROW())),"",INDIRECT("'"&$Q$2&"'!G"&ROW())),"") -> 0.2089518 | T6: =IF(OR($G6="",$S6=""),"",$G6-$S6) -> 0.044899821 | U6: =IFERROR(IF(ISBLANK(INDIRECT("'"&$Q$2&"'!K"&ROW())),"",INDIRECT("'"&$Q$2&"'!K"&ROW())),"") -> 0.17869416 | V6: =IF(OR($K6="",$U6=""),"",$K6-$U6) -> 0.17990643 | W6: =IFERROR(IF(ISBLANK(INDIRECT("'"&$Q$2&"'!O"&ROW())),"",INDIRECT("'"&$Q$2&"'!O"&ROW())),"") -> 1 | X6: =IF(OR($O6="",$W6=""),"",$O6-$W6) -> 16
A7: ВКонтакте | B7: Новый Уренгой | C7: 95 | D7: 84352 | E7: =IF($D7="","",IFERROR(IF(ISBLANK(INDIRECT("'"&$Q$2&"'!D"&ROW())),"",INDIRECT("'"&$Q$2&"'!D"&ROW())),"")) -> 78870 | F7: =IF(OR(D7="",E7=""),"",D7-E7) -> 5482 | G7: =IFERROR(F7/E7,"") -> 0.069506783 | H7: 1068 | I7: =IF($H7="","",IFERROR(IF(ISBLANK(INDIRECT("'"&$Q$2&"'!H"&ROW())),"",INDIRECT("'"&$Q$2&"'!H"&ROW())),"")) -> 796 | J7: =IF(OR(H7="",I7=""),"",H7-I7) -> 272 | K7: =IFERROR(J7/I7,"") -> 0.34170854 | L7: =IFERROR(D7/C7,"") -> 887.91579 | M7: =IFERROR(H7/D7*1000,"") -> 12.661229 | N7: 24901 | O7: =IFERROR(IF(OR(N7="",ISBLANK(INDIRECT("'"&$Q$2&"'!N"&ROW()))),"",N7-INDIRECT("'"&$Q$2&"'!N"&ROW())),"") -> 33 | S7: =IFERROR(IF(ISBLANK(INDIRECT("'"&$Q$2&"'!G"&ROW())),"",INDIRECT("'"&$Q$2&"'!G"&ROW())),"") -> -0.2706744 | T7: =IF(OR($G7="",$S7=""),"",$G7-$S7) -> 0.34018118 | U7: =IFERROR(IF(ISBLANK(INDIRECT("'"&$Q$2&"'!K"&ROW())),"",INDIRECT("'"&$Q$2&"'!K"&ROW())),"") -> -0.22341463 | V7: =IF(OR($K7="",$U7=""),"",$K7-$U7) -> 0.56512318 | W7: =IFERROR(IF(ISBLANK(INDIRECT("'"&$Q$2&"'!O"&ROW())),"",INDIRECT("'"&$Q$2&"'!O"&ROW())),"") -> 36 | X7: =IF(OR($O7="",$W7=""),"",$O7-$W7) -> -3
A8: ВКонтакте | B8: Надым | C8: 76 | D8: 196212 | E8: =IF($D8="","",IFERROR(IF(ISBLANK(INDIRECT("'"&$Q$2&"'!D"&ROW())),"",INDIRECT("'"&$Q$2&"'!D"&ROW())),"")) -> 296983 | F8: =IF(OR(D8="",E8=""),"",D8-E8) -> -100771 | G8: =IFERROR(F8/E8,"") -> -0.33931572 | H8: 2605 | I8: =IF($H8="","",IFERROR(IF(ISBLANK(INDIRECT("'"&$Q$2&"'!H"&ROW())),"",INDIRECT("'"&$Q$2&"'!H"&ROW())),"")) -> 3566 | J8: =IF(OR(H8="",I8=""),"",H8-I8) -> -961 | K8: =IFERROR(J8/I8,"") -> -0.26948962 | L8: =IFERROR(D8/C8,"") -> 2581.7368 | M8: =IFERROR(H8/D8*1000,"") -> 13.276456 | N8: 21769 | O8: =IFERROR(IF(OR(N8="",ISBLANK(INDIRECT("'"&$Q$2&"'!N"&ROW()))),"",N8-INDIRECT("'"&$Q$2&"'!N"&ROW())),"") -> 25 | S8: =IFERROR(IF(ISBLANK(INDIRECT("'"&$Q$2&"'!G"&ROW())),"",INDIRECT("'"&$Q$2&"'!G"&ROW())),"") -> -0.14654172 | T8: =IF(OR($G8="",$S8=""),"",$G8-$S8) -> -0.192774 | U8: =IFERROR(IF(ISBLANK(INDIRECT("'"&$Q$2&"'!K"&ROW())),"",INDIRECT("'"&$Q$2&"'!K"&ROW())),"") -> -0.046524064 | V8: =IF(OR($K8="",$U8=""),"",$K8-$U8) -> -0.22296556 | W8: =IFERROR(IF(ISBLANK(INDIRECT("'"&$Q$2&"'!O"&ROW())),"",INDIRECT("'"&$Q$2&"'!O"&ROW())),"") -> 29 | X8: =IF(OR($O8="",$W8=""),"",$O8-$W8) -> -4
