Workbook

Sheet Сводка
A1: Еженедельный съём соцсетей
A2: Текущая неделя — лист: | B2: 21-27.09
A3: Прошлая неделя — лист: | B3: 14-20.09
A4: снято 28.09.2026 · ВК 27/27, ТГ 22/22 (Барков), МАКС 21/21 (MaxStat), ОК 14/20 (админские выгрузки)
A6: Площадка | B6: Публикаций | C6: Просмотры | D6: Просмотры пред. неделя (сопост. периметр) | E6: Δ % | F6: Лайки | G6: Лайки пред. неделя (сопост. периметр) | H6: Δ % | I6: Лайков на 1000 просмотров | J6: Подписчики | K6: Прирост подписчиков | L6: Δ % просмотров пред. неделя | M6: Ускорение просмотров, п.п. | N6: Δ % лайков пред. неделя | O6: Ускорение лайков, п.п. | P6: Прирост подписч. пред. неделя | Q6: Ускорение подписчиков, чел.
A7: ВКонтакте | B7: {=INDIRECT("'"&$B$2&"'!C30")} -> 1883 | C7: {=IF($B7=0,"",INDIRECT("'"&$B$2&"'!D30"))} -> 4273439 | D7: {=IF($B7=0,"",INDIRECT("'"&$B$2&"'!E30"))} -> 3693588 | E7: =IF(B7=0,"",IFERROR(C7/D7-1,"")) -> 0.15698854 | F7: {=IF($B7=0,"",INDIRECT("'"&$B$2&"'!H30"))} -> 29907 | G7: {=IF($B7=0,"",INDIRECT("'"&$B$2&"'!I30"))} -> 33462 | H7: =IF(B7=0,"",IFERROR(F7/G7-1,"")) -> -0.10623991 | I7: =IFERROR(F7/C7*1000,"") -> 6.9983449 | J7: {=IF($B7=0,"",INDIRECT("'"&$B$2&"'!N30"))} -> 465281 | K7: {=IF($B7=0,"",INDIRECT("'"&$B$2&"'!O30"))} -> 728 | L7: {=IFERROR(IF(INDIRECT("'"&$B$3&"'!G30")="","",INDIRECT("'"&$B$3&"'!G30")),"")} -> 0.22306668 | M7: =IF(OR($E7="",$L7=""),"",$E7-$L7) -> -0.06607814 | N7: {=IFERROR(IF(INDIRECT("'"&$B$3&"'!K30")="","",INDIRECT("'"&$B$3&"'!K30")),"")} -> 0.029916898 | O7: =IF(OR($H7="",$N7=""),"",$H7-$N7) -> -0.13615681 | P7: {=IFERROR(IF(INDIRECT("'"&$B$3&"'!O30")="","",INDIRECT("'"&$B$3&"'!O30")),"")} -> 3078 | Q7: =IF(OR($B7=0,$K7="",$P7=""),"",$K7-$P7) -> -2350
A8: Одноклассники | B8: {=INDIRECT("'"&$B$2&"'!C51")} -> 1190 | C8: {=IF($B8=0,"",INDIRECT("'"&$B$2&"'!D51"))} -> 177893 | D8: {=IF($B8=0,"",INDIRECT("'"&$B$2&"'!E51"))} -> 210483 | E8: =IF(B8=0,"",IFERROR(C8/D8-1,"")) -> -0.15483436 | F8: {=IF($B8=0,"",INDIRECT("'"&$B$2&"'!H51"))} -> 1166 | G8: {=IF($B8=0,"",INDIRECT("'"&$B$2&"'!I51"))} -> 1421 | H8: =IF(B8=0,"",IFERROR(F8/G8-1,"")) -> -0.17945109 | I8: =IFERROR(F8/C8*1000,"") -> 6.5545019 | J8: {=IF($B8=0,"",INDIRECT("'"&$B$2&"'!N51"))} -> 89518 | K8: {=IF($B8=0,"",INDIRECT("'"&$B$2&"'!O51"))} -> 14 | L8: {=IFERROR(IF(INDIRECT("'"&$B$3&"'!G51")="","",INDIRECT("'"&$B$3&"'!G51")),"")} -> -0.47715808 | M8: =IF(OR($E8="",$L8=""),"",$E8-$L8) -> 0.32232372 | N8: {=IFERROR(IF(INDIRECT("'"&$B$3&"'!K51")="","",INDIRECT("'"&$B$3&"'!K51")),"")} -> -0.24364766 | O8: =IF(OR($H8="",$N8=""),"",$H8-$N8) -> 0.064196566 | P8: {=IFERROR(IF(INDIRECT("'"&$B$3&"'!O51")="","",INDIRECT("'"&$B$3&"'!O51")),"")} -> 48 | Q8: =IF(OR($B8=0,$K8="",$P8=""),"",$K8-$P8) -> -34
A9: Telegram | B9: {=INDIRECT("'"&$B$2&"'!C74")} -> 1665 | C9: {=IF($B9=0,"",INDIRECT("'"&$B$2&"'!D74"))} -> 419798 | D9: {=IF($B9=0,"",INDIRECT("'"&$B$2&"'!E74"))} -> 485768 | E9: =IF(B9=0,"",IFERROR(C9/D9-1,"")) -> -0.13580557 | F9: {=IF($B9=0,"",INDIRECT("'"&$B$2&"'!H74"))} -> 2673 | G9: {=IF($B9=0,"",INDIRECT("'"&$B$2&"'!I74"))} -> 2618 | H9: =IF(B9=0,"",IFERROR(F9/G9-1,"")) -> 0.021008403 | I9: =IFERROR(F9/C9*1000,"") -> 6.3673481 | J9: {=IF($B9=0,"",INDIRECT("'"&$B$2&"'!N74"))} -> 98109 | K9: {=IF($B9=0,"",INDIRECT("'"&$B$2&"'!O74"))} -> -210 | L9: {=IFERROR(IF(INDIRECT("'"&$B$3&"'!G74")="","",INDIRECT("'"&$B$3&"'!G74")),"")} -> 0.018439199 | M9: =IF(OR($E9="",$L9=""),"",$E9-$L9) -> -0.15424477 | N9: {=IFERROR(IF(INDIRECT("'"&$B$3&"'!K74")="","",INDIRECT("'"&$B$3&"'!K74")),"")} -> -0.18059468 | O9: =IF(OR($H9="",$N9=""),"",$H9-$N9) -> 0.20160308 | P9: {=IFERROR(IF(INDIRECT("'"&$B$3&"'!O74")="","",INDIRECT("'"&$B$3&"'!O74")),"")} -> -179 | Q9: =IF(OR($B9=0,$K9="",$P9=""),"",$K9-$P9) -> -31
A10: МАКС | B10: {=INDIRECT("'"&$B$2&"'!C96")} -> 1428 | C10: {=IF($B10=0,"",INDIRECT("'"&$B$2&"'!D96"))} -> 1003512 | D10: {=IF($B10=0,"",INDIRECT("'"&$B$2&"'!E96"))} -> 1238429 | E10: =IF(B10=0,"",IFERROR(C10/D10-1,"")) -> -0.18968952 | F10: {=IF($B10=0,"",INDIRECT("'"&$B$2&"'!H96"))} -> 13864 | G10: {=IF($B10=0,"",INDIRECT("'"&$B$2&"'!I96"))} -> 16231 | H10: =IF(B10=0,"",IFERROR(F10/G10-1,"")) -> -0.14583205 | I10: =IFERROR(F10/C10*1000,"") -> 13.81548 | J10: {=IF($B10=0,"",INDIRECT("'"&$B$2&"'!N96"))} -> 31298 | K10: {=IF($B10=0,"",INDIRECT("'"&$B$2&"'!O96"))} -> 242 | L10: {=IFERROR(IF(INDIRECT("'"&$B$3&"'!G96")="","",INDIRECT("'"&$B$3&"'!G96")),"")} -> 0.19045028 | M10: =IF(OR($E10="",$L10=""),"",$E10-$L10) -> -0.3801398 | N10: {=IFERROR(IF(INDIRECT("'"&$B$3&"'!K96")="","",INDIRECT("'"&$B$3&"'!K96")),"")} -> 0.027278481 | O10: =IF(OR($H10="",$N10=""),"",$H10-$N10) -> -0.17311053 | P10: {=IFERROR(IF(INDIRECT("'"&$B$3&"'!O96")="","",INDIRECT("'"&$B$3&"'!O96")),"")} -> 560 | Q10: =IF(OR($B10=0,$K10="",$P10=""),"",$K10-$P10) -> -318
A11: ИТОГО | B11: =SUM(B7:B10) -> 6166 | C11: =SUM(C7:C10) -> 5874642 | D11: =SUM(D7:D10) -> 5628268 | E11: =IF(OR(B7=0,B8=0,B9=0,B10=0),"",IFERROR(C11/D11-1,"")) -> 0.04377439 | F11: =SUM(F7:F10) -> 47610 | G11: =SUM(G7:G10) -> 53732 | H11: =IF(OR(B7=0,B8=0,B9=0,B10=0),"",IFERROR(F11/G11-1,"")) -> -0.11393583 | I11: =IFERROR(F11/C11*1000,"") -> 8.1043236 | J11: =SUM(J7:J10) -> 684206 | K11: =SUM(K7:K10) -> 774 | L11: {=IFERROR(IF(INDIRECT("'"&$B$3&"'!G97")="","",INDIRECT("'"&$B$3&"'!G97")),"")} -> 0.12525281 | M11: =IF(OR($E11="",$L11=""),"",$E11-$L11) -> -0.081478424 | N11: {=IFERROR(IF(INDIRECT("'"&$B$3&"'!K97")="","",INDIRECT("'"&$B$3&"'!K97")),"")} -> -0.00067239719 | O11: =IF(OR($H11="",$N11=""),"",$H11-$N11) -> -0.11326343 | P11: {=IFERROR(IF(INDIRECT("'"&$B$3&"'!O97")="","",INDIRECT("'"&$B$3&"'!O97")),"")} -> 3507 | Q11: =IF(OR(B7=0,B8=0,B9=0,B10=0),"",$K11-$P11) -> -2733
A13: ускорение = насколько прирост этой недели отличается от прироста прошлой, в процентных пунктах.
A14: Плюс — рост ускорился, минус — рост замедлился (или падение усилилось). Считается от Δ % листа прошлой недели.

Sheet 21-27.09
A1: Недельный съём · 21–27.09.2026 | Q1: Лист прошлой недели (питает колонки E, I, O):
A2: Площадка | B2: Ресурс | C2: Публикаций | D2: Просмотры | E2: Просмотры пред. неделя | F2: Δ просмотров | G2: Δ % | H2: Лайки | I2: Лайки пред. неделя | J2: Δ лайков | K2: Δ % | L2: Ср. просмотров на пост | M2: Лайков на 1000 просмотров | N2: Подписчики | O2: Прирост подписчиков | Q2: 14-20.09 | S2: Δ % просмотров пред. неделя | T2: Ускорение просмотров, п.п. | U2: Δ % лайков пред. неделя | V2: Ускорение лайков, п.п. | W2: Прирост подписч. пред. неделя | X2: Ускорение подписчиков, чел.
A3: ВКонтакте | B3: Ямал-Медиа | C3: 114 | D3: 1913477 | E3: =IF($D3="","",IFERROR(IF(ISBLANK(INDIRECT("'"&$Q$2&"'!D"&ROW())),"",INDIRECT("'"&$Q$2&"'!D"&ROW())),"")) -> 516875 | F3: =IF(OR(D3="",E3=""),"",D3-E3) -> 1396602 | G3: =IFERROR(F3/E3,"") -> 2.7020111 | H3: 4474 | I3: =IF($H3="","",IFERROR(IF(ISBLANK(INDIRECT("'"&$Q$2&"'!H"&ROW())),"",INDIRECT("'"&$Q$2&"'!H"&ROW())),"")) -> 1943 | J3: =IF(OR(H3="",I3=""),"",H3-I3) -> 2531 | K3: =IFERROR(J3/I3,"") -> 1.3026248 | L3: =IFERROR(D3/C3,"") -> 16784.886 | M3: =IFERROR(H3/D3*1000,"") -> 2.338152 | N3: 89358 | O3: =IFERROR(IF(OR(N3="",ISBLANK(INDIRECT("'"&$Q$2&"'!N"&ROW()))),"",N3-INDIRECT("'"&$Q$2&"'!N"&ROW())),"") -> 282 | Q3: Колонки E и I берут прошлую неделю только по строкам, снятым в текущей — сравнение идёт по сопоставимому периметру. | S3: =IFERROR(IF(ISBLANK(INDIRECT("'"&$Q$2&"'!G"&ROW())),"",INDIRECT("'"&$Q$2&"'!G"&ROW())),"") -> 0.4077305 | T3: =IF(OR($G3="",$S3=""),"",$G3-$S3) -> 2.2942806 | U3: =IFERROR(IF(ISBLANK(INDIRECT("'"&$Q$2&"'!K"&ROW())),"",INDIRECT("'"&$Q$2&"'!K"&ROW())),"") -> 0.32809296 | V3: =IF(OR($K3="",$U3=""),"",$K3-$U3) -> 0.97453185 | W3: =IFERROR(IF(ISBLANK(INDIRECT("'"&$Q$2&"'!O"&ROW())),"",INDIRECT("'"&$Q$2&"'!O"&ROW())),"") -> 1085 | X3: =IF(OR($O3="",$W3=""),"",$O3-$W3) -> -803
A4: ВКонтакте | B4: Север-Пресс | C4: 129 | D4: 126444 | E4: =IF($D4="","",IFERROR(IF(ISBLANK(INDIRECT("'"&$Q$2&"'!D"&ROW())),"",INDIRECT("'"&$Q$2&"'!D"&ROW())),"")) -> 216205 | F4: =IF(OR(D4="",E4=""),"",D4-E4) -> -89761 | G4: =IFERROR(F4/E4,"") -> -0.41516616 | H4: 528 | I4: =IF($H4="","",IFERROR(IF(ISBLANK(INDIRECT("'"&$Q$2&"'!H"&ROW())),"",INDIRECT("'"&$Q$2&"'!H"&ROW())),"")) -> 695 | J4: =IF(OR(H4="",I4=""),"",H4-I4) -> -167 | K4: =IFERROR(J4/I4,"") -> -0.24028777 | L4: =IFERROR(D4/C4,"") -> 980.18605 | M4: =IFERROR(H4/D4*1000,"") -> 4.1757616 | N4: 26260 | O4: =IFERROR(IF(OR(N4="",ISBLANK(INDIRECT("'"&$Q$2&"'!N"&ROW()))),"",N4-INDIRECT("'"&$Q$2&"'!N"&ROW())),"") -> 11 | Q4: ОК: «просмотры» = VIEWS листа Topics, лайки = сумма LIKES листа Actions (по группе, как в прошлых съёмах). | S4: =IFERROR(IF(ISBLANK(INDIRECT("'"&$Q$2&"'!G"&ROW())),"",INDIRECT("'"&$Q$2&"'!G"&ROW())),"") -> 0.64780349 | T4: =IF(OR($G4="",$S4=""),"",$G4-$S4) -> -1.0629696 | U4: =IFERROR(IF(ISBLANK(INDIRECT("'"&$Q$2&"'!K"&ROW())),"",INDIRECT("'"&$Q$2&"'!K"&ROW())),"") -> 0.21929825 | V4: =IF(OR($K4="",$U4=""),"",$K4-$U4) -> -0.45958602 | W4: =IFERROR(IF(ISBLANK(INDIRECT("'"&$Q$2&"'!O"&ROW())),"",INDIRECT("'"&$Q$2&"'!O"&ROW())),"") -> 25 | X4: =IF(OR($O4="",$W4=""),"",$O4-$W4) -> -14
A5: ВКонтакте | B5: Лента СП | C5: 243 | D5: 3977 | E5: =IF($D5="","",IFERROR(IF(ISBLANK(INDIRECT("'"&$Q$2&"'!D"&ROW())),"",INDIRECT("'"&$Q$2&"'!D"&ROW())),"")) -> 4223 | F5: =IF(OR(D5="",E5=""),"",D5-E5) -> -246 | G5: =IFERROR(F5/E5,"") -> -0.058252427 | H5: 12 | I5: =IF($H5="","",IFERROR(IF(ISBLANK(INDIRECT("'"&$Q$2&"'!H"&ROW())),"",INDIRECT("'"&$Q$2&"'!H"&ROW())),"")) -> 10 | J5: =IF(OR(H5="",I5=""),"",H5-I5) -> 2 | K5: =IFERROR(J5/I5,"") -> 0.2 | L5: =IFERROR(D5/C5,"") -> 16.366255 | M5: =IFERROR(H5/D5*1000,"") -> 3.0173498 | N5: 3500 | O5: =IFERROR(IF(OR(N5="",ISBLANK(INDIRECT("'"&$Q$2&"'!N"&ROW()))),"",N5-INDIRECT("'"&$Q$2&"'!N"&ROW())),"") -> -1 | S5: =IFERROR(IF(ISBLANK(INDIRECT("'"&$Q$2&"'!G"&ROW())),"",INDIRECT("'"&$Q$2&"'!G"&ROW())),"") -> -0.30656814 | T5: =IF(OR($G5="",$S5=""),"",$G5-$S5) -> 0.24831572 | U5: =IFERROR(IF(ISBLANK(INDIRECT("'"&$Q$2&"'!K"&ROW())),"",INDIRECT("'"&$Q$2&"'!K"&ROW())),"") -> -0.28571429 | V5: =IF(OR($K5="",$U5=""),"",$K5-$U5) -> 0.48571429 | W5: =IFERROR(IF(ISBLANK(INDIRECT("'"&$Q$2&"'!O"&ROW())),"",INDIRECT("'"&$Q$2&"'!O"&ROW())),"") -> -2 | X5: =IF(OR($O5="",$W5=""),"",$O5-$W5) -> 1
A6: ВКонтакте | B6: Красный Север | C6: 87 | D6: 63285 | E6: =IF($D6="","",IFERROR(IF(ISBLANK(INDIRECT("'"&$Q$2&"'!D"&ROW())),"",INDIRECT("'"&$Q$2&"'!D"&ROW())),"")) -> 52347 | F6: =IF(OR(D6="",E6=""),"",D6-E6) -> 10938 | G6: =IFERROR(F6/E6,"") -> 0.2089518 | H6: 343 | I6: =IF($H6="","",IFERROR(IF(ISBLANK(INDIRECT("'"&$Q$2&"'!H"&ROW())),"",INDIRECT("'"&$Q$2&"'!H"&ROW())),"")) -> 291 | J6: =IF(OR(H6="",I6=""),"",H6-I6) -> 52 | K6: =IFERROR(J6/I6,"") -> 0.17869416 | L6: =IFERROR(D6/C6,"") -> 727.41379 | M6: =IFERROR(H6/D6*1000,"") -> 5.4199257 | N6: 22932 | O6: =IFERROR(IF(OR(N6="",ISBLANK(INDIRECT("'"&$Q$2&"'!N"&ROW()))),"",N6-INDIRECT("'"&$Q$2&"'!N"&ROW())),"") -> 1 | S6: =IFERROR(IF(ISBLANK(INDIRECT("'"&$Q$2&"'!G"&ROW())),"",INDIRECT("'"&$Q$2&"'!G"&ROW())),"") -> -0.072453753 | T6: =IF(OR($G6="",$S6=""),"",$G6-$S6) -> 0.28140556 | U6: =IFERROR(IF(ISBLANK(INDIRECT("'"&$Q$2&"'!K"&ROW())),"",INDIRECT("'"&$Q$2&"'!K"&ROW())),"") -> 0.081784387 | V6: =IF(OR($K6="",$U6=""),"",$K6-$U6) -> 0.096909771 | W6: =IFERROR(IF(ISBLANK(INDIRECT("'"&$Q$2&"'!O"&ROW())),"",INDIRECT("'"&$Q$2&"'!O"&ROW())),"") -> -4 | X6: =IF(OR($O6="",$W6=""),"",$O6-$W6) -> 5
A7: ВКонтакте | B7: Новый Уренгой | C7: 98 | D7: 78870 | E7: =IF($D7="","",IFERROR(IF(ISBLANK(INDIRECT("'"&$Q$2&"'!D"&ROW())),"",INDIRECT("'"&$Q$2&"'!D"&ROW())),"")) -> 108141 | F7: =IF(OR(D7="",E7=""),"",D7-E7) -> -29271 | G7: =IFERROR(F7/E7,"") -> -0.2706744 | H7: 796 | I7: =IF($H7="","",IFERROR(IF(ISBLANK(INDIRECT("'"&$Q$2&"'!H"&ROW())),"",INDIRECT("'"&$Q$2&"'!H"&ROW())),"")) -> 1025 | J7: =IF(OR(H7="",I7=""),"",H7-I7) -> -229 | K7: =IFERROR(J7/I7,"") -> -0.22341463 | L7: =IFERROR(D7/C7,"") -> 804.79592 | M7: =IFERROR(H7/D7*1000,"") -> 10.092557 | N7: 24868 | O7: =IFERROR(IF(OR(N7="",ISBLANK(INDIRECT("'"&$Q$2&"'!N"&ROW()))),"",N7-INDIRECT("'"&$Q$2&"'!N"&ROW())),"") -> 36 | S7: =IFERROR(IF(ISBLANK(INDIRECT("'"&$Q$2&"'!G"&ROW())),"",INDIRECT("'"&$Q$2&"'!G"&ROW())),"") -> 0.027751114 | T7: =IF(OR($G7="",$S7=""),"",$G7-$S7) -> -0.29842551 | U7: =IFERROR(IF(ISBLANK(INDIRECT("'"&$Q$2&"'!K"&ROW())),"",INDIRECT("'"&$Q$2&"'!K"&ROW())),"") -> -0.15983607 | V7: =IF(OR($K7="",$U7=""),"",$K7-$U7) -> -0.063578569 | W7: =IFERROR(IF(ISBLANK(INDIRECT("'"&$Q$2&"'!O"&ROW())),"",INDIRECT("'"&$Q$2&"'!O"&ROW())),"") -> 317 | X7: =IF(OR($O7="",$W7=""),"",$O7-$W7) -> -281
A8: ВКонтакте | B8: Надым | C8: 87 | D8: 296983 | E8: =IF($D8="","",IFERROR(IF(ISBLANK(INDIRECT("'"&$Q$2&"'!D"&ROW())),"",INDIRECT("'"&$Q$2&"'!D"&ROW())),"")) -> 347976 | F8: =IF(OR(D8="",E8=""),"",D8-E8) -> -50993 | G8: =IFERROR(F8/E8,"") -> -0.14654172 | H8: 3566 | I8: =IF($H8="","",IFERROR(IF(ISBLANK(INDIRECT("'"&$Q$2&"'!H"&ROW())),"",INDIRECT("'"&$Q$2&"'!H"&ROW())),"")) -> 3740 | J8: =IF(OR(H8="",I8=""),"",H8-I8) -> -174 | K8: =IFERROR(J8/I8,"") -> -0.046524064 | L8: =IFERROR(D8/C8,"") -> 3413.5977 | M8: =IFERROR(H8/D8*1000,"") -> 12.007421 | N8: 21744 | O8: =IFERROR(IF(OR(N8="",ISBLANK(INDIRECT("'"&$Q$2&"'!N"&ROW()))),"",N8-INDIRECT("'"&$Q$2&"'!N"&ROW())),"") -> 29 | S8: =IFERROR(IF(ISBLANK(INDIRECT("'"&$Q$2&"'!G"&ROW())),"",INDIRECT("'"&$Q$2&"'!G"&ROW())),"") -> 0.27833658 | T8: =IF(OR($G8="",$S8=""),"",$G8-$S8) -> -0.42487829 | U8: =IFERROR(IF(ISBLANK(INDIRECT("'"&$Q$2&"'!K"&ROW())),"",INDIRECT("'"&$Q$2&"'!K"&ROW())),"") -> -0.13864579 | V8: =IF(OR($K8="",$U8=""),"",$K8-$U8) -> 0.092121721 | W8: =IFERROR(IF(ISBLANK(INDIRECT("'"&$Q$2&"'!O"&ROW())),"",INDIRECT("'"&$Q$2&"'!O"&ROW())),"") -> 218 | X8: =IF(OR($O8="",$W8=""),"",$O8-$W8) -> -189
A9: ВКонтакте | B9: Ноябрьск | C9: 96 | D9: 322545 | E9: =IF($D9="","",IFERROR(IF(ISBLANK(INDIRECT("'"&$Q$2&"'!D"&ROW())),"",INDIRECT("'"&$Q$2&"'!D"&ROW())),"")) -> 424827 | F9: =IF(OR(D9="",E9=""),"",D9-E9) -> -102282 | G9: =IFERROR(F9/E9,"") -> -0.24076153 | H9: 4156 | I9: =IF($H9="","",IFERROR(IF(ISBLANK(INDIRECT("'"&$Q$2&"'!H"&ROW())),"",INDIRECT("'"&$Q$2&"'!H"&ROW())),"")) -> 4187 | J9: =IF(OR(H9="",I9=""),"",H9-I9) -> -31 | K9: =IFERROR(J9/I9,"") -> -0.0074038691 | L9: =IFERROR(D9/C9,"") -> 3359.8438 | M9: =IFERROR(H9/D9*1000,"") -> 12.885024 | N9: 31330 | O9: =IFERROR(IF(OR(N9="",ISBLANK(INDIRECT("'"&$Q$2&"'!N"&ROW()))),"",N9-INDIRECT("'"&$Q$2&"'!N"&ROW())),"") -> 29 | S9: =IFERROR(IF(ISBLANK(INDIRECT("'"&$Q$2&"'!G"&ROW())),"",INDIRECT("'"&$Q$2&"'!G"&ROW())),"") -> 0.3302532 | T9: =IF(OR($G9="",$S9=""),"",$G9-$S9) -> -0.57101473 | U9: =IFERROR(IF(ISBLANK(INDIRECT("'"&$Q$2&"'!K"&ROW())),"",INDIRECT("'"&$Q$2&"'!K"&ROW())),"") -> 0.037670384 | V9: =IF(OR($K9="",$U9=""),"",$K9-$U9) -> -0.045074253 | W9: =IFERROR(IF(ISBLANK(INDIRECT("'"&$Q$2&"'!O"&ROW())),"",INDIRECT("'"&$Q$2&"'!O"&ROW())),"") -> 271 | X9: =IF(OR($O9="",$W9=""),"",$O9-$W9) -> -242
A10: ВКонтакте | B10: Салехард | C10: 135 | D10: 167913 | E10: =IF($D10="","",IFERROR(IF(ISBLANK(INDIRECT("'"&$Q$2&"'!D"&ROW())),"",INDIRECT("'"&$Q$2&"'!D"&ROW())),"")) -> 202830 | F10: =IF(OR(D10="",E10=""),"",D10-E10) -> -34917 | G10: =IFERROR(F10/E10,"") -> -0.17214909 | H10: 1192 | I10: =IF($H10="","",IFERROR(IF(ISBLANK(INDIRECT("'"&$Q$2&"'!H"&ROW())),"",INDIRECT("'"&$Q$2&"'!H"&ROW())),"")) -> 1305 | J10: =IF(OR(H10="",I10=""),"",H10-I10) -> -113 | K10: =IFERROR(J10/I10,"") -> -0.086590038 | L10: =IFERROR(D10/C10,"") -> 1243.8 | M10: =IFERROR(H10/D10*1000,"") -> 7.0989143 | N10: 21586 | O10: =IFERROR(IF(OR(N10="",ISBLANK(INDIRECT("'"&$Q$2&"'!N"&ROW()))),"",N10-INDIRECT("'"&$Q$2&"'!N"&ROW())),"") -> 12 | S10: =IFERROR(IF(ISBLANK(INDIRECT("'"&$Q$2&"'!G"&ROW())),"",INDIRECT("'"&$Q$2&"'!G"&ROW())),"") -> 0.025694188 | T10: =IF(OR($G10="",$S10=""),"",$G10-$S10) -> -0.19784328 | U10: =IFERROR(IF(ISBLANK(INDIRECT("'"&$Q$2&"'!K"&ROW())),"",INDIRECT("'"&$Q$2&"'!K"&ROW())),"") -> -0.1453831 | V10: =IF(OR($K10="",$U10=""),"",$K10-$U10) -> 0.058793066 | W10: =IFERROR(IF(ISBLANK(INDIRECT("'"&$Q$2&"'!O"&ROW())),"",INDIRECT("'"&$Q$2&"'!O"&ROW())),"") -> 199 | X10: =IF(OR($O10="",$W10=""),"",$O10-$W10) -> -187
A11: ВКонтакте | B11: Приуралье | C11: 106 | D11: 407601 | E11: =IF($D11="","",IFERROR(IF(ISBLANK(INDIRECT("'"&$Q$2&"'!D"&ROW())),"",INDIRECT("'"&$Q$2&"'!D"&ROW())),"")) -> 572378 | F11: =IF(OR(D11="",E11=""),"",D11-E11) -> -164777 | G11: =IFERROR(F11/E11,"") -> -0.28788143 | H11: 3694 | I11: =IF($H11="","",IFERROR(IF(ISBLANK(INDIRECT("'"&$Q$2&"'!H"&ROW())),"",INDIRECT("'"&$Q$2&"'!H"&ROW())),"")) -> 4467 | J11: =IF(OR(H11="",I11=""),"",H11-I11) -> -773 | K11: =IFERROR(J11/I11,"") -> -0.17304679 | L11: =IFERROR(D11/C11,"") -> 3845.2925 | M11: =IFERROR(H11/D11*1000,"") -> 9.0627844 | N11: 20797 | O11: =IFERROR(IF(OR(N11="",ISBLANK(INDIRECT("'"&$Q$2&"'!N"&ROW()))),"",N11-INDIRECT("'"&$Q$2&"'!N"&ROW())),"") -> 23 | S11: =IFERROR(IF(ISBLANK(INDIRECT("'"&$Q$2&"'!G"&ROW())),"",INDIRECT("'"&$Q$2&"'!G"&ROW())),"") -> 0.49110357 | T11: =IF(OR($G11="",$S11=""),"",$G11-$S11) -> -0.77898501 | U11: =IFERROR(IF(ISBLANK(INDIRECT("'"&$Q$2&"'!K"&ROW())),"",INDIRECT("'"&$Q$2&"'!K"&ROW())),"") -> 0.27847739 | V11: =IF(OR($K11="",$U11=""),"",$K11-$U11) -> -0.45152418 | W11: =IFERROR(IF(ISBLANK(INDIRECT("'"&$Q$2&"'!O"&ROW())),"",INDIRECT("'"&$Q$2&"'!O"&ROW())),"") -> 138 | X11: =IF(OR($O11="",$W11=""),"",$O11-$W11) -> -115
A12: ВКонтакте | B12: Лабытнанги | C12: 66 | D12: 111561 | E12: =IF($D12="","",IFERROR(IF(ISBLANK(INDIRECT("'"&$Q$2&"'!D"&ROW())),"",INDIRECT("'"&$Q$2&"'!D"&ROW())),"")) -> 151998 | F12: =IF(OR(D12="",E12=""),"",D12-E12) -> -40437 | G12: =IFERROR(F12/E12,"") -> -0.2660364 | H12: 1930 | I12: =IF($H12="","",IFERROR(IF(ISBLANK(INDIRECT("'"&$Q$2&"'!H"&ROW())),"",INDIRECT("'"&$Q$2&"'!H"&ROW())),"")) -> 2359 | J12: =IF(OR(H12="",I12=""),"",H12-I12) -> -429 | K12: =IFERROR(J12/I12,"") -> -0.18185672 | L12: =IFERROR(D12/C12,"") -> 1690.3182 | M12: =IFERROR(H12/D12*1000,"") -> 17.299952 | N12: 15498 | O12: =IFERROR(IF(OR(N12="",ISBLANK(INDIRECT("'"&$Q$2&"'!N"&ROW()))),"",N12-INDIRECT("'"&$Q$2&"'!N"&ROW())),"") -> 44 | S12: =IFERROR(IF(ISBLANK(INDIRECT("'"&$Q$2&"'!G"&ROW())),"",INDIRECT("'"&$Q$2&"'!G"&ROW())),"") -> 0.0069827221 | T12: =IF(OR($G12="",$S12=""),"",$G12-$S12) -> -0.27301912 | U12: =IFERROR(IF(ISBLANK(INDIRECT("'"&$Q$2&"'!K"&ROW())),"",INDIRECT("'"&$Q$2&"'!K"&ROW())),"") -> -0.13462949 | V12: =IF(OR($K12="",$U12=""),"",$K12-$U12) -> -0.047227225 | W12: =IFERROR(IF(ISBLANK(INDIRECT("'"&$Q$2&"'!O"&ROW())),"",INDIRECT("'"&$Q$2&"'!O"&ROW())),"") -> 76 | X12: =IF(OR($O12="",$W12=""),"",$O12-$W12) -> -32
A13: ВКонтакте | B13: Пуровский | C13: 49 | D13: 33284 | E13: =IF($D13="","",IFERROR(IF(ISBLANK(INDIRECT("'"&$Q$2&"'!D"&ROW())),"",INDIRECT("'"&$Q$2&"'!D"&ROW())),"")) -> 48629 | F13: =IF(OR(D13="",E13=""),"",D13-E13) -> -15345 | G13: =IFERROR(F13/E13,"") -> -0.31555245 | H13: 353 | I13: =IF($H13="","",IFERROR(IF(ISBLANK(INDIRECT("'"&$Q$2&"'!H"&ROW())),"",INDIRECT("'"&$Q$2&"'!H"&ROW())),"")) -> 706 | J13: =IF(OR(H13="",I13=""),"",H13-I13) -> -353 | K13: =IFERROR(J13/I13,"") -> -0.5 | L13: =IFERROR(D13/C13,"") -> 679.26531 | M13: =IFERROR(H13/D13*1000,"") -> 10.605696 | N13: 16443 | O13: =IFERROR(IF(OR(N13="",ISBLANK(INDIRECT("'"&$Q$2&"'!N"&ROW()))),"",N13-INDIRECT("'"&$Q$2&"'!N"&ROW())),"") -> -4 | S13: =IFERROR(IF(ISBLANK(INDIRECT("'"&$Q$2&"'!G"&ROW())),"",INDIRECT("'"&$Q$2&"'!G"&ROW())),"") -> 0.66754681 | T13: =IF(OR($G13="",$S13=""),"",$G13-$S13) -> -0.98309926 | U13: =IFERROR(IF(ISBLANK(INDIRECT("'"&$Q$2&"'!K"&ROW())),"",INDIRECT("'"&$Q$2&"'!K"&ROW())),"") -> 0.44969199 | V13: =IF(OR($K13="",$U13=""),"",$K13-$U13) -> -0.94969199 | W13: =IFERROR(IF(ISBLANK(INDIRECT("'"&$Q$2&"'!O"&ROW())),"",INDIRECT("'"&$Q$2&"'!O"&ROW())),"") -> 101 | X13: =IF(OR($O13="",$W13=""),"",$O13-$W13) -> -105
A14: ВКонтакте | B14: Тазовский | C14: 56 | D14: 48840 | E14: =IF($D14="","",IFERROR(IF(ISBLANK(INDIRECT("'"&$Q$2&"'!D"&ROW())),"",INDIRECT("'"&$Q$2&"'!D"&ROW())),"")) -> 82265 | F14: =IF(OR(D14="",E14=""),"",D14-E14) -> -33425 | G14: =IFERROR(F14/E14,"") -> -0.40630888 | H14: 534 | I14: =IF($H14="","",IFERROR(IF(ISBLANK(INDIRECT("'"&$Q$2&"'!H"&ROW())),"",INDIRECT("'"&$Q$2&"'!H"&ROW())),"")) -> 787 | J14: =IF(OR(H14="",I14=""),"",H14-I14) -> -253 | K14: =IFERROR(J14/I14,"") -> -0.32147395 | L14: =IFERROR(D14/C14,"") -> 872.14286 | M14: =IFERROR(H14/D14*1000,"") -> 10.933661 | N14: 6439 | O14: =IFERROR(IF(OR(N14="",ISBLANK(INDIRECT("'"&$Q$2&"'!N"&ROW()))),"",N14-INDIRECT("'"&$Q$2&"'!N"&ROW())),"") -> 37 | S14: =IFERROR(IF(ISBLANK(INDIRECT("'"&$Q$2&"'!G"&ROW())),"",INDIRECT("'"&$Q$2&"'!G"&ROW())),"") -> 0.56889482 | T14: =IF(OR($G14="",$S14=""),"",$G14-$S14) -> -0.9752037 | U14: =IFERROR(IF(ISBLANK(INDIRECT("'"&$Q$2&"'!K"&ROW())),"",INDIRECT("'"&$Q$2&"'!K"&ROW())),"") -> 0.64989518 | V14: =IF(OR($K14="",$U14=""),"",$K14-$U14) -> -0.97136913 | W14: =IFERROR(IF(ISBLANK(INDIRECT("'"&$Q$2&"'!O"&ROW())),"",INDIRECT("'"&$Q$2&"'!O"&ROW())),"") -> 74 | X14: =IF(OR($O14="",$W14=""),"",$O14-$W14) -> -37
A15: ВКонтакте | B15: Красноселькуп | C15: 29 | D15: 30735 | E15: =IF($D15="","",IFERROR(IF(ISBLANK(INDIRECT("'"&$Q$2&"'!D"&ROW())),"",INDIRECT("'"&$Q$2&"'!D"&ROW())),"")) -> 43212 | F15: =IF(OR(D15="",E15=""),"",D15-E15) -> -12477 | G15: =IFERROR(F15/E15,"") -> -0.28873924 | H15: 302 | I15: =IF($H15="","",IFERROR(IF(ISBLANK(INDIRECT("'"&$Q$2&"'!H"&ROW())),"",INDIRECT("'"&$Q$2&"'!H"&ROW())),"")) -> 348 | J15: =IF(OR(H15="",I15=""),"",H15-I15) -> -46 | K15: =IFERROR(J15/I15,"") -> -0.13218391 | L15: =IFERROR(D15/C15,"") -> 1059.8276 | M15: =IFERROR(H15/D15*1000,"") -> 9.8259313 | N15: 3687 | O15: =IFERROR(IF(OR(N15="",ISBLANK(INDIRECT("'"&$Q$2&"'!N"&ROW()))),"",N15-INDIRECT("'"&$Q$2&"'!N"&ROW())),"") -> 8 | S15: =IFERROR(IF(ISBLANK(INDIRECT("'"&$Q$2&"'!G"&ROW())),"",INDIRECT("'"&$Q$2&"'!G"&ROW())),"") -> 0.3764852 | T15: =IF(OR($G15="",$S15=""),"",$G15-$S15) -> -0.66522444 | U15: =IFERROR(IF(ISBLANK(INDIRECT("'"&$Q$2&"'!K"&ROW())),"",INDIRECT("'"&$Q$2&"'!K"&ROW())),"") -> -0.35911602 | V15: =IF(OR($K15="",$U15=""),"",$K15-$U15) -> 0.22693211 | W15: =IFERROR(IF(ISBLANK(INDIRECT("'"&$Q$2&"'!O"&ROW())),"",INDIRECT("'"&$Q$2&"'!O"&ROW())),"") -> 24 | X15: =IF(OR($O15="",$W15=""),"",$O15-$W15) -> -16
A16: ВКонтакте | B16: Ямальский | C16: 50 | D16: 99250 | E16: =IF($D16="","",IFERROR(IF(ISBLANK(INDIRECT("'"&$Q$2&"'!D"&ROW())),"",INDIRECT("'"&$Q$2&"'!D"&ROW())),"")) -> 158474 | F16: =IF(OR(D16="",E16=""),"",D16-E16) -> -59224 | G16: =IFERROR(F16/E16,"") -> -0.3737143 | H16: 1001 | I16: =IF($H16="","",IFERROR(IF(ISBLANK(INDIRECT("'"&$Q$2&"'!H"&ROW())),"",INDIRECT("'"&$Q$2&"'!H"&ROW())),"")) -> 1498 | J16: =IF(OR(H16="",I16=""),"",H16-I16) -> -497 | K16: =IFERROR(J16/I16,"") -> -0.3317757 | L16: =IFERROR(D16/C16,"") -> 1985 | M16: =IFERROR(H16/D16*1000,"") -> 10.085642 | N16: 12813 | O16: =IFERROR(IF(OR(N16="",ISBLANK(INDIRECT("'"&$Q$2&"'!N"&ROW()))),"",N16-INDIRECT("'"&$Q$2&"'!N"&ROW())),"") -> 80 | S16: =IFERROR(IF(ISBLANK(INDIRECT("'"&$Q$2&"'!G"&ROW())),"",INDIRECT("'"&$Q$2&"'!G"&ROW())),"") -> 0.16253173 | T16: =IF(OR($G16="",$S16=""),"",$G16-$S16) -> -0.53624603 | U16: =IFERROR(IF(ISBLANK(INDIRECT("'"&$Q$2&"'!K"&ROW())),"",INDIRECT("'"&$Q$2&"'!K"&ROW())),"") -> -0.23571429 | V16: =IF(OR($K16="",$U16=""),"",$K16-$U16) -> -0.096061415 | W16: =IFERROR(IF(ISBLANK(INDIRECT("'"&$Q$2&"'!O"&ROW())),"",INDIRECT("'"&$Q$2&"'!O"&ROW())),"") -> 268 | X16: =IF(OR($O16="",$W16=""),"",$O16-$W16) -> -188
... A29: ВКонтакте | B29: Морошка | C29: 7 | D29: 10725 | E29: =IF($D29="","",IFERROR(IF(ISBLANK(INDIRECT("'"&$Q$2&"'!D"&ROW())),"",INDIRECT("'"&$Q$2&"'!D"&ROW())),"")) -> 3666 | F29: =IF(OR(D29="",E29=""),"",D29-E29) -> 7059 | G29: =IFERROR(F29/E29,"") -> 1.9255319 | H29: 253 | I29: =IF($H29="","",IFERROR(IF(ISBLANK(INDIRECT("'"&$Q$2&"'!H"&ROW())),"",INDIRECT("'"&$Q$2&"'!H"&ROW())),"")) -> 85 | J29: =IF(OR(H29="",I29=""),"",H29-I29) -> 168 | K29: =IFERROR(J29/I29,"") -> 1.9764706 | L29: =IFERROR(D29/C29,"") -> 1532.1429 | M29: =IFERROR(H29/D29*1000,"") -> 23.589744 | N29: 9625 | O29: =IFERROR(IF(OR(N29="",ISBLANK(INDIRECT("'"&$Q$2&"'!N"&ROW()))),"",N29-INDIRECT("'"&$Q$2&"'!N"&ROW())),"") -> 23 | S29: =IFERROR(IF(ISBLANK(INDIRECT("'"&$Q$2&"'!G"&ROW())),"",INDIRECT("'"&$Q$2&"'!G"&ROW())),"") -> -0.90270184 | T29: =IF(OR($G29="",$S29=""),"",$G29-$S29) -> 2.8282338 | U29: =IFERROR(IF(ISBLANK(INDIRECT("'"&$Q$2&"'!K"&ROW())),"",INDIRECT("'"&$Q$2&"'!K"&ROW())),"") -> 0.63461538 | V29: =IF(OR($K29="",$U29=""),"",$K29-$U29) -> 1.3418552 | W29: =IFERROR(IF(ISBLANK(INDIRECT("'"&$Q$2&"'!O"&ROW())),"",INDIRECT("'"&$Q$2&"'!O"&ROW())),"") -> 30 | X29: =IF(OR($O29="",$W29=""),"",$O29-$W29) -> -7
B30: Итого ВКонтакте | C30: =SUM(C3:C29) -> 1883 | D30: =SUM(D3:D29) -> 4273439 | E30: =SUM(E3:E29) -> 3693588 | F30: =SUM(F3:F29) -> 579851 | G30: =IF(C30=0,"",IFERROR(F30/E30,"")) -> 0.15698854 | H30: =SUM(H3:H29) -> 29907 | I30: =SUM(I3:I29) -> 33462 | J30: =SUM(J3:J29) -> -3555 | K30: =IF(C30=0,"",IFERROR(J30/I30,"")) -> -0.10623991 | L30: =IFERROR(D30/C30,"") -> 2269.4843 | M30: =IFERROR(H30/D30*1000,"") -> 6.9983449 | N30: =SUM(N3:N29) -> 465281 | O30: =SUM(O3:O29) -> 728 | S30: =IFERROR(IF(ISBLANK(INDIRECT("'"&$Q$2&"'!G"&ROW())),"",INDIRECT("'"&$Q$2&"'!G"&ROW())),"") -> 0.22306668 | T30: =IF(OR($G30="",$S30=""),"",$G30-$S30) -> -0.06607814 | U30: =IFERROR(IF(ISBLANK(INDIRECT("'"&$Q$2&"'!K"&ROW())),"",INDIRECT("'"&$Q$2&"'!K"&ROW())),"") -> 0.029916898 | V30: =IF(OR($K30="",$U30=""),"",$K30-$U30) -> -0.13615681 | W30: =IFERROR(IF(ISBLANK(INDIRECT("'"&$Q$2&"'!O"&ROW())),"",INDIRECT("'"&$Q$2&"'!O"&ROW())),"") -> 3078 | X30: =IF(OR(C30=0,$O30="",$W30=""),"",$O30-$W30) -> -2350
A31: Одноклассники | B31: Ямал-Медиа | C31: 118 | D31: 25088 | E31: =IF($D31="","",IFERROR(IF(ISBLANK(INDIRECT("'"&$Q$2&"'!D"&ROW())),"",INDIRECT("'"&$Q$2&"'!D"&ROW())),"")) -> 36700 | F31: =IF(OR(D31="",E31=""),"",D31-E31) -> -11612 | G31: =IFERROR(F31/E31,"") -> -0.31640327 | H31: 112 | I31: =IF($H31="","",IFERROR(IF(ISBLANK(INDIRECT("'"&$Q$2&"'!H"&ROW())),"",INDIRECT("'"&$Q$2&"'!H"&ROW())),"")) -> 116 | J31: =IF(OR(H31="",I31=""),"",H31-I31) -> -4 | K31: =IFERROR(J31/I31,"") -> -0.034482759 | L31: =IFERROR(D31/C31,"") -> 212.61017 | M31: =IFERROR(H31/D31*1000,"") -> 4.4642857 | N31: 32491 | O31: =IFERROR(IF(OR(N31="",ISBLANK(INDIRECT("'"&$Q$2&"'!N"&ROW()))),"",N31-INDIRECT("'"&$Q$2&"'!N"&ROW())),"") -> 3 | S31: =IFERROR(IF(ISBLANK(INDIRECT("'"&$Q$2&"'!G"&ROW())),"",INDIRECT("'"&$Q$2&"'!G"&ROW())),"") -> -0.87413273 | T31: =IF(OR($G31="",$S31=""),"",$G31-$S31) -> 0.55772946 | U31: =IFERROR(IF(ISBLANK(INDIRECT("'"&$Q$2&"'!K"&ROW())),"",INDIRECT("'"&$Q$2&"'!K"&ROW())),"") -> -0.086614173 | V31: =IF(OR($K31="",$U31=""),"",$K31-$U31) -> 0.052131415 | W31: =IFERROR(IF(ISBLANK(INDIRECT("'"&$Q$2&"'!O"&ROW())),"",INDIRECT("'"&$Q$2&"'!O"&ROW())),"") -> 15 | X31: =IF(OR($O31="",$W31=""),"",$O31-$W31) -> -12
A32: Одноклассники | B32: Север-Пресс | C32: 109 | D32: 31127 | E32: =IF($D32="","",IFERROR(IF(ISBLANK(INDIRECT("'"&$Q$2&"'!D"&ROW())),"",INDIRECT("'"&$Q$2&"'!D"&ROW())),"")) -> 42212 | F32: =IF(OR(D32="",E32=""),"",D32-E32) -> -11085 | G32: =IFERROR(F32/E32,"") -> -0.26260305 | H32: 35 | I32: =IF($H32="","",IFERROR(IF(ISBLANK(INDIRECT("'"&$Q$2&"'!H"&ROW())),"",INDIRECT("'"&$Q$2&"'!H"&ROW())),"")) -> 92 | J32: =IF(OR(H32="",I32=""),"",H32-I32) -> -57 | K32: =IFERROR(J32/I32,"") -> -0.61956522 | L32: =IFERROR(D32/C32,"") -> 285.56881 | M32: =IFERROR(H32/D32*1000,"") -> 1.1244257 | N32: 21738 | O32: =IFERROR(IF(OR(N32="",ISBLANK(INDIRECT("'"&$Q$2&"'!N"&ROW()))),"",N32-INDIRECT("'"&$Q$2&"'!N"&ROW())),"") -> 1 | S32: =IFERROR(IF(ISBLANK(INDIRECT("'"&$Q$2&"'!G"&ROW())),"",INDIRECT("'"&$Q$2&"'!G"&ROW())),"") -> 0.035953567 | T32: =IF(OR($G32="",$S32=""),"",$G32-$S32) -> -0.29855662 | U32: =IFERROR(IF(ISBLANK(INDIRECT("'"&$Q$2&"'!K"&ROW())),"",INDIRECT("'"&$Q$2&"'!K"&ROW())),"") -> 0.35294118 | V32: =IF(OR($K32="",$U32=""),"",$K32-$U32) -> -0.97250639 | W32: =IFERROR(IF(ISBLANK(INDIRECT("'"&$Q$2&"'!O"&ROW())),"",INDIRECT("'"&$Q$2&"'!O"&ROW())),"") -> 2 | X32: =IF(OR($O32="",$W32=""),"",$O32-$W32) -> -1
A33: Одноклассники | B33: Красный Север | C33: 75 | D33: 24654 | E33: =IF($D33="","",IFERROR(IF(ISBLANK(INDIRECT("'"&$Q$2&"'!D"&ROW())),"",INDIRECT("'"&$Q$2&"'!D"&ROW())),"")) -> 16771 | F33: =IF(OR(D33="",E33=""),"",D33-E33) -> 7883 | G33: =IFERROR(F33/E33,"") -> 0.47003756 | H33: 18 | I33: =IF($H33="","",IFERROR(IF(ISBLANK(INDIRECT("'"&$Q$2&"'!H"&ROW())),"",INDIRECT("'"&$Q$2&"'!H"&ROW())),"")) -> 5 | J33: =IF(OR(H33="",I33=""),"",H33-I33) -> 13 | K33: =IFERROR(J33/I33,"") -> 2.6 | L33: =IFERROR(D33/C33,"") -> 328.72 | M33: =IFERROR(H33/D33*1000,"") -> 0.73010465 | N33: 8958 | O33: =IFERROR(IF(OR(N33="",ISBLANK(INDIRECT("'"&$Q$2&"'!N"&ROW()))),"",N33-INDIRECT("'"&$Q$2&"'!N"&ROW())),"") -> 1 | S33: =IFERROR(IF(ISBLANK(INDIRECT("'"&$Q$2&"'!G"&ROW())),"",INDIRECT("'"&$Q$2&"'!G"&ROW())),"") -> -0.085301336 | T33: =IF(OR($G33="",$S33=""),"",$G33-$S33) -> 0.5553389 | U33: =IFERROR(IF(ISBLANK(INDIRECT("'"&$Q$2&"'!K"&ROW())),"",INDIRECT("'"&$Q$2&"'!K"&ROW())),"") -> 0.25 | V33: =IF(OR($K33="",$U33=""),"",$K33-$U33) -> 2.35 | W33: =IFERROR(IF(ISBLANK(INDIRECT("'"&$Q$2&"'!O"&ROW())),"",INDIRECT("'"&$Q$2&"'!O"&ROW())),"") -> -4 | X33: =IF(OR($O33="",$W33=""),"",$O33-$W33) -> 5
A34: Одноклассники | B34: Новый Уренгой | C34: 84 | D34: 604 | E34: =IF($D34="","",IFERROR(IF(ISBLANK(INDIRECT("'"&$Q$2&"'!D"&ROW())),"",INDIRECT("'"&$Q$2&"'!D"&ROW())),"")) -> 721 | F34: =IF(OR(D34="",E34=""),"",D34-E34) -> -117 | G34: =IFERROR(F34/E34,"") -> -0.16227462 | H34: 0 | I34: =IF($H34="","",IFERROR(IF(ISBLANK(INDIRECT("'"&$Q$2&"'!H"&ROW())),"",INDIRECT("'"&$Q$2&"'!H"&ROW())),"")) -> 0 | J34: =IF(OR(H34="",I34=""),"",H34-I34) -> 0 | K34: =IFERROR(J34/I34,"") | L34: =IFERROR(D34/C34,"") -> 7.1904762 | M34: =IFERROR(H34/D34*1000,"") -> 0 | N34: 6 | O34: =IFERROR(IF(OR(N34="",ISBLANK(INDIRECT("'"&$Q$2&"'!N"&ROW()))),"",N34-INDIRECT("'"&$Q$2&"'!N"&ROW())),"") -> 0 | S34: =IFERROR(IF(ISBLANK(INDIRECT("'"&$Q$2&"'!G"&ROW())),"",INDIRECT("'"&$Q$2&"'!G"&ROW())),"") -> -0.20331492 | T34: =IF(OR($G34="",$S34=""),"",$G34-$S34) -> 0.041040299 | U34: =IFERROR(IF(ISBLANK(INDIRECT("'"&$Q$2&"'!K"&ROW())),"",INDIRECT("'"&$Q$2&"'!K"&ROW())),"") | V34: =IF(OR($K34="",$U34=""),"",$K34-$U34) | W34: =IFERROR(IF(ISBLANK(INDIRECT("'"&$Q$2&"'!O"&ROW())),"",INDIRECT("'"&$Q$2&"'!O"&ROW())),"") -> 0 | X34: =IF(OR($O34="",$W34=""),"",$O34-$W34) -> 0
A35: Одноклассники | B35: Надым | C35: 83 | D35: 8859 | E35: =IF($D35="","",IFERROR(IF(ISBLANK(INDIRECT("'"&$Q$2&"'!D"&ROW())),"",INDIRECT("'"&$Q$2&"'!D"&ROW())),"")) -> 9472 | F35: =IF(OR(D35="",E35=""),"",D35-E35) -> -613 | G35: =IFERROR(F35/E35,"") -> -0.064717061 | H35: 70 | I35: =IF($H35="","",IFERROR(IF(ISBLANK(INDIRECT("'"&$Q$2&"'!H"&ROW())),"",INDIRECT("'"&$Q$2&"'!H"&ROW())),"")) -> 48 | J35: =IF(OR(H35="",I35=""),"",H35-I35) -> 22 | K35: =IFERROR(J35/I35,"") -> 0.45833333 | L35: =IFERROR(D35/C35,"") -> 106.73494 | M35: =IFERROR(H35/D35*1000,"") -> 7.901569 | N35: 1941 | O35: =IFERROR(IF(OR(N35="",ISBLANK(INDIRECT("'"&$Q$2&"'!N"&ROW()))),"",N35-INDIRECT("'"&$Q$2&"'!N"&ROW())),"") -> 0 | S35: =IFERROR(IF(ISBLANK(INDIRECT("'"&$Q$2&"'!G"&ROW())),"",INDIRECT("'"&$Q$2&"'!G"&ROW())),"") -> -0.074728924 | T35: =IF(OR($G35="",$S35=""),"",$G35-$S35) -> 0.010011864 | U35: =IFERROR(IF(ISBLANK(INDIRECT("'"&$Q$2&"'!K"&ROW())),"",INDIRECT("'"&$Q$2&"'!K"&ROW())),"") -> -0.61904762 | V35: =IF(OR($K35="",$U35=""),"",$K35-$U35) -> 1.077381 | W35: =IFERROR(IF(ISBLANK(INDIRECT("'"&$Q$2&"'!O"&ROW())),"",INDIRECT("'"&$Q$2&"'!O"&ROW())),"") -> 4 | X35: =IF(OR($O35="",$W35=""),"",$O35-$W35) -> -4
A36: Одноклассники | B36: Ноябрьск | E36: =IF($D36="","",IFERROR(IF(ISBLANK(INDIRECT("'"&$Q$2&"'!D"&ROW())),"",INDIRECT("'"&$Q$2&"'!D"&ROW())),"")) | F36: =IF(OR(D36="",E36=""),"",D36-E36) | G36: =IFERROR(F36/E36,"") | I36: =IF($H36="","",IFERROR(IF(ISBLANK(INDIRECT("'"&$Q$2&"'!H"&ROW())),"",INDIRECT("'"&$Q$2&"'!H"&ROW())),"")) | J36: =IF(OR(H36="",I36=""),"",H36-I36) | K36: =IFERROR(J36/I36,"") | L36: =IFERROR(D36/C36,"") | M36: =IFERROR(H36/D36*1000,"") | O36: =IFERROR(IF(OR(N36="",ISBLANK(INDIRECT("'"&$Q$2&"'!N"&ROW()))),"",N36-INDIRECT("'"&$Q$2&"'!N"&ROW())),"") | S36: =IFERROR(IF(ISBLANK(INDIRECT("'"&$Q$2&"'!G"&ROW())),"",INDIRECT("'"&$Q$2&"'!G"&ROW())),"") -> -0.037648158 | T36: =IF(OR($G36="",$S36=""),"",$G36-$S36) | U36: =IFERROR(IF(ISBLANK(INDIRECT("'"&$Q$2&"'!K"&ROW())),"",INDIRECT("'"&$Q$2&"'!K"&ROW())),"") -> -0.41525424 | V36: =IF(OR($K36="",$U36=""),"",$K36-$U36) | W36: =IFERROR(IF(ISBLANK(INDIRECT("'"&$Q$2&"'!O"&ROW())),"",INDIRECT("'"&$Q$2&"'!O"&ROW())),"") -> 7 | X36: =IF(OR($O36="",$W36=""),"",$O36-$W36)
A37: Одноклассники | B37: Салехард | C37: 117 | D37: 5607 | E37: =IF($D37="","",IFERROR(IF(ISBLANK(INDIRECT("'"&$Q$2&"'!D"&ROW())),"",INDIRECT("'"&$Q$2&"'!D"&ROW())),"")) -> 6504 | F37: =IF(OR(D37="",E37=""),"",D37-E37) -> -897 | G37: =IFERROR(F37/E37,"") -> -0.13791513 | H37: 18 | I37: =IF($H37="","",IFERROR(IF(ISBLANK(INDIRECT("'"&$Q$2&"'!H"&ROW())),"",INDIRECT("'"&$Q$2&"'!H"&ROW())),"")) -> 48 | J37: =IF(OR(H37="",I37=""),"",H37-I37) -> -30 | K37: =IFERROR(J37/I37,"") -> -0.625 | L37: =IFERROR(D37/C37,"") -> 47.923077 | M37: =IFERROR(H37/D37*1000,"") -> 3.2102729 | N37: 3238 | O37: =IFERROR(IF(OR(N37="",ISBLANK(INDIRECT("'"&$Q$2&"'!N"&ROW()))),"",N37-INDIRECT("'"&$Q$2&"'!N"&ROW())),"") -> 1 | S37: =IFERROR(IF(ISBLANK(INDIRECT("'"&$Q$2&"'!G"&ROW())),"",INDIRECT("'"&$Q$2&"'!G"&ROW())),"") -> -0.14555964 | T37: =IF(OR($G37="",$S37=""),"",$G37-$S37) -> 0.0076445135 | U37: =IFERROR(IF(ISBLANK(INDIRECT("'"&$Q$2&"'!K"&ROW())),"",INDIRECT("'"&$Q$2&"'!K"&ROW())),"") -> -0.18644068 | V37: =IF(OR($K37="",$U37=""),"",$K37-$U37) -> -0.43855932 | W37: =IFERROR(IF(ISBLANK(INDIRECT("'"&$Q$2&"'!O"&ROW())),"",INDIRECT("'"&$Q$2&"'!O"&ROW())),"") -> 1 | X37: =IF(OR($O37="",$W37=""),"",$O37-$W37) -> 0
A38: Одноклассники | B38: Приуралье | C38: 107 | D38: 9151 | E38: =IF($D38="","",IFERROR(IF(ISBLANK(INDIRECT("'"&$Q$2&"'!D"&ROW())),"",INDIRECT("'"&$Q$2&"'!D"&ROW())),"")) -> 10887 | F38: =IF(OR(D38="",E38=""),"",D38-E38) -> -1736 | G38: =IFERROR(F38/E38,"") -> -0.15945623 | H38: 151 | I38: =IF($H38="","",IFERROR(IF(ISBLANK(INDIRECT("'"&$Q$2&"'!H"&ROW())),"",INDIRECT("'"&$Q$2&"'!H"&ROW())),"")) -> 183 | J38: =IF(OR(H38="",I38=""),"",H38-I38) -> -32 | K38: =IFERROR(J38/I38,"") -> -0.17486339 | L38: =IFERROR(D38/C38,"") -> 85.523364 | M38: =IFERROR(H38/D38*1000,"") -> 16.500929 | N38: 1711 | O38: =IFERROR(IF(OR(N38="",ISBLANK(INDIRECT("'"&$Q$2&"'!N"&ROW()))),"",N38-INDIRECT("'"&$Q$2&"'!N"&ROW())),"") -> 0 | S38: =IFERROR(IF(ISBLANK(INDIRECT("'"&$Q$2&"'!G"&ROW())),"",INDIRECT("'"&$Q$2&"'!G"&ROW())),"") -> 0.35141509 | T38: =IF(OR($G38="",$S38=""),"",$G38-$S38) -> -0.51087133 | U38: =IFERROR(IF(ISBLANK(INDIRECT("'"&$Q$2&"'!K"&ROW())),"",INDIRECT("'"&$Q$2&"'!K"&ROW())),"") -> 0.063953488 | V38: =IF(OR($K38="",$U38=""),"",$K38-$U38) -> -0.23881688 | W38: =IFERROR(IF(ISBLANK(INDIRECT("'"&$Q$2&"'!O"&ROW())),"",INDIRECT("'"&$Q$2&"'!O"&ROW())),"") -> 6 | X38: =IF(OR($O38="",$W38=""),"",$O38-$W38) -> -6
A39: Одноклассники | B39: Лабытнанги | C39: 53 | D39: 4189 | E39: =IF($D39="","",IFERROR(IF(ISBLANK(INDIRECT("'"&$Q$2&"'!D"&ROW())),"",INDIRECT("'"&$Q$2&"'!D"&ROW())),"")) -> 4212 | F39: =IF(OR(D39="",E39=""),"",D39-E39) -> -23 | G39: =IFERROR(F39/E39,"") -> -0.0054605888 | H39: 3 | I39: =IF($H39="","",IFERROR(IF(ISBLANK(INDIRECT("'"&$Q$2&"'!H"&ROW())),"",INDIRECT("'"&$Q$2&"'!H"&ROW())),"")) -> 8 | J39: =IF(OR(H39="",I39=""),"",H39-I39) -> -5 | K39: =IFERROR(J39/I39,"") -> -0.625 | L39: =IFERROR(D39/C39,"") -> 79.037736 | M39: =IFERROR(H39/D39*1000,"") -> 0.71616138 | N39: 225 | O39: =IFERROR(IF(OR(N39="",ISBLANK(INDIRECT("'"&$Q$2&"'!N"&ROW()))),"",N39-INDIRECT("'"&$Q$2&"'!N"&ROW())),"") -> 0 | S39: =IFERROR(IF(ISBLANK(INDIRECT("'"&$Q$2&"'!G"&ROW())),"",INDIRECT("'"&$Q$2&"'!G"&ROW())),"") -> 1.1700155 | T39: =IF(OR($G39="",$S39=""),"",$G39-$S39) -> -1.175476 | U39: =IFERROR(IF(ISBLANK(INDIRECT("'"&$Q$2&"'!K"&ROW())),"",INDIRECT("'"&$Q$2&"'!K"&ROW())),"") -> -0.2 | V39: =IF(OR($K39="",$U39=""),"",$K39-$U39) -> -0.425 | W39: =IFERROR(IF(ISBLANK(INDIRECT("'"&$Q$2&"'!O"&ROW())),"",INDIRECT("'"&$Q$2&"'!O"&ROW())),"") -> 1 | X39: =IF(OR($O39="",$W39=""),"",$O39-$W39) -> -1
A40: Одноклассники | B40: Пуровский | E40: =IF($D40="","",IFERROR(IF(ISBLANK(INDIRECT("'"&$Q$2&"'!D"&ROW())),"",INDIRECT("'"&$Q$2&"'!D"&ROW())),"")) | F40: =IF(OR(D40="",E40=""),"",D40-E40) | G40: =IFERROR(F40/E40,"") | I40: =IF($H40="","",IFERROR(IF(ISBLANK(INDIRECT("'"&$Q$2&"'!H"&ROW())),"",INDIRECT("'"&$Q$2&"'!H"&ROW())),"")) | J40: =IF(OR(H40="",I40=""),"",H40-I40) | K40: =IFERROR(J40/I40,"") | L40: =IFERROR(D40/C40,"") | M40: =IFERROR(H40/D40*1000,"") | O40: =IFERROR(IF(OR(N40="",ISBLANK(INDIRECT("'"&$Q$2&"'!N"&ROW()))),"",N40-INDIRECT("'"&$Q$2&"'!N"&ROW())),"") | S40: =IFERROR(IF(ISBLANK(INDIRECT("'"&$Q$2&"'!G"&ROW())),"",INDIRECT("'"&$Q$2&"'!G"&ROW())),"") -> 0.10353739 | T40: =IF(OR($G40="",$S40=""),"",$G40-$S40) | U40: =IFERROR(IF(ISBLANK(INDIRECT("'"&$Q$2&"'!K"&ROW())),"",INDIRECT("'"&$Q$2&"'!K"&ROW())),"") -> -0.42553191 | V40: =IF(OR($K40="",$U40=""),"",$K40-$U40) | W40: =IFERROR(IF(ISBLANK(INDIRECT("'"&$Q$2&"'!O"&ROW())),"",INDIRECT("'"&$Q$2&"'!O"&ROW())),"") -> 1 | X40: =IF(OR($O40="",$W40=""),"",$O40-$W40)
A41: Одноклассники | B41: Тазовский | C41: 50 | D41: 12390 | E41: =IF($D41="","",IFERROR(IF(ISBLANK(INDIRECT("'"&$Q$2&"'!D"&ROW())),"",INDIRECT("'"&$Q$2&"'!D"&ROW())),"")) -> 12790 | F41: =IF(OR(D41="",E41=""),"",D41-E41) -> -400 | G41: =IFERROR(F41/E41,"") -> -0.031274433 | H41: 121 | I41: =IF($H41="","",IFERROR(IF(ISBLANK(INDIRECT("'"&$Q$2&"'!H"&ROW())),"",INDIRECT("'"&$Q$2&"'!H"&ROW())),"")) -> 102 | J41: =IF(OR(H41="",I41=""),"",H41-I41) -> 19 | K41: =IFERROR(J41/I41,"") -> 0.18627451 | L41: =IFERROR(D41/C41,"") -> 247.8 | M41: =IFERROR(H41/D41*1000,"") -> 9.7659403 | N41: 3531 | O41: =IFERROR(IF(OR(N41="",ISBLANK(INDIRECT("'"&$Q$2&"'!N"&ROW()))),"",N41-INDIRECT("'"&$Q$2&"'!N"&ROW())),"") -> 2 | S41: =IFERROR(IF(ISBLANK(INDIRECT("'"&$Q$2&"'!G"&ROW())),"",INDIRECT("'"&$Q$2&"'!G"&ROW())),"") -> 0.49765808 | T41: =IF(OR($G41="",$S41=""),"",$G41-$S41) -> -0.52893251 | U41: =IFERROR(IF(ISBLANK(INDIRECT("'"&$Q$2&"'!K"&ROW())),"",INDIRECT("'"&$Q$2&"'!K"&ROW())),"") -> -0.081081081 | V41: =IF(OR($K41="",$U41=""),"",$K41-$U41) -> 0.26735559 | W41: =IFERROR(IF(ISBLANK(INDIRECT("'"&$Q$2&"'!O"&ROW())),"",INDIRECT("'"&$Q$2&"'!O"&ROW())),"") -> -1 | X41: =IF(OR($O41="",$W41=""),"",$O41-$W41) -> 3
A42: Одноклассники | B42: Красноселькуп | C42: 25 | D42: 6594 | E42: =IF($D42="","",IFERROR(IF(ISBLANK(INDIRECT("'"&$Q$2&"'!D"&ROW())),"",INDIRECT("'"&$Q$2&"'!D"&ROW())),"")) -> 7517 | F42: =IF(OR(D42="",E42=""),"",D42-E42) -> -923 | G42: =IFERROR(F42/E42,"") -> -0.12278835 | H42: 83 | I42: =IF($H42="","",IFERROR(IF(ISBLANK(INDIRECT("'"&$Q$2&"'!H"&ROW())),"",INDIRECT("'"&$Q$2&"'!H"&ROW())),"")) -> 133 | J42: =IF(OR(H42="",I42=""),"",H42-I42) -> -50 | K42: =IFERROR(J42/I42,"") -> -0.37593985 | L42: =IFERROR(D42/C42,"") -> 263.76 | M42: =IFERROR(H42/D42*1000,"") -> 12.5872 | N42: 653 | O42: =IFERROR(IF(OR(N42="",ISBLANK(INDIRECT("'"&$Q$2&"'!N"&ROW()))),"",N42-INDIRECT("'"&$Q$2&"'!N"&ROW())),"") -> 2 | S42: =IFERROR(IF(ISBLANK(INDIRECT("'"&$Q$2&"'!G"&ROW())),"",INDIRECT("'"&$Q$2&"'!G"&ROW())),"") -> 0.23614537 | T42: =IF(OR($G42="",$S42=""),"",$G42-$S42) -> -0.35893372 | U42: =IFERROR(IF(ISBLANK(INDIRECT("'"&$Q$2&"'!K"&ROW())),"",INDIRECT("'"&$Q$2&"'!K"&ROW())),"") -> -0.46370968 | V42: =IF(OR($K42="",$U42=""),"",$K42-$U42) -> 0.087769828 | W42: =IFERROR(IF(ISBLANK(INDIRECT("'"&$Q$2&"'!O"&ROW())),"",INDIRECT("'"&$Q$2&"'!O"&ROW())),"") -> 1 | X42: =IF(OR($O42="",$W42=""),"",$O42-$W42) -> 1
A43: Одноклассники | B43: Ямальский | C43: 43 | D43: 2452 | E43: =IF($D43="","",IFERROR(IF(ISBLANK(INDIRECT("'"&$Q$2&"'!D"&ROW())),"",INDIRECT("'"&$Q$2&"'!D"&ROW())),"")) -> 3667 | F43: =IF(OR(D43="",E43=""),"",D43-E43) -> -1215 | G43: =IFERROR(F43/E43,"") -> -0.33133352 | H43: 11 | I43: =IF($H43="","",IFERROR(IF(ISBLANK(INDIRECT("'"&$Q$2&"'!H"&ROW())),"",INDIRECT("'"&$Q$2&"'!H"&ROW())),"")) -> 25 | J43: =IF(OR(H43="",I43=""),"",H43-I43) -> -14 | K43: =IFERROR(J43/I43,"") -> -0.56 | L43: =IFERROR(D43/C43,"") -> 57.023256 | M43: =IFERROR(H43/D43*1000,"") -> 4.4861338 | N43: 1952 | O43: =IFERROR(IF(OR(N43="",ISBLANK(INDIRECT("'"&$Q$2&"'!N"&ROW()))),"",N43-INDIRECT("'"&$Q$2&"'!N"&ROW())),"") -> 0 | S43: =IFERROR(IF(ISBLANK(INDIRECT("'"&$Q$2&"'!G"&ROW())),"",INDIRECT("'"&$Q$2&"'!G"&ROW())),"") -> -0.27558277 | T43: =IF(OR($G43="",$S43=""),"",$G43-$S43) -> -0.055750742 | U43: =IFERROR(IF(ISBLANK(INDIRECT("'"&$Q$2&"'!K"&ROW())),"",INDIRECT("'"&$Q$2&"'!K"&ROW())),"") -> -0.56140351 | V43: =IF(OR($K43="",$U43=""),"",$K43-$U43) -> 0.0014035088 | W43: =IFERROR(IF(ISBLANK(INDIRECT("'"&$Q$2&"'!O"&ROW())),"",INDIRECT("'"&$Q$2&"'!O"&ROW())),"") -> 0 | X43: =IF(OR($O43="",$W43=""),"",$O43-$W43) -> 0
A44: Одноклассники | B44: Шурышкарский | E44: =IF($D44="","",IFERROR(IF(ISBLANK(INDIRECT("'"&$Q$2&"'!D"&ROW())),"",INDIRECT("'"&$Q$2&"'!D"&ROW())),"")) | F44: =IF(OR(D44="",E44=""),"",D44-E44) | G44: =IFERROR(F44/E44,"") | I44: =IF($H44="","",IFERROR(IF(ISBLANK(INDIRECT("'"&$Q$2&"'!H"&ROW())),"",INDIRECT("'"&$Q$2&"'!H"&ROW())),"")) | J44: =IF(OR(H44="",I44=""),"",H44-I44) | K44: =IFERROR(J44/I44,"") | L44: =IFERROR(D44/C44,"") | M44: =IFERROR(H44/D44*1000,"") | O44: =IFERROR(IF(OR(N44="",ISBLANK(INDIRECT("'"&$Q$2&"'!N"&ROW()))),"",N44-INDIRECT("'"&$Q$2&"'!N"&ROW())),"") | S44: =IFERROR(IF(ISBLANK(INDIRECT("'"&$Q$2&"'!G"&ROW())),"",INDIRECT("'"&$Q$2&"'!G"&ROW())),"") -> -0.51842024 | T44: =IF(OR($G44="",$S44=""),"",$G44-$S44) | U44: =IFERROR(IF(ISBLANK(INDIRECT("'"&$Q$2&"'!K"&ROW())),"",INDIRECT("'"&$Q$2&"'!K"&ROW())),"") -> -0.40669014 | V44: =IF(OR($K44="",$U44=""),"",$K44-$U44) | W44: =IFERROR(IF(ISBLANK(INDIRECT("'"&$Q$2&"'!O"&ROW())),"",INDIRECT("'"&$Q$2&"'!O"&ROW())),"") -> 5 | X44: =IF(OR($O44="",$W44=""),"",$O44-$W44)
A45: Одноклассники | B45: Муравленко | C45: 50 | D45: 14463 | E45: =IF($D45="","",IFERROR(IF(ISBLANK(INDIRECT("'"&$Q$2&"'!D"&ROW())),"",INDIRECT("'"&$Q$2&"'!D"&ROW())),"")) -> 21536 | F45: =IF(OR(D45="",E45=""),"",D45-E45) -> -7073 | G45: =IFERROR(F45/E45,"") -> -0.32842682 | H45: 201 | I45: =IF($H45="","",IFERROR(IF(ISBLANK(INDIRECT("'"&$Q$2&"'!H"&ROW())),"",INDIRECT("'"&$Q$2&"'!H"&ROW())),"")) -> 308 | J45: =IF(OR(H45="",I45=""),"",H45-I45) -> -107 | K45: =IFERROR(J45/I45,"") -> -0.3474026 | L45: =IFERROR(D45/C45,"") -> 289.26 | M45: =IFERROR(H45/D45*1000,"") -> 13.897532 | N45: 3747 | O45: =IFERROR(IF(OR(N45="",ISBLANK(INDIRECT("'"&$Q$2&"'!N"&ROW()))),"",N45-INDIRECT("'"&$Q$2&"'!N"&ROW())),"") -> 1 | S45: =IFERROR(IF(ISBLANK(INDIRECT("'"&$Q$2&"'!G"&ROW())),"",INDIRECT("'"&$Q$2&"'!G"&ROW())),"") -> 0.061880578 | T45: =IF(OR($G45="",$S45=""),"",$G45-$S45) -> -0.3903074 | U45: =IFERROR(IF(ISBLANK(INDIRECT("'"&$Q$2&"'!K"&ROW())),"",INDIRECT("'"&$Q$2&"'!K"&ROW())),"") -> -0.16531165 | V45: =IF(OR($K45="",$U45=""),"",$K45-$U45) -> -0.18209094 | W45: =IFERROR(IF(ISBLANK(INDIRECT("'"&$Q$2&"'!O"&ROW())),"",INDIRECT("'"&$Q$2&"'!O"&ROW())),"") -> 3 | X45: =IF(OR($O45="",$W45=""),"",$O45-$W45) -> -2
A46: Одноклассники | B46: Губкинский | C46: 62 | D46: 22558 | E46: =IF($D46="","",IFERROR(IF(ISBLANK(INDIRECT("'"&$Q$2&"'!D"&ROW())),"",INDIRECT("'"&$Q$2&"'!D"&ROW())),"")) -> 29521 | F46: =IF(OR(D46="",E46=""),"",D46-E46) -> -6963 | G46: =IFERROR(F46/E46,"") -> -0.23586599 | H46: 342 | I46: =IF($H46="","",IFERROR(IF(ISBLANK(INDIRECT("'"&$Q$2&"'!H"&ROW())),"",INDIRECT("'"&$Q$2&"'!H"&ROW())),"")) -> 351 | J46: =IF(OR(H46="",I46=""),"",H46-I46) -> -9 | K46: =IFERROR(J46/I46,"") -> -0.025641026 | L46: =IFERROR(D46/C46,"") -> 363.83871 | M46: =IFERROR(H46/D46*1000,"") -> 15.160919 | N46: 4507 | O46: =IFERROR(IF(OR(N46="",ISBLANK(INDIRECT("'"&$Q$2&"'!N"&ROW()))),"",N46-INDIRECT("'"&$Q$2&"'!N"&ROW())),"") -> 3 | S46: =IFERROR(IF(ISBLANK(INDIRECT("'"&$Q$2&"'!G"&ROW())),"",INDIRECT("'"&$Q$2&"'!G"&ROW())),"") -> 0.51265628 | T46: =IF(OR($G46="",$S46=""),"",$G46-$S46) -> -0.74852228 | U46: =IFERROR(IF(ISBLANK(INDIRECT("'"&$Q$2&"'!K"&ROW())),"",INDIRECT("'"&$Q$2&"'!K"&ROW())),"") -> 0.017391304 | V46: =IF(OR($K46="",$U46=""),"",$K46-$U46) -> -0.04303233 | W46: =IFERROR(IF(ISBLANK(INDIRECT("'"&$Q$2&"'!O"&ROW())),"",INDIRECT("'"&$Q$2&"'!O"&ROW())),"") -> 0 | X46: =IF(OR($O46="",$W46=""),"",$O46-$W46) -> 3
A47: Одноклассники | B47: Нярьяна Нгэрм | E47: =IF($D47="","",IFERROR(IF(ISBLANK(INDIRECT("'"&$Q$2&"'!D"&ROW())),"",INDIRECT("'"&$Q$2&"'!D"&ROW())),"")) | F47: =IF(OR(D47="",E47=""),"",D47-E47) | G47: =IFERROR(F47/E47,"") | I47: =IF($H47="","",IFERROR(IF(ISBLANK(INDIRECT("'"&$Q$2&"'!H"&ROW())),"",INDIRECT("'"&$Q$2&"'!H"&ROW())),"")) | J47: =IF(OR(H47="",I47=""),"",H47-I47) | K47: =IFERROR(J47/I47,"") | L47: =IFERROR(D47/C47,"") | M47: =IFERROR(H47/D47*1000,"") | O47: =IFERROR(IF(OR(N47="",ISBLANK(INDIRECT("'"&$Q$2&"'!N"&ROW()))),"",N47-INDIRECT("'"&$Q$2&"'!N"&ROW())),"") | S47: =IFERROR(IF(ISBLANK(INDIRECT("'"&$Q$2&"'!G"&ROW())),"",INDIRECT("'"&$Q$2&"'!G"&ROW())),"") -> 0.5045045 | T47: =IF(OR($G47="",$S47=""),"",$G47-$S47) | U47: =IFERROR(IF(ISBLANK(INDIRECT("'"&$Q$2&"'!K"&ROW())),"",INDIRECT("'"&$Q$2&"'!K"&ROW())),"") -> 0.071428571 | V47: =IF(OR($K47="",$U47=""),"",$K47-$U47) | W47: =IFERROR(IF(ISBLANK(INDIRECT("'"&$Q$2&"'!O"&ROW())),"",INDIRECT("'"&$Q$2&"'!O"&ROW())),"") -> 1 | X47: =IF(OR($O47="",$W47=""),"",$O47-$W47)
A48: Одноклассники | B48: Лух Авт | E48: =IF($D48="","",IFERROR(IF(ISBLANK(INDIRECT("'"&$Q$2&"'!D"&ROW())),"",INDIRECT("'"&$Q$2&"'!D"&ROW())),"")) | F48: =IF(OR(D48="",E48=""),"",D48-E48) | G48: =IFERROR(F48/E48,"") | I48: =IF($H48="","",IFERROR(IF(ISBLANK(INDIRECT("'"&$Q$2&"'!H"&ROW())),"",INDIRECT("'"&$Q$2&"'!H"&ROW())),"")) | J48: =IF(OR(H48="",I48=""),"",H48-I48) | K48: =IFERROR(J48/I48,"") | L48: =IFERROR(D48/C48,"") | M48: =IFERROR(H48/D48*1000,"") | O48: =IFERROR(IF(OR(N48="",ISBLANK(INDIRECT("'"&$Q$2&"'!N"&ROW()))),"",N48-INDIRECT("'"&$Q$2&"'!N"&ROW())),"") | S48: =IFERROR(IF(ISBLANK(INDIRECT("'"&$Q$2&"'!G"&ROW())),"",INDIRECT("'"&$Q$2&"'!G"&ROW())),"") -> -0.19645293 | T48: =IF(OR($G48="",$S48=""),"",$G48-$S48) | U48: =IFERROR(IF(ISBLANK(INDIRECT("'"&$Q$2&"'!K"&ROW())),"",INDIRECT("'"&$Q$2&"'!K"&ROW())),"") -> 0.36893204 | V48: =IF(OR($K48="",$U48=""),"",$K48-$U48) | W48: =IFERROR(IF(ISBLANK(INDIRECT("'"&$Q$2&"'!O"&ROW())),"",INDIRECT("'"&$Q$2&"'!O"&ROW())),"") -> 3 | X48: =IF(OR($O48="",$W48=""),"",$O48-$W48)
A49: Одноклассники | B49: МК-Ямал | C49: 214 | D49: 10157 | E49: =IF($D49="","",IFERROR(IF(ISBLANK(INDIRECT("'"&$Q$2&"'!D"&ROW())),"",INDIRECT("'"&$Q$2&"'!D"&ROW())),"")) -> 7973 | F49: =IF(OR(D49="",E49=""),"",D49-E49) -> 2184 | G49: =IFERROR(F49/E49,"") -> 0.2739245 | H49: 1 | I49: =IF($H49="","",IFERROR(IF(ISBLANK(INDIRECT("'"&$Q$2&"'!H"&ROW())),"",INDIRECT("'"&$Q$2&"'!H"&ROW())),"")) -> 2 | J49: =IF(OR(H49="",I49=""),"",H49-I49) -> -1 | K49: =IFERROR(J49/I49,"") -> -0.5 | L49: =IFERROR(D49/C49,"") -> 47.462617 | M49: =IFERROR(H49/D49*1000,"") -> 0.098454268 | N49: 4820 | O49: =IFERROR(IF(OR(N49="",ISBLANK(INDIRECT("'"&$Q$2&"'!N"&ROW()))),"",N49-INDIRECT("'"&$Q$2&"'!N"&ROW())),"") -> 0 | S49: =IFERROR(IF(ISBLANK(INDIRECT("'"&$Q$2&"'!G"&ROW())),"",INDIRECT("'"&$Q$2&"'!G"&ROW())),"") -> 0.25955766 | T49: =IF(OR($G49="",$S49=""),"",$G49-$S49) -> 0.014366833 | U49: =IFERROR(IF(ISBLANK(INDIRECT("'"&$Q$2&"'!K"&ROW())),"",INDIRECT("'"&$Q$2&"'!K"&ROW())),"") -> 0 | V49: =IF(OR($K49="",$U49=""),"",$K49-$U49) -> -0.5 | W49: =IFERROR(IF(ISBLANK(INDIRECT("'"&$Q$2&"'!O"&ROW())),"",INDIRECT("'"&$Q$2&"'!O"&ROW())),"") -> 3 | X49: =IF(OR($O49="",$W49=""),"",$O49-$W49) -> -3
A50: Одноклассники | B50: Морошка | E50: =IF($D50="","",IFERROR(IF(ISBLANK(INDIRECT("'"&$Q$2&"'!D"&ROW())),"",INDIRECT("'"&$Q$2&"'!D"&ROW())),"")) | F50: =IF(OR(D50="",E50=""),"",D50-E50) | G50: =IFERROR(F50/E50,"") | I50: =IF($H50="","",IFERROR(IF(ISBLANK(INDIRECT("'"&$Q$2&"'!H"&ROW())),"",INDIRECT("'"&$Q$2&"'!H"&ROW())),"")) | J50: =IF(OR(H50="",I50=""),"",H50-I50) | K50: =IFERROR(J50/I50,"") | L50: =IFERROR(D50/C50,"") | M50: =IFERROR(H50/D50*1000,"") | O50: =IFERROR(IF(OR(N50="",ISBLANK(INDIRECT("'"&$Q$2&"'!N"&ROW()))),"",N50-INDIRECT("'"&$Q$2&"'!N"&ROW())),"") | S50: =IFERROR(IF(ISBLANK(INDIRECT("'"&$Q$2&"'!G"&ROW())),"",INDIRECT("'"&$Q$2&"'!G"&ROW())),"") -> 3.037037 | T50: =IF(OR($G50="",$S50=""),"",$G50-$S50) | U50: =IFERROR(IF(ISBLANK(INDIRECT("'"&$Q$2&"'!K"&ROW())),"",INDIRECT("'"&$Q$2&"'!K"&ROW())),"") -> -0.25 | V50: =IF(OR($K50="",$U50=""),"",$K50-$U50) | W50: =IFERROR(IF(ISBLANK(INDIRECT("'"&$Q$2&"'!O"&ROW())),"",INDIRECT("'"&$Q$2&"'!O"&ROW())),"") -> 0 | X50: =IF(OR($O50="",$W50=""),"",$O50-$W50)
B51: Итого Одноклассники | C51: =SUM(C31:C50) -> 1190 | D51: =SUM(D31:D50) -> 177893 | E51: =SUM(E31:E50) -> 210483 | F51: =SUM(F31:F50) -> -32590 | G51: =IF(C51=0,"",IFERROR(F51/E51,"")) -> -0.15483436 | H51: =SUM(H31:H50) -> 1166 | I51: =SUM(I31:I50) -> 1421 | J51: =SUM(J31:J50) -> -255 | K51: =IF(C51=0,"",IFERROR(J51/I51,"")) -> -0.17945109 | L51: =IFERROR(D51/C51,"") -> 149.48992 | M51: =IFERROR(H51/D51*1000,"") -> 6.5545019 | N51: =SUM(N31:N50) -> 89518 | O51: =SUM(O31:O50) -> 14 | S51: =IFERROR(IF(ISBLANK(INDIRECT("'"&$Q$2&"'!G"&ROW())),"",INDIRECT("'"&$Q$2&"'!G"&ROW())),"") -> -0.47715808 | T51: =IF(OR($G51="",$S51=""),"",$G51-$S51) -> 0.32232372 | U51: =IFERROR(IF(ISBLANK(INDIRECT("'"&$Q$2&"'!K"&ROW())),"",INDIRECT("'"&$Q$2&"'!K"&ROW())),"") -> -0.24364766 | V51: =IF(OR($K51="",$U51=""),"",$K51-$U51) -> 0.064196566 | W51: =IFERROR(IF(ISBLANK(INDIRECT("'"&$Q$2&"'!O"&ROW())),"",INDIRECT("'"&$Q$2&"'!O"&ROW())),"") -> 48 | X51: =IF(OR(C51=0,$O51="",$W51=""),"",$O51-$W51) -> -34
A52: Telegram | B52: Ямал-Медиа | C52: 141 | D52: 86846 | E52: =IF($D52="","",IFERROR(IF(ISBLANK(INDIRECT("'"&$Q$2&"'!D"&ROW())),"",INDIRECT("'"&$Q$2&"'!D"&ROW())),"")) -> 41618 | F52: =IF(OR(D52="",E52=""),"",D52-E52) -> 45228 | G52: =IFERROR(F52/E52,"") -> 1.0867413 | H52: 262 | I52: =IF($H52="","",IFERROR(IF(ISBLANK(INDIRECT("'"&$Q$2&"'!H"&ROW())),"",INDIRECT("'"&$Q$2&"'!H"&ROW())),"")) -> 257 | J52: =IF(OR(H52="",I52=""),"",H52-I52) -> 5 | K52: =IFERROR(J52/I52,"") -> 0.019455253 | L52: =IFERROR(D52/C52,"") -> 615.92908 | M52: =IFERROR(H52/D52*1000,"") -> 3.0168344 | N52: 11764 | O52: =IFERROR(IF(OR(N52="",ISBLANK(INDIRECT("'"&$Q$2&"'!N"&ROW()))),"",N52-INDIRECT("'"&$Q$2&"'!N"&ROW())),"") -> -25 | S52: =IFERROR(IF(ISBLANK(INDIRECT("'"&$Q$2&"'!G"&ROW())),"",INDIRECT("'"&$Q$2&"'!G"&ROW())),"") -> -0.46944239 | T52: =IF(OR($G52="",$S52=""),"",$G52-$S52) -> 1.5561837 | U52: =IFERROR(IF(ISBLANK(INDIRECT("'"&$Q$2&"'!K"&ROW())),"",INDIRECT("'"&$Q$2&"'!K"&ROW())),"") -> -0.29781421 | V52: =IF(OR($K52="",$U52=""),"",$K52-$U52) -> 0.31726946 | W52: =IFERROR(IF(ISBLANK(INDIRECT("'"&$Q$2&"'!O"&ROW())),"",INDIRECT("'"&$Q$2&"'!O"&ROW())),"") -> -22 | X52: =IF(OR($O52="",$W52=""),"",$O52-$W52) -> -3
...

Sheet 14-20.09
A1: Недельный съём · 14–20.09.2026 | Q1: Лист прошлой недели (питает колонки E, I, O):
A2: Площадка | B2: Ресурс | C2: Публикаций | D2: Просмотры | E2: Просмотры пред. неделя | F2: Δ просмотров | G2: Δ % | H2: Лайки | I2: Лайки пред. неделя | J2: Δ лайков | K2: Δ % | L2: Ср. просмотров на пост | M2: Лайков на 1000 просмотров | N2: Подписчики | O2: Прирост подписчиков | Q2: 07-13.09 | S2: Δ % просмотров пред. неделя | T2: Ускорение просмотров, п.п. | U2: Δ % лайков пред. неделя | V2: Ускорение лайков, п.п. | W2: Прирост подписч. пред. неделя | X2: Ускорение подписчиков, чел.
A3: ВКонтакте | B3: Ямал-Медиа | C3: 123 | D3: 516875 | E3: =IF($D3="","",IFERROR(IF(ISBLANK(INDIRECT("'"&$Q$2&"'!D"&ROW())),"",INDIRECT("'"&$Q$2&"'!D"&ROW())),"")) -> 367169 | F3: =IF(OR(D3="",E3=""),"",D3-E3) -> 149706 | G3: =IFERROR(F3/E3,"") -> 0.4077305 | H3: 1943 | I3: =IF($H3="","",IFERROR(IF(ISBLANK(INDIRECT("'"&$Q$2&"'!H"&ROW())),"",INDIRECT("'"&$Q$2&"'!H"&ROW())),"")) -> 1463 | J3: =IF(OR(H3="",I3=""),"",H3-I3) -> 480 | K3: =IFERROR(J3/I3,"") -> 0.32809296 | L3: =IFERROR(D3/C3,"") -> 4202.2358 | M3: =IFERROR(H3/D3*1000,"") -> 3.7591294 | N3: 89076 | O3: =IFERROR(IF(OR(N3="",ISBLANK(INDIRECT("'"&$Q$2&"'!N"&ROW()))),"",N3-INDIRECT("'"&$Q$2&"'!N"&ROW())),"") -> 1085 | Q3: Колонки E и I берут прошлую неделю только по строкам, снятым в текущей — сравнение идёт по сопоставимому периметру. | S3: =IFERROR(IF(ISBLANK(INDIRECT("'"&$Q$2&"'!G"&ROW())),"",INDIRECT("'"&$Q$2&"'!G"&ROW())),"") -> -0.083594152 | T3: =IF(OR($G3="",$S3=""),"",$G3-$S3) -> 0.49132465 | U3: =IFERROR(IF(ISBLANK(INDIRECT("'"&$Q$2&"'!K"&ROW())),"",INDIRECT("'"&$Q$2&"'!K"&ROW())),"") -> -0.24470831 | V3: =IF(OR($K3="",$U3=""),"",$K3-$U3) -> 0.57280127 | W3: =IFERROR(IF(ISBLANK(INDIRECT("'"&$Q$2&"'!O"&ROW())),"",INDIRECT("'"&$Q$2&"'!O"&ROW())),"") -> 193 | X3: =IF(OR($O3="",$W3=""),"",$O3-$W3) -> 892
A4: ВКонтакте | B4: Север-Пресс | C4: 144 | D4: 216205 | E4: =IF($D4="","",IFERROR(IF(ISBLANK(INDIRECT("'"&$Q$2&"'!D"&ROW())),"",INDIRECT("'"&$Q$2&"'!D"&ROW())),"")) -> 131208 | F4: =IF(OR(D4="",E4=""),"",D4-E4) -> 84997 | G4: =IFERROR(F4/E4,"") -> 0.64780349 | H4: 695 | I4: =IF($H4="","",IFERROR(IF(ISBLANK(INDIRECT("'"&$Q$2&"'!H"&ROW())),"",INDIRECT("'"&$Q$2&"'!H"&ROW())),"")) -> 570 | J4: =IF(OR(H4="",I4=""),"",H4-I4) -> 125 | K4: =IFERROR(J4/I4,"") -> 0.21929825 | L4: =IFERROR(D4/C4,"") -> 1501.4236 | M4: =IFERROR(H4/D4*1000,"") -> 3.2145418 | N4: 26249 | O4: =IFERROR(IF(OR(N4="",ISBLANK(INDIRECT("'"&$Q$2&"'!N"&ROW()))),"",N4-INDIRECT("'"&$Q$2&"'!N"&ROW())),"") -> 25 | Q4: ОК: «просмотры» = VIEWS листа Topics, лайки = сумма LIKES листа Actions (по группе, как в прошлых съёмах). | S4: =IFERROR(IF(ISBLANK(INDIRECT("'"&$Q$2&"'!G"&ROW())),"",INDIRECT("'"&$Q$2&"'!G"&ROW())),"") -> 0.32282131 | T4: =IF(OR($G4="",$S4=""),"",$G4-$S4) -> 0.32498218 | U4: =IFERROR(IF(ISBLANK(INDIRECT("'"&$Q$2&"'!K"&ROW())),"",INDIRECT("'"&$Q$2&"'!K"&ROW())),"") -> 0.21535181 | V4: =IF(OR($K4="",$U4=""),"",$K4-$U4) -> 0.0039464332 | W4: =IFERROR(IF(ISBLANK(INDIRECT("'"&$Q$2&"'!O"&ROW())),"",INDIRECT("'"&$Q$2&"'!O"&ROW())),"") -> 21 | X4: =IF(OR($O4="",$W4=""),"",$O4-$W4) -> 4
A5: ВКонтакте | B5: Лента СП | C5: 245 | D5: 4223 | E5: =IF($D5="","",IFERROR(IF(ISBLANK(INDIRECT("'"&$Q$2&"'!D"&ROW())),"",INDIRECT("'"&$Q$2&"'!D"&ROW())),"")) -> 6090 | F5: =IF(OR(D5="",E5=""),"",D5-E5) -> -1867 | G5: =IFERROR(F5/E5,"") -> -0.30656814 | H5: 10 | I5: =IF($H5="","",IFERROR(IF(ISBLANK(INDIRECT("'"&$Q$2&"'!H"&ROW())),"",INDIRECT("'"&$Q$2&"'!H"&ROW())),"")) -> 14 | J5: =IF(OR(H5="",I5=""),"",H5-I5) -> -4 | K5: =IFERROR(J5/I5,"") -> -0.28571429 | L5: =IFERROR(D5/C5,"") -> 17.236735 | M5: =IFERROR(H5/D5*1000,"") -> 2.3679848 | N5: 3501 | O5: =IFERROR(IF(OR(N5="",ISBLANK(INDIRECT("'"&$Q$2&"'!N"&ROW()))),"",N5-INDIRECT("'"&$Q$2&"'!N"&ROW())),"") -> -2 | S5: =IFERROR(IF(ISBLANK(INDIRECT("'"&$Q$2&"'!G"&ROW())),"",INDIRECT("'"&$Q$2&"'!G"&ROW())),"") -> 0.16644321 | T5: =IF(OR($G5="",$S5=""),"",$G5-$S5) -> -0.47301135 | U5: =IFERROR(IF(ISBLANK(INDIRECT("'"&$Q$2&"'!K"&ROW())),"",INDIRECT("'"&$Q$2&"'!K"&ROW())),"") -> 0.076923077 | V5: =IF(OR($K5="",$U5=""),"",$K5-$U5) -> -0.36263736 | W5: =IFERROR(IF(ISBLANK(INDIRECT("'"&$Q$2&"'!O"&ROW())),"",INDIRECT("'"&$Q$2&"'!O"&ROW())),"") -> 2 | X5: =IF(OR($O5="",$W5=""),"",$O5-$W5) -> -4
A6: ВКонтакте | B6: Красный Север | C6: 96 | D6: 52347 | E6: =IF($D6="","",IFERROR(IF(ISBLANK(INDIRECT("'"&$Q$2&"'!D"&ROW())),"",INDIRECT("'"&$Q$2&"'!D"&ROW())),"")) -> 56436 | F6: =IF(OR(D6="",E6=""),"",D6-E6) -> -4089 | G6: =IFERROR(F6/E6,"") -> -0.072453753 | H6: 291 | I6: =IF($H6="","",IFERROR(IF(ISBLANK(INDIRECT("'"&$Q$2&"'!H"&ROW())),"",INDIRECT("'"&$Q$2&"'!H"&ROW())),"")) -> 269 | J6: =IF(OR(H6="",I6=""),"",H6-I6) -> 22 | K6: =IFERROR(J6/I6,"") -> 0.081784387 | L6: =IFERROR(D6/C6,"") -> 545.28125 | M6: =IFERROR(H6/D6*1000,"") -> 5.5590578 | N6: 22931 | O6: =IFERROR(IF(OR(N6="",ISBLANK(INDIRECT("'"&$Q$2&"'!N"&ROW()))),"",N6-INDIRECT("'"&$Q$2&"'!N"&ROW())),"") -> -4 | S6: =IFERROR(IF(ISBLANK(INDIRECT("'"&$Q$2&"'!G"&ROW())),"",INDIRECT("'"&$Q$2&"'!G"&ROW())),"") -> -0.14980416 | T6: =IF(OR($G6="",$S6=""),"",$G6-$S6) -> 0.077350405 | U6: =IFERROR(IF(ISBLANK(INDIRECT("'"&$Q$2&"'!K"&ROW())),"",INDIRECT("'"&$Q$2&"'!K"&ROW())),"") -> -0.085034014 | V6: =IF(OR($K6="",$U6=""),"",$K6-$U6) -> 0.1668184 | W6: =IFERROR(IF(ISBLANK(INDIRECT("'"&$Q$2&"'!O"&ROW())),"",INDIRECT("'"&$Q$2&"'!O"&ROW())),"") -> 11 | X6: =IF(OR($O6="",$W6=""),"",$O6-$W6) -> -15
A7: ВКонтакте | B7: Новый Уренгой | C7: 125 | D7: 108141 | E7: =IF($D7="","",IFERROR(IF(ISBLANK(INDIRECT("'"&$Q$2&"'!D"&ROW())),"",INDIRECT("'"&$Q$2&"'!D"&ROW())),"")) -> 105221 | F7: =IF(OR(D7="",E7=""),"",D7-E7) -> 2920 | G7: =IFERROR(F7/E7,"") -> 0.027751114 | H7: 1025 | I7: =IF($H7="","",IFERROR(IF(ISBLANK(INDIRECT("'"&$Q$2&"'!H"&ROW())),"",INDIRECT("'"&$Q$2&"'!H"&ROW())),"")) -> 1220 | J7: =IF(OR(H7="",I7=""),"",H7-I7) -> -195 | K7: =IFERROR(J7/I7,"") -> -0.15983607 | L7: =IFERROR(D7/C7,"") -> 865.128 | M7: =IFERROR(H7/D7*1000,"") -> 9.4783662 | N7: 24832 | O7: =IFERROR(IF(OR(N7="",ISBLANK(INDIRECT("'"&$Q$2&"'!N"&ROW()))),"",N7-INDIRECT("'"&$Q$2&"'!N"&ROW())),"") -> 317 | S7: =IFERROR(IF(ISBLANK(INDIRECT("'"&$Q$2&"'!G"&ROW())),"",INDIRECT("'"&$Q$2&"'!G"&ROW())),"") -> -0.47512845 | T7: =IF(OR($G7="",$S7=""),"",$G7-$S7) -> 0.50287956 | U7: =IFERROR(IF(ISBLANK(INDIRECT("'"&$Q$2&"'!K"&ROW())),"",INDIRECT("'"&$Q$2&"'!K"&ROW())),"") -> -0.44970681 | V7: =IF(OR($K7="",$U7=""),"",$K7-$U7) -> 0.28987075 | W7: =IFERROR(IF(ISBLANK(INDIRECT("'"&$Q$2&"'!O"&ROW())),"",INDIRECT("'"&$Q$2&"'!O"&ROW())),"") -> 73 | X7: =IF(OR($O7="",$W7=""),"",$O7-$W7) -> 244
A8: ВКонтакте | B8: Надым | C8: 117 | D8: 347976 | E8: =IF($D8="","",IFERROR(IF(ISBLANK(INDIRECT("'"&$Q$2&"'!D"&ROW())),"",INDIRECT("'"&$Q$2&"'!D"&ROW())),"")) -> 272210 | F8: =IF(OR(D8="",E8=""),"",D8-E8) -> 75766 | G8: =IFERROR(F8/E8,"") -> 0.27833658 | H8: 3740 | I8: =IF($H8="","",IFERROR(IF(ISBLANK(INDIRECT("'"&$Q$2&"'!H"&ROW())),"",INDIRECT("'"&$Q$2&"'!H"&ROW())),"")) -> 4342 | J8: =IF(OR(H8="",I8=""),"",H8-I8) -> -602 | K8: =IFERROR(J8/I8,"") -> -0.13864579 | L8: =IFERROR(D8/C8,"") -> 2974.1538 | M8: =IFERROR(H8/D8*1000,"") -> 10.747868 | N8: 21715 | O8: =IFERROR(IF(OR(N8="",ISBLANK(INDIRECT("'"&$Q$2&"'!N"&ROW()))),"",N8-INDIRECT("'"&$Q$2&"'!N"&ROW())),"") -> 218 | S8: =IFERROR(IF(ISBLANK(INDIRECT("'"&$Q$2&"'!G"&ROW())),"",INDIRECT("'"&$Q$2&"'!G"&ROW())),"") -> -0.26824875 | T8: =IF(OR($G8="",$S8=""),"",$G8-$S8) -> 0.54658533 | U8: =IFERROR(IF(ISBLANK(INDIRECT("'"&$Q$2&"'!K"&ROW())),"",INDIRECT("'"&$Q$2&"'!K"&ROW())),"") -> -0.29087049 | V8: =IF(OR($K8="",$U8=""),"",$K8-$U8) -> 0.1522247 | W8: =IFERROR(IF(ISBLANK(INDIRECT("'"&$Q$2&"'!O"&ROW())),"",INDIRECT("'"&$Q$2&"'!O"&ROW())),"") -> 60 | X8: =IF(OR($O8="",$W8=""),"",$O8-$W8) -> 158
A9: ВКонтакте | B9: Ноябрьск | C9: 119 | D9: 424827 | E9: =IF($D9="","",IFERROR(IF(ISBLANK(INDIRECT("'"&$Q$2&"'!D"&ROW())),"",INDIRECT("'"&$Q$2&"'!D"&ROW())),"")) -> 319358 | F9: =IF(OR(D9="",E9=""),"",D9-E9) -> 105469 | G9: =IFERROR(F9/E9,"") -> 0.3302532 | H9: 4187 | I9: =IF($H9="","",IFERROR(IF(ISBLANK(INDIRECT("'"&$Q$2&"'!H"&ROW())),"",INDIRECT("'"&$Q$2&"'!H"&ROW())),"")) -> 4035 | J9: =IF(OR(H9="",I9=""),"",H9-I9) -> 152 | K9: =IFERROR(J9/I9,"") -> 0.037670384 | L9: =IFERROR(D9/C9,"") -> 3569.9748 | M9: =IFERROR(H9/D9*1000,"") -> 9.8557766 | N9: 31301 | O9: =IFERROR(IF(OR(N9="",ISBLANK(INDIRECT("'"&$Q$2&"'!N"&ROW()))),"",N9-INDIRECT("'"&$Q$2&"'!N"&ROW())),"") -> 271 | S9: =IFERROR(IF(ISBLANK(INDIRECT("'"&$Q$2&"'!G"&ROW())),"",INDIRECT("'"&$Q$2&"'!G"&ROW())),"") -> -0.32202087 | T9: =IF(OR($G9="",$S9=""),"",$G9-$S9) -> 0.65227407 | U9: =IFERROR(IF(ISBLANK(INDIRECT("'"&$Q$2&"'!K"&ROW())),"",INDIRECT("'"&$Q$2&"'!K"&ROW())),"") -> -0.40071291 | V9: =IF(OR($K9="",$U9=""),"",$K9-$U9) -> 0.43838329 | W9: =IFERROR(IF(ISBLANK(INDIRECT("'"&$Q$2&"'!O"&ROW())),"",INDIRECT("'"&$Q$2&"'!O"&ROW())),"") -> 47 | X9: =IF(OR($O9="",$W9=""),"",$O9-$W9) -> 224
